Workbook

Sheet Exec_Dashboard
A1: EXECUTIVE DASHBOARD — COO One-Page View
A2: Regional Fiber Broadband • Weekly Executive Review • Red / Yellow / Green health • All values roll up automatically from the input tabs
B4: REPORTING CONTROLS
B5: Reporting Month ▶ | C5: Jun-2026 | D5: =MATCH(C5,Lists!$A$2:$A$13,0) | E5: (Period index — drives MTD / YTD / Rolling-12)
B7: COMPANY HEALTH — KPI SCORECARD (current reporting month)
B8: TOTAL CUSTOMERS | D8: NEW SALES (MTD) | F8: DISCONNECTS (MTD) | H8: NET ADDS (MTD) | J8: TAKE RATE
B9: =SUMIFS(Customer_Data!$C$4:$C$1003,Customer_Data!$A$4:$A$1003,Exec_Dashboard!$C$5) | D9: =SUMIFS(Customer_Data!$D$4:$D$1003,Customer_Data!$A$4:$A$1003,Exec_Dashboard!$C$5) | F9: =SUMIFS(Customer_Data!$E$4:$E$1003,Customer_Data!$A$4:$A$1003,Exec_Dashboard!$C$5) | H9: =SUMIFS(Customer_Data!$D$4:$D$1003,Customer_Data!$A$4:$A$1003,Exec_Dashboard!$C$5)-SUMIFS(Customer_Data!$E$4:$E$1003,Customer_Data!$A$4:$A$1003,Exec_Dashboard!$C$5) | J9: =IF(SUMIFS(Customer_Data!$F$4:$F$1003,Customer_Data!$A$4:$A$1003,Exec_Dashboard!$C$5)=0,0,SUMIFS(Customer_Data!$C$4:$C$1003,Customer_Data!$A$4:$A$1003,Exec_Dashboard!$C$5)/SUMIFS(Customer_Data!$F$4:$F$1003,Customer_Data!$A$4:$A$1003,Exec_Dashboard!$C$5))
B10: End-of-month subscribers | D10: =IF(D9>=SUMIFS(Sales_Targets!$C$4:$C$1003,Sales_Targets!$A$4:$A$1003,Exec_Dashboard!$C$5),"GREEN",IF(D9>=0.9*SUMIFS(Sales_Targets!$C$4:$C$1003,Sales_Targets!$A$4:$A$1003,Exec_Dashboard!$C$5),"YELLOW","RED")) | F10: =IF(F9<=0.02*SUMIFS(Customer_Data!$C$4:$C$1003,Customer_Data!$A$4:$A$1003,Exec_Dashboard!$C$5),"GREEN",IF(F9<=0.03*SUMIFS(Customer_Data!$C$4:$C$1003,Customer_Data!$A$4:$A$1003,Exec_Dashboard!$C$5),"YELLOW","RED")) | H10: =IF(H9>0,"GREEN",IF(H9=0,"YELLOW","RED")) | J10: =IF(J9>=0.35,"GREEN",IF(J9>=0.25,"YELLOW","RED"))
B13: REVENUE (MTD) | D13: ARPU | F13: MRR | H13: CHURN RATE | J13: HOMES PASSED
B14: =SUMIFS(Financial_Data!$C$4:$C$1003,Financial_Data!$A$4:$A$1003,Exec_Dashboard!$C$5) | D14: =IF(SUMIFS(Customer_Data!$C$4:$C$1003,Customer_Data!$A$4:$A$1003,Exec_Dashboard!$C$5)=0,0,SUMIFS(Financial_Data!$D$4:$D$1003,Financial_Data!$A$4:$A$1003,Exec_Dashboard!$C$5)/SUMIFS(Customer_Data!$C$4:$C$1003,Customer_Data!$A$4:$A$1003,Exec_Dashboard!$C$5)) | F14: =SUMIFS(Financial_Data!$D$4:$D$1003,Financial_Data!$A$4:$A$1003,Exec_Dashboard!$C$5) | H14: =IF(SUMIFS(Customer_Data!$C$4:$C$1003,Customer_Data!$B$4:$B$1003,Exec_Dashboard!$D$5-1)=0,0,SUMIFS(Customer_Data!$E$4:$E$1003,Customer_Data!$A$4:$A$1003,Exec_Dashboard!$C$5)/SUMIFS(Customer_Data!$C$4:$C$1003,Customer_Data!$B$4:$B$1003,Exec_Dashboard!$D$5-1)) | J14: =SUMIFS(Customer_Data!$F$4:$F$1003,Customer_Data!$A$4:$A$1003,Exec_Dashboard!$C$5)
B15: Total billed this month | D15: =IF(D14>=75,"GREEN",IF(D14>=65,"YELLOW","RED")) | F15: Monthly recurring revenue | H15: =IF(H14<=0.015,"GREEN",IF(H14<=0.025,"YELLOW","RED")) | J15: Cumulative passings
B18: ACTIVE PROJECTS | D18: PROJECTS BEHIND | F18: INSTALL BACKLOG | H18: AVG DAYS TO INSTALL | J18: TROUBLE TICKETS (MTD)
B19: =(COUNTIFS(Project_Data!$F$4:$F$1003,"On Track")+COUNTIFS(Project_Data!$F$4:$F$1003,"At Risk")+COUNTIFS(Project_Data!$F$4:$F$1003,"Behind")) | D19: =COUNTIFS(Project_Data!$F$4:$F$1003,"Behind") | F19: =SUMIFS(Operations_Data!$F$4:$F$1003,Operations_Data!$B$4:$B$1003,"<="&Exec_Dashboard!$D$5)-SUMIFS(Operations_Data!$G$4:$G$1003,Operations_Data!$B$4:$B$1003,"<="&Exec_Dashboard!$D$5) | H19: =AVERAGEIFS(Operations_Data!$H$4:$H$1003,Operations_Data!$A$4:$A$1003,Exec_Dashboard!$C$5) | J19: =SUMIFS(Operations_Data!$I$4:$I$1003,Operations_Data!$A$4:$A$1003,Exec_Dashboard!$C$5)
B20: Capital builds in flight | D20: =IF(D19=0,"GREEN",IF(D19<=1,"YELLOW","RED")) | F20: =IF(F19<=200,"GREEN",IF(F19<=400,"YELLOW","RED")) | H20: =IF(H19<=7,"GREEN",IF(H19<=10,"YELLOW","RED")) | J20: =IF(J19<=250,"GREEN",IF(J19<=320,"YELLOW","RED"))
B23: BUDGET vs ACTUAL (REV) | D23: CASH (END OF MONTH) | F23: 90-DAY CASH FORECAST | H23: GRANT REIMB RECEIVED | J23: GRANT OUTSTANDING
B24: =SUMIFS(Financial_Data!$C$4:$C$1003,Financial_Data!$A$4:$A$1003,Exec_Dashboard!$C$5)-SUMIFS(Financial_Data!$J$4:$J$1003,Financial_Data!$A$4:$A$1003,Exec_Dashboard!$C$5) | D24: =SUMIFS(Financial_Data!$N$4:$N$1003,Financial_Data!$A$4:$A$1003,Exec_Dashboard!$C$5) | F24: =SUMIFS(Financial_Data!$N$4:$N$1003,Financial_Data!$A$4:$A$1003,Exec_Dashboard!$C$5)+3*SUMIFS(Financial_Data!$M$4:$M$1003,Financial_Data!$A$4:$A$1003,Exec_Dashboard!$C$5)+SUM(Grant_Data!$E$4:$E$1003)-SUM(Grant_Data!$F$4:$F$1003)-3*(SUMIFS(Financial_Data!$F$4:$F$1003,Financial_Data!$A$4:$A$1003,Exec_Dashboard!$C$5)+SUMIFS(Financial_Data!$E$4:$E$1003,Financial_Data!$A$4:$A$1003,Exec_Dashboard!$C$5)+SUMIFS(Financial_Data!$H$4:$H$1003,Financial_Data!$A$4:$A$1003,Exec_Dashboard!$C$5)) | H24: =SUMIFS(Grant_Data!$F$4:$F$1003,Grant_Data!$F$4:$F$1003,">0") | J24: =SUM(Grant_Data!$E$4:$E$1003)-SUM(Grant_Data!$F$4:$F$1003)
B25: =IF(B24>=0,"GREEN",IF(B24>=-0.05*SUMIFS(Financial_Data!$J$4:$J$1003,Financial_Data!$A$4:$A$1003,Exec_Dashboard!$C$5),"YELLOW","RED")) | D25: =IF(D24>=3000000,"GREEN",IF(D24>=1500000,"YELLOW","RED")) | F25: =IF(F24>=1500000,"GREEN",IF(F24>=500000,"YELLOW","RED")) | H25: Outstanding shown on Financial tab | J25: =IF(J24<=500000,"GREEN",IF(J24<=1200000,"YELLOW","RED"))
F27: AUTO-GENERATED EXECUTIVE SUMMARY
B28: MAJOR RISKS (RED) | D28: KEY DECISIONS NEEDED | F28: ="As of "&C5&": "&SUMIFS(Customer_Data!$C$4:$C$1003,Customer_Data!$A$4:$A$1003,Exec_Dashboard!$C$5)&" customers, net adds "&(SUMIFS(Customer_Data!$D$4:$D$1003,Customer_Data!$A$4:$A$1003,Exec_Dashboard!$C$5)-SUMIFS(Customer_Data!$E$4:$E$1003,Customer_Data!$A$4:$A$1003,Exec_Dashboard!$C$5))&" ("&TEXT(IF(SUMIFS(Customer_Data!$C$4:$C$1003,Customer_Data!$B$4:$B$1003,Exec_Dashboard!$D$5-1)=0,0,SUMIFS(Customer_Data!$E$4:$E$1003,Customer_Data!$A$4:$A$1003,Exec_Dashboard!$C$5)/SUMIFS(Customer_Data!$C$4:$C$1003,Customer_Data!$B$4:$B$1003,Exec_Dashboard!$D$5-1)),"0.0%")&" churn). Revenue "&TEXT(SUMIFS(Financial_Data!$C$4:$C$1003,Financial_Data!$A$4:$A$1003,Exec_Dashboard!$C$5),"$#,##0")&" vs budget "&TEXT(SUMIFS(Financial_Data!$J$4:$J$1003,Financial_Data!$A$4:$A$1003,Exec_Dashboard!$C$5),"$#,##0")&". "&(COUNTIFS(Project_Data!$F$4:$F$1003,"On Track")+COUNTIFS(Project_Data!$F$4:$F$1003,"At Risk")+COUNTIFS(Project_Data!$F$4:$F$1003,"Behind"))&" active projects, "&COUNTIFS(Project_Data!$F$4:$F$1003,"Behind")&" behind. Install backlog "&(SUMIFS(Operations_Data!$F$4:$F$1003,Operations_Data!$B$4:$B$1003,"<="&Exec_Dashboard!$D$5)-SUMIFS(Operations_Data!$G$4:$G$1003,Operations_Data!$B$4:$B$1003,"<="&Exec_Dashboard!$D$5))&", avg "&TEXT(AVERAGEIFS(Operations_Data!$H$4:$H$1003,Operations_Data!$A$4:$A$1003,Exec_Dashboard!$C$5),"0.0")&" days. "&COUNTIFS(Risk_Register!$F$4:$F$1003,">=15")&" red risk(s), "&COUNTIFS(Board_Actions!$I$4:$I$1003,"Yes",Board_Actions!$H$4:$H$1003,"<>Complete")&" decision(s) need executive action."
B29: =COUNTIFS(Risk_Register!$F$4:$F$1003,">=15") | D29: =COUNTIFS(Board_Actions!$I$4:$I$1003,"Yes",Board_Actions!$H$4:$H$1003,"<>Complete")
B30: =IF(B29=0,"GREEN",IF(B29<=1,"YELLOW","RED")) | D30: =IF(D29=0,"GREEN",IF(D29<=3,"YELLOW","RED"))
B33: TIME-SERIES ROLLUPS — This Month / YTD / Rolling-12 / Prior Month / Goal / Variance
B34: Metric | C34: This Month | D34: YTD | E34: Rolling 12 | F34: Prior Month | G34: Goal (MTD) | H34: Variance | I34: Status
B35: New Sales | C35: =SUMIFS(Calc!$C$2:$C$13,Calc!$A$2:$A$13,Exec_Dashboard!$C$5) | D35: =SUMIFS(Calc!$C$2:$C$13,Calc!$B$2:$B$13,"<="&Exec_Dashboard!$D$5) | E35: =SUMIFS(Calc!$C$2:$C$13,Calc!$B$2:$B$13,">"&(Exec_Dashboard!$D$5-12)) | F35: =SUMIFS(Calc!$C$2:$C$13,Calc!$B$2:$B$13,Exec_Dashboard!$D$5-1) | G35: =SUMIFS(Sales_Targets!$C$4:$C$1003,Sales_Targets!$A$4:$A$1003,Exec_Dashboard!$C$5) | H35: =C35-G35 | I35: =IF(C35>=G35,"GREEN",IF(C35>=0.9*G35,"YELLOW","RED"))
B36: Disconnects | C36: =SUMIFS(Calc!$D$2:$D$13,Calc!$A$2:$A$13,Exec_Dashboard!$C$5) | D36: =SUMIFS(Calc!$D$2:$D$13,Calc!$B$2:$B$13,"<="&Exec_Dashboard!$D$5) | E36: =SUMIFS(Calc!$D$2:$D$13,Calc!$B$2:$B$13,">"&(Exec_Dashboard!$D$5-12)) | F36: =SUMIFS(Calc!$D$2:$D$13,Calc!$B$2:$B$13,Exec_Dashboard!$D$5-1) | G36: — | H36: =C36-F36 | I36: =IF(C36<=F36,"GREEN",IF(C36<=1.05*F36,"YELLOW","RED"))
B37: Net Adds | C37: =SUMIFS(Calc!$E$2:$E$13,Calc!$A$2:$A$13,Exec_Dashboard!$C$5) | D37: =SUMIFS(Calc!$E$2:$E$13,Calc!$B$2:$B$13,"<="&Exec_Dashboard!$D$5) | E37: =SUMIFS(Calc!$E$2:$E$13,Calc!$B$2:$B$13,">"&(Exec_Dashboard!$D$5-12)) | F37: =SUMIFS(Calc!$E$2:$E$13,Calc!$B$2:$B$13,Exec_Dashboard!$D$5-1) | G37: — | H37: =C37-F37 | I37: =IF(C37>=F37,"GREEN",IF(C37>=0.95*F37,"YELLOW","RED"))
B38: Revenue | C38: =SUMIFS(Calc!$J$2:$J$13,Calc!$A$2:$A$13,Exec_Dashboard!$C$5) | D38: =SUMIFS(Calc!$J$2:$J$13,Calc!$B$2:$B$13,"<="&Exec_Dashboard!$D$5) | E38: =SUMIFS(Calc!$J$2:$J$13,Calc!$B$2:$B$13,">"&(Exec_Dashboard!$D$5-12)) | F38: =SUMIFS(Calc!$J$2:$J$13,Calc!$B$2:$B$13,Exec_Dashboard!$D$5-1) | G38: =SUMIFS(Financial_Data!$J$4:$J$1003,Financial_Data!$A$4:$A$1003,Exec_Dashboard!$C$5) | H38: =C38-G38 | I38: =IF(C38>=G38,"GREEN",IF(C38>=0.9*G38,"YELLOW","RED"))
B39: MRR | C39: =SUMIFS(Calc!$K$2:$K$13,Calc!$A$2:$A$13,Exec_Dashboard!$C$5) | D39: =SUMIFS(Calc!$K$2:$K$13,Calc!$A$2:$A$13,Exec_Dashboard!$C$5) | E39: =SUMIFS(Calc!$K$2:$K$13,Calc!$A$2:$A$13,Exec_Dashboard!$C$5) | F39: =SUMIFS(Calc!$K$2:$K$13,Calc!$B$2:$B$13,Exec_Dashboard!$D$5-1) | G39: — | H39: =C39-F39 | I39: =IF(C39>=F39,"GREEN",IF(C39>=0.95*F39,"YELLOW","RED"))
B40: CapEx | C40: =SUMIFS(Calc!$M$2:$M$13,Calc!$A$2:$A$13,Exec_Dashboard!$C$5) | D40: =SUMIFS(Calc!$M$2:$M$13,Calc!$B$2:$B$13,"<="&Exec_Dashboard!$D$5) | E40: =SUMIFS(Calc!$M$2:$M$13,Calc!$B$2:$B$13,">"&(Exec_Dashboard!$D$5-12)) | F40: =SUMIFS(Calc!$M$2:$M$13,Calc!$B$2:$B$13,Exec_Dashboard!$D$5-1) | G40: =SUMIFS(Financial_Data!$L$4:$L$1003,Financial_Data!$A$4:$A$1003,Exec_Dashboard!$C$5) | H40: =C40-G40 | I40: =IF(C40<=G40,"GREEN",IF(C40<=1.1*G40,"YELLOW","RED"))
B41: OpEx | C41: =SUMIFS(Calc!$N$2:$N$13,Calc!$A$2:$A$13,Exec_Dashboard!$C$5) | D41: =SUMIFS(Calc!$N$2:$N$13,Calc!$B$2:$B$13,"<="&Exec_Dashboard!$D$5) | E41: =SUMIFS(Calc!$N$2:$N$13,Calc!$B$2:$B$13,">"&(Exec_Dashboard!$D$5-12)) | F41: =SUMIFS(Calc!$N$2:$N$13,Calc!$B$2:$B$13,Exec_Dashboard!$D$5-1) | G41: =SUMIFS(Financial_Data!$K$4:$K$1003,Financial_Data!$A$4:$A$1003,Exec_Dashboard!$C$5) | H41: =C41-G41 | I41: =IF(C41<=G41,"GREEN",IF(C41<=1.1*G41,"YELLOW","RED"))
B42: Installs Completed | C42: =SUMIFS(Calc!$Q$2:$Q$13,Calc!$A$2:$A$13,Exec_Dashboard!$C$5) | D42: =SUMIFS(Calc!$Q$2:$Q$13,Calc!$B$2:$B$13,"<="&Exec_Dashboard!$D$5) | E42: =SUMIFS(Calc!$Q$2:$Q$13,Calc!$B$2:$B$13,">"&(Exec_Dashboard!$D$5-12)) | F42: =SUMIFS(Calc!$Q$2:$Q$13,Calc!$B$2:$B$13,Exec_Dashboard!$D$5-1) | G42: — | H42: =C42-F42 | I42: =IF(C42>=F42,"GREEN",IF(C42>=0.95*F42,"YELLOW","RED"))
B43: Trouble Tickets | C43: =SUMIFS(Calc!$U$2:$U$13,Calc!$A$2:$A$13,Exec_Dashboard!$C$5) | D43: =SUMIFS(Calc!$U$2:$U$13,Calc!$B$2:$B$13,"<="&Exec_Dashboard!$D$5) | E43: =SUMIFS(Calc!$U$2:$U$13,Calc!$B$2:$B$13,">"&(Exec_Dashboard!$D$5-12)) | F43: =SUMIFS(Calc!$U$2:$U$13,Calc!$B$2:$B$13,Exec_Dashboard!$D$5-1) | G43: — | H43: =C43-F43 | I43: =IF(C43<=F43,"GREEN",IF(C43<=1.05*F43,"YELLOW","RED"))
B44: Activations | C44: =SUMIFS(Calc!$W$2:$W$13,Calc!$A$2:$A$13,Exec_Dashboard!$C$5) | D44: =SUMIFS(Calc!$W$2:$W$13,Calc!$B$2:$B$13,"<="&Exec_Dashboard!$D$5) | E44: =SUMIFS(Calc!$W$2:$W$13,Calc!$B$2:$B$13,">"&(Exec_Dashboard!$D$5-12)) | F44: =SUMIFS(Calc!$W$2:$W$13,Calc!$B$2:$B$13,Exec_Dashboard!$D$5-1) | G44: — | H44: =C44-F44 | I44: =IF(C44>=F44,"GREEN",IF(C44>=0.95*F44,"YELLOW","RED"))
B46: TOP OPEN RISKS (highest score) | G46: DECISIONS NEEDED FROM LEADERSHIP / BOARD
B47: Risk | C47: Score | D47: RYG | G47: Decision / Action | J47: Owner | K47: Priority
B48: =IFERROR(INDEX(Risk_Register!$B$4:$B$1003,MATCH(LARGE(Risk_Register!$F$4:$F$1003,1),Risk_Register!$F$4:$F$1003,0)),"") | D48: =LARGE(Risk_Register!$F$4:$F$1003,1) | E48: =IF(D48>=15,"RED",IF(D48>=8,"YELLOW","GREEN")) | G48: =IFERROR(INDEX(Board_Actions!$B$4:$B$1003,AGGREGATE(15,6,(ROW(Board_Actions!$I$4:$I$1003)-3)/((Board_Actions!$I$4:$I$1003="Yes")*(Board_Actions!$H$4:$H$1003<>"Complete")),1)),"") | J48: =IFERROR(INDEX(Board_Actions!$D$4:$D$1003,AGGREGATE(15,6,(ROW(Board_Actions!$I$4:$I$1003)-3)/((Board_Actions!$I$4:$I$1003="Yes")*(Board_Actions!$H$4:$H$1003<>"Complete")),1)),"") | K48: =IFERROR(INDEX(Board_Actions!$G$4:$G$1003,AGGREGATE(15,6,(ROW(Board_Actions!$I$4:$I$1003)-3)/((Board_Actions!$I$4:$I$1003="Yes")*(Board_Actions!$H$4:$H$1003<>"Complete")),1)),"")
B49: =IFERROR(INDEX(Risk_Register!$B$4:$B$1003,MATCH(LARGE(Risk_Register!$F$4:$F$1003,2),Risk_Register!$F$4:$F$1003,0)),"") | D49: =LARGE(Risk_Register!$F$4:$F$1003,2) | E49: =IF(D49>=15,"RED",IF(D49>=8,"YELLOW","GREEN")) | G49: =IFERROR(INDEX(Board_Actions!$B$4:$B$1003,AGGREGATE(15,6,(ROW(Board_Actions!$I$4:$I$1003)-3)/((Board_Actions!$I$4:$I$1003="Yes")*(Board_Actions!$H$4:$H$1003<>"Complete")),2)),"") | J49: =IFERROR(INDEX(Board_Actions!$D$4:$D$1003,AGGREGATE(15,6,(ROW(Board_Actions!$I$4:$I$1003)-3)/((Board_Actions!$I$4:$I$1003="Yes")*(Board_Actions!$H$4:$H$1003<>"Complete")),2)),"") | K49: =IFERROR(INDEX(Board_Actions!$G$4:$G$1003,AGGREGATE(15,6,(ROW(Board_Actions!$I$4:$I$1003)-3)/((Board_Actions!$I$4:$I$1003="Yes")*(Board_Actions!$H$4:$H$1003<>"Complete")),2)),"")
B50: =IFERROR(INDEX(Risk_Register!$B$4:$B$1003,MATCH(LARGE(Risk_Register!$F$4:$F$1003,3),Risk_Register!$F$4:$F$1003,0)),"") | D50: =LARGE(Risk_Register!$F$4:$F$1003,3) | E50: =IF(D50>=15,"RED",IF(D50>=8,"YELLOW","GREEN")) | G50: =IFERROR(INDEX(Board_Actions!$B$4:$B$1003,AGGREGATE(15,6,(ROW(Board_Actions!$I$4:$I$1003)-3)/((Board_Actions!$I$4:$I$1003="Yes")*(Board_Actions!$H$4:$H$1003<>"Complete")),3)),"") | J50: =IFERROR(INDEX(Board_Actions!$D$4:$D$1003,AGGREGATE(15,6,(ROW(Board_Actions!$I$4:$I$1003)-3)/((Board_Actions!$I$4:$I$1003="Yes")*(Board_Actions!$H$4:$H$1003<>"Complete")),3)),"") | K50: =IFERROR(INDEX(Board_Actions!$G$4:$G$1003,AGGREGATE(15,6,(ROW(Board_Actions!$I$4:$I$1003)-3)/((Board_Actions!$I$4:$I$1003="Yes")*(Board_Actions!$H$4:$H$1003<>"Complete")),3)),"")
B51: =IFERROR(INDEX(Risk_Register!$B$4:$B$1003,MATCH(LARGE(Risk_Register!$F$4:$F$1003,4),Risk_Register!$F$4:$F$1003,0)),"") | D51: =LARGE(Risk_Register!$F$4:$F$1003,4) | E51: =IF(D51>=15,"RED",IF(D51>=8,"YELLOW","GREEN")) | G51: =IFERROR(INDEX(Board_Actions!$B$4:$B$1003,AGGREGATE(15,6,(ROW(Board_Actions!$I$4:$I$1003)-3)/((Board_Actions!$I$4:$I$1003="Yes")*(Board_Actions!$H$4:$H$1003<>"Complete")),4)),"") | J51: =IFERROR(INDEX(Board_Actions!$D$4:$D$1003,AGGREGATE(15,6,(ROW(Board_Actions!$I$4:$I$1003)-3)/((Board_Actions!$I$4:$I$1003="Yes")*(Board_Actions!$H$4:$H$1003<>"Complete")),4)),"") | K51: =IFERROR(INDEX(Board_Actions!$G$4:$G$1003,AGGREGATE(15,6,(ROW(Board_Actions!$I$4:$I$1003)-3)/((Board_Actions!$I$4:$I$1003="Yes")*(Board_Actions!$H$4:$H$1003<>"Complete")),4)),"")
B52: =IFERROR(INDEX(Risk_Register!$B$4:$B$1003,MATCH(LARGE(Risk_Register!$F$4:$F$1003,5),Risk_Register!$F$4:$F$1003,0)),"") | D52: =LARGE(Risk_Register!$F$4:$F$1003,5) | E52: =IF(D52>=15,"RED",IF(D52>=8,"YELLOW","GREEN")) | G52: =IFERROR(INDEX(Board_Actions!$B$4:$B$1003,AGGREGATE(15,6,(ROW(Board_Actions!$I$4:$I$1003)-3)/((Board_Actions!$I$4:$I$1003="Yes")*(Board_Actions!$H$4:$H$1003<>"Complete")),5)),"") | J52: =IFERROR(INDEX(Board_Actions!$D$4:$D$1003,AGGREGATE(15,6,(ROW(Board_Actions!$I$4:$I$1003)-3)/((Board_Actions!$I$4:$I$1003="Yes")*(Board_Actions!$H$4:$H$1003<>"Complete")),5)),"") | K52: =IFERROR(INDEX(Board_Actions!$G$4:$G$1003,AGGREGATE(15,6,(ROW(Board_Actions!$I$4:$I$1003)-3)/((Board_Actions!$I$4:$I$1003="Yes")*(Board_Actions!$H$4:$H$1003<>"Complete")),5)),"")
...

Sheet Sales_Dashboard
A1: SALES MANAGEMENT DASHBOARD
A2: Leads → Qualified → Connects • pipeline, channels, counties, reps, goal vs actual • reporting month set on Exec Dashboard
B4: SALES KPIs (current reporting month)
B5: LEADS (MTD) | D5: QUALIFIED (MTD) | F5: CONVERSION RATE | H5: CONNECTS (MTD) | J5: GOAL (MTD) | L5: VARIANCE TO GOAL
B6: =SUMIFS(Sales_Data!$H$4:$H$1003,Sales_Data!$A$4:$A$1003,Exec_Dashboard!$C$5) | D6: =SUMIFS(Sales_Data!$I$4:$I$1003,Sales_Data!$A$4:$A$1003,Exec_Dashboard!$C$5) | F6: =IF(SUMIFS(Sales_Data!$H$4:$H$1003,Sales_Data!$A$4:$A$1003,Exec_Dashboard!$C$5)=0,0,SUMIFS(Sales_Data!$J$4:$J$1003,Sales_Data!$A$4:$A$1003,Exec_Dashboard!$C$5)/SUMIFS(Sales_Data!$H$4:$H$1003,Sales_Data!$A$4:$A$1003,Exec_Dashboard!$C$5)) | H6: =SUMIFS(Sales_Data!$J$4:$J$1003,Sales_Data!$A$4:$A$1003,Exec_Dashboard!$C$5) | J6: =SUMIFS(Sales_Targets!$C$4:$C$1003,Sales_Targets!$A$4:$A$1003,Exec_Dashboard!$C$5) | L6: =SUMIFS(Sales_Data!$J$4:$J$1003,Sales_Data!$A$4:$A$1003,Exec_Dashboard!$C$5)-SUMIFS(Sales_Targets!$C$4:$C$1003,Sales_Targets!$A$4:$A$1003,Exec_Dashboard!$C$5)
B7: Top of funnel | D7: Sales-qualified | F7: =IF(F6>=0.25,"GREEN",IF(F6>=0.15,"YELLOW","RED")) | H7: Closed-won units | J7: Monthly target | L7: =IF(L6>=0,"GREEN",IF(L6>=-0.1*SUMIFS(Sales_Targets!$C$4:$C$1003,Sales_Targets!$A$4:$A$1003,Exec_Dashboard!$C$5),"YELLOW","RED"))
B10: NEW MRR ADDED | D10: RESIDENTIAL SALES | F10: BUSINESS SALES | H10: PIPELINE VALUE (OPEN) | J10: CLOSED-WON (ARR) | L10: LOST OPPORTUNITIES
B11: =SUMIFS(Sales_Data!$K$4:$K$1003,Sales_Data!$A$4:$A$1003,Exec_Dashboard!$C$5) | D11: =SUMIFS(Sales_Data!$J$4:$J$1003,Sales_Data!$A$4:$A$1003,Exec_Dashboard!$C$5,Sales_Data!$D$4:$D$1003,"Residential") | F11: =SUMIFS(Sales_Data!$J$4:$J$1003,Sales_Data!$A$4:$A$1003,Exec_Dashboard!$C$5,Sales_Data!$D$4:$D$1003,"Business") | H11: =SUMIFS(Pipeline!$G$4:$G$1003,Pipeline!$F$4:$F$1003,"<>Closed-Won",Pipeline!$F$4:$F$1003,"<>Closed-Lost") | J11: =SUMIFS(Pipeline!$G$4:$G$1003,Pipeline!$F$4:$F$1003,"Closed-Won") | L11: =COUNTIFS(Pipeline!$F$4:$F$1003,"Closed-Lost")
B12: Recurring $ added | H12: =IF(H11>=1500000,"GREEN",IF(H11>=800000,"YELLOW","RED"))
B15: ENTERPRISE OPPS (OPEN) | D15: HOA / DEVELOPER OPPS | F15: BULK AGREEMENT OPPS | H15: DOOR KNOCKS (MTD) | J15: QUAL → CLOSE RATE | L15: AVG NEW MRR / CONNECT
B16: =COUNTIFS(Pipeline!$E$4:$E$1003,"Enterprise/DIA",Pipeline!$F$4:$F$1003,"<>Closed-Lost",Pipeline!$F$4:$F$1003,"<>Closed-Won") | D16: =COUNTIFS(Pipeline!$E$4:$E$1003,"HOA/Developer") | F16: =COUNTIFS(Pipeline!$E$4:$E$1003,"Bulk Agreement") | H16: =SUMIFS(Sales_Data!$L$4:$L$1003,Sales_Data!$A$4:$A$1003,Exec_Dashboard!$C$5) | J16: =IF(SUMIFS(Sales_Data!$I$4:$I$1003,Sales_Data!$A$4:$A$1003,Exec_Dashboard!$C$5)=0,0,SUMIFS(Sales_Data!$J$4:$J$1003,Sales_Data!$A$4:$A$1003,Exec_Dashboard!$C$5)/SUMIFS(Sales_Data!$I$4:$I$1003,Sales_Data!$A$4:$A$1003,Exec_Dashboard!$C$5)) | L16: =IF(SUMIFS(Sales_Data!$J$4:$J$1003,Sales_Data!$A$4:$A$1003,Exec_Dashboard!$C$5)=0,0,SUMIFS(Sales_Data!$K$4:$K$1003,Sales_Data!$A$4:$A$1003,Exec_Dashboard!$C$5)/SUMIFS(Sales_Data!$J$4:$J$1003,Sales_Data!$A$4:$A$1003,Exec_Dashboard!$C$5))
B17: DIA pipeline count | H17: D2D activity | J17: =IF(J16>=0.5,"GREEN",IF(J16>=0.3,"YELLOW","RED"))
B20: ANALYTICS
P60: Sales by County | S60: Sales by Channel | V60: Sales by Rep | Y60: Pipeline by Stage | AB60: Lost Reasons
P61: Category | Q61: Value | S61: Category | T61: Value | V61: Category | W61: Value | Y61: Category | Z61: Value | AB61: Category | AC61: Value
P62: Robeson | Q62: =SUMIFS(Sales_Data!$J$4:$J$1003,Sales_Data!$C$4:$C$1003,"Robeson") | S62: Door-to-Door | T62: =SUMIFS(Sales_Data!$J$4:$J$1003,Sales_Data!$E$4:$E$1003,"Door-to-Door") | V62: Maria Lopez | W62: =SUMIFS(Sales_Data!$J$4:$J$1003,Sales_Data!$G$4:$G$1003,"Maria Lopez") | Y62: Prospect | Z62: =SUMIFS(Pipeline!$G$4:$G$1003,Pipeline!$F$4:$F$1003,"Prospect") | AB62: Price | AC62: =COUNTIFS(Pipeline!$J$4:$J$1003,"Price")
P63: Hoke | Q63: =SUMIFS(Sales_Data!$J$4:$J$1003,Sales_Data!$C$4:$C$1003,"Hoke") | S63: Inbound Call | T63: =SUMIFS(Sales_Data!$J$4:$J$1003,Sales_Data!$E$4:$E$1003,"Inbound Call") | V63: James Carter | W63: =SUMIFS(Sales_Data!$J$4:$J$1003,Sales_Data!$G$4:$G$1003,"James Carter") | Y63: Qualified | Z63: =SUMIFS(Pipeline!$G$4:$G$1003,Pipeline!$F$4:$F$1003,"Qualified") | AB63: Competitor Fiber | AC63: =COUNTIFS(Pipeline!$J$4:$J$1003,"Competitor Fiber")
P64: Cumberland | Q64: =SUMIFS(Sales_Data!$J$4:$J$1003,Sales_Data!$C$4:$C$1003,"Cumberland") | S64: Website | T64: =SUMIFS(Sales_Data!$J$4:$J$1003,Sales_Data!$E$4:$E$1003,"Website") | V64: Tanya Hunt | W64: =SUMIFS(Sales_Data!$J$4:$J$1003,Sales_Data!$G$4:$G$1003,"Tanya Hunt") | Y64: Proposal | Z64: =SUMIFS(Pipeline!$G$4:$G$1003,Pipeline!$F$4:$F$1003,"Proposal") | AB64: No Coverage Yet | AC64: =COUNTIFS(Pipeline!$J$4:$J$1003,"No Coverage Yet")
P65: Scotland | Q65: =SUMIFS(Sales_Data!$J$4:$J$1003,Sales_Data!$C$4:$C$1003,"Scotland") | S65: Referral | T65: =SUMIFS(Sales_Data!$J$4:$J$1003,Sales_Data!$E$4:$E$1003,"Referral") | V65: Derek Oxendine | W65: =SUMIFS(Sales_Data!$J$4:$J$1003,Sales_Data!$G$4:$G$1003,"Derek Oxendine") | Y65: Negotiation | Z65: =SUMIFS(Pipeline!$G$4:$G$1003,Pipeline!$F$4:$F$1003,"Negotiation") | AB65: Timing | AC65: =COUNTIFS(Pipeline!$J$4:$J$1003,"Timing")
P66: Bladen | Q66: =SUMIFS(Sales_Data!$J$4:$J$1003,Sales_Data!$C$4:$C$1003,"Bladen") | S66: Event | T66: =SUMIFS(Sales_Data!$J$4:$J$1003,Sales_Data!$E$4:$E$1003,"Event") | V66: Sarah Locklear | W66: =SUMIFS(Sales_Data!$J$4:$J$1003,Sales_Data!$G$4:$G$1003,"Sarah Locklear") | Y66: Closed-Won | Z66: =SUMIFS(Pipeline!$G$4:$G$1003,Pipeline!$F$4:$F$1003,"Closed-Won") | AB66: Credit/Install Fee | AC66: =COUNTIFS(Pipeline!$J$4:$J$1003,"Credit/Install Fee")
P67: Columbus | Q67: =SUMIFS(Sales_Data!$J$4:$J$1003,Sales_Data!$C$4:$C$1003,"Columbus") | S67: HOA/Developer | T67: =SUMIFS(Sales_Data!$J$4:$J$1003,Sales_Data!$E$4:$E$1003,"HOA/Developer") | AB67: Lost Contact | AC67: =COUNTIFS(Pipeline!$J$4:$J$1003,"Lost Contact")
P75: Goal vs Actual (monthly)
P76: Month | Q76: Actual | R76: Goal
P77: =Sales_Targets!A4 | Q77: =SUMIFS(Sales_Data!$J$4:$J$1003,Sales_Data!$B$4:$B$1003,Sales_Targets!B4) | R77: =Sales_Targets!C4
P78: =Sales_Targets!A5 | Q78: =SUMIFS(Sales_Data!$J$4:$J$1003,Sales_Data!$B$4:$B$1003,Sales_Targets!B5) | R78: =Sales_Targets!C5
P79: =Sales_Targets!A6 | Q79: =SUMIFS(Sales_Data!$J$4:$J$1003,Sales_Data!$B$4:$B$1003,Sales_Targets!B6) | R79: =Sales_Targets!C6
P80: =Sales_Targets!A7 | Q80: =SUMIFS(Sales_Data!$J$4:$J$1003,Sales_Data!$B$4:$B$1003,Sales_Targets!B7) | R80: =Sales_Targets!C7
P81: =Sales_Targets!A8 | Q81: =SUMIFS(Sales_Data!$J$4:$J$1003,Sales_Data!$B$4:$B$1003,Sales_Targets!B8) | R81: =Sales_Targets!C8
P82: =Sales_Targets!A9 | Q82: =SUMIFS(Sales_Data!$J$4:$J$1003,Sales_Data!$B$4:$B$1003,Sales_Targets!B9) | R82: =Sales_Targets!C9
P83: =Sales_Targets!A10 | Q83: =SUMIFS(Sales_Data!$J$4:$J$1003,Sales_Data!$B$4:$B$1003,Sales_Targets!B10) | R83: =Sales_Targets!C10
P84: =Sales_Targets!A11 | Q84: =SUMIFS(Sales_Data!$J$4:$J$1003,Sales_Data!$B$4:$B$1003,Sales_Targets!B11) | R84: =Sales_Targets!C11
P85: =Sales_Targets!A12 | Q85: =SUMIFS(Sales_Data!$J$4:$J$1003,Sales_Data!$B$4:$B$1003,Sales_Targets!B12) | R85: =Sales_Targets!C12
P86: =Sales_Targets!A13 | Q86: =SUMIFS(Sales_Data!$J$4:$J$1003,Sales_Data!$B$4:$B$1003,Sales_Targets!B13) | R86: =Sales_Targets!C13
P87: =Sales_Targets!A14 | Q87: =SUMIFS(Sales_Data!$J$4:$J$1003,Sales_Data!$B$4:$B$1003,Sales_Targets!B14) | R87: =Sales_Targets!C14
P88: =Sales_Targets!A15 | Q88: =SUMIFS(Sales_Data!$J$4:$J$1003,Sales_Data!$B$4:$B$1003,Sales_Targets!B15) | R88: =Sales_Targets!C15

Sheet Ops_Dashboard
A1: OPERATIONS MANAGEMENT DASHBOARD
A2: Build → Drop → Install → Activate • trouble tickets, contractors, project health • reporting month set on Exec Dashboard
B4: OPERATIONS KPIs (current reporting month)
B5: HOMES PASSED ADDED | D5: FOOTAGE BUILT | F5: COST / HOME PASSED | H5: DROPS COMPLETED | J5: SPLICES COMPLETED | L5: ACTIVATIONS
B6: =SUMIFS(Operations_Data!$C$4:$C$1003,Operations_Data!$A$4:$A$1003,Exec_Dashboard!$C$5) | D6: =SUMIFS(Operations_Data!$D$4:$D$1003,Operations_Data!$A$4:$A$1003,Exec_Dashboard!$C$5) | F6: =IF(SUMIFS(Operations_Data!$C$4:$C$1003,Operations_Data!$A$4:$A$1003,Exec_Dashboard!$C$5)=0,0,SUMIFS(Financial_Data!$E$4:$E$1003,Financial_Data!$A$4:$A$1003,Exec_Dashboard!$C$5)/SUMIFS(Operations_Data!$C$4:$C$1003,Operations_Data!$A$4:$A$1003,Exec_Dashboard!$C$5)) | H6: =SUMIFS(Operations_Data!$E$4:$E$1003,Operations_Data!$A$4:$A$1003,Exec_Dashboard!$C$5) | J6: =SUMIFS(Operations_Data!$M$4:$M$1003,Operations_Data!$A$4:$A$1003,Exec_Dashboard!$C$5) | L6: =SUMIFS(Operations_Data!$L$4:$L$1003,Operations_Data!$A$4:$A$1003,Exec_Dashboard!$C$5)
B7: This month | D7: Linear feet | F7: =IF(F6<=700,"GREEN",IF(F6<=950,"YELLOW","RED"))
B10: INSTALLS SCHEDULED | D10: INSTALLS COMPLETED | F10: INSTALL BACKLOG | H10: AVG DAYS TO INSTALL | J10: TROUBLE TICKETS | L10: REPEAT TICKET %
B11: =SUMIFS(Operations_Data!$F$4:$F$1003,Operations_Data!$A$4:$A$1003,Exec_Dashboard!$C$5) | D11: =SUMIFS(Operations_Data!$G$4:$G$1003,Operations_Data!$A$4:$A$1003,Exec_Dashboard!$C$5) | F11: =SUMIFS(Operations_Data!$F$4:$F$1003,Operations_Data!$B$4:$B$1003,"<="&Exec_Dashboard!$D$5)-SUMIFS(Operations_Data!$G$4:$G$1003,Operations_Data!$B$4:$B$1003,"<="&Exec_Dashboard!$D$5) | H11: =AVERAGEIFS(Operations_Data!$H$4:$H$1003,Operations_Data!$A$4:$A$1003,Exec_Dashboard!$C$5) | J11: =SUMIFS(Operations_Data!$I$4:$I$1003,Operations_Data!$A$4:$A$1003,Exec_Dashboard!$C$5) | L11: =IF(SUMIFS(Operations_Data!$I$4:$I$1003,Operations_Data!$A$4:$A$1003,Exec_Dashboard!$C$5)=0,0,SUMIFS(Operations_Data!$J$4:$J$1003,Operations_Data!$A$4:$A$1003,Exec_Dashboard!$C$5)/SUMIFS(Operations_Data!$I$4:$I$1003,Operations_Data!$A$4:$A$1003,Exec_Dashboard!$C$5))
D12: =IF(D11>=SUMIFS(Operations_Data!$F$4:$F$1003,Operations_Data!$A$4:$A$1003,Exec_Dashboard!$C$5),"GREEN",IF(D11>=0.85*SUMIFS(Operations_Data!$F$4:$F$1003,Operations_Data!$A$4:$A$1003,Exec_Dashboard!$C$5),"YELLOW","RED")) | F12: =IF(F11<=200,"GREEN",IF(F11<=400,"YELLOW","RED")) | H12: =IF(H11<=7,"GREEN",IF(H11<=10,"YELLOW","RED")) | J12: =IF(J11<=250,"GREEN",IF(J11<=320,"YELLOW","RED")) | L12: =IF(L11<=0.1,"GREEN",IF(L11<=0.15,"YELLOW","RED"))
B15: OUTAGES (MTD) | D15: PROJECTS ON TRACK | F15: PROJECTS AT RISK | H15: PROJECTS BEHIND | J15: AVG PROJECT % COMPLETE | L15: AVG CONTRACTOR SCORE
B16: =SUMIFS(Operations_Data!$K$4:$K$1003,Operations_Data!$A$4:$A$1003,Exec_Dashboard!$C$5) | D16: =COUNTIFS(Project_Data!$F$4:$F$1003,"On Track") | F16: =COUNTIFS(Project_Data!$F$4:$F$1003,"At Risk") | H16: =COUNTIFS(Project_Data!$F$4:$F$1003,"Behind") | J16: =AVERAGE(Project_Data!$E$4:$E$1003) | L16: =AVERAGE(Project_Data!$Q$4:$Q$1003)
B17: =IF(B16<=2,"GREEN",IF(B16<=4,"YELLOW","RED")) | F17: =IF(F16=0,"GREEN",IF(F16<=2,"YELLOW","RED")) | H17: =IF(H16=0,"GREEN",IF(H16<=1,"YELLOW","RED")) | L17: =IF(L16>=8,"GREEN",IF(L16>=6.5,"YELLOW","RED"))
B20: PROJECT HEALTH & ANALYTICS
P60: Build Progress by Project
P61: Project | Q61: % Complete
P62: =Project_Data!A4 | Q62: =Project_Data!E4
P63: =Project_Data!A5 | Q63: =Project_Data!E5
P64: =Project_Data!A6 | Q64: =Project_Data!E6
P65: =Project_Data!A7 | Q65: =Project_Data!E7
P66: =Project_Data!A8 | Q66: =Project_Data!E8
P67: =Project_Data!A9 | Q67: =Project_Data!E9
P68: =Project_Data!A10 | Q68: =Project_Data!E10
P69: =Project_Data!A11 | Q69: =Project_Data!E11
P70: =Project_Data!A12 | Q70: =Project_Data!E12
P71: =Project_Data!A13 | Q71: =Project_Data!E13
P80: Project Status
P81: Status | Q81: Count
P82: On Track | Q82: =COUNTIFS(Project_Data!$F$4:$F$1003,"On Track")
P83: At Risk | Q83: =COUNTIFS(Project_Data!$F$4:$F$1003,"At Risk")
P84: Behind | Q84: =COUNTIFS(Project_Data!$F$4:$F$1003,"Behind")
P85: Complete | Q85: =COUNTIFS(Project_Data!$F$4:$F$1003,"Complete")
P90: Contractor Performance
P91: Contractor | Q91: Avg Score
P92: Cape Fear Underground | Q92: =IFERROR(AVERAGEIFS(Project_Data!$Q$4:$Q$1003,Project_Data!$P$4:$P$1003,"Cape Fear Underground"),0)
P93: FiberBuild Co | Q93: =IFERROR(AVERAGEIFS(Project_Data!$Q$4:$Q$1003,Project_Data!$P$4:$P$1003,"FiberBuild Co"),0)
P94: In-House Crew | Q94: =IFERROR(AVERAGEIFS(Project_Data!$Q$4:$Q$1003,Project_Data!$P$4:$P$1003,"In-House Crew"),0)
P95: Sandhill Construction | Q95: =IFERROR(AVERAGEIFS(Project_Data!$Q$4:$Q$1003,Project_Data!$P$4:$P$1003,"Sandhill Construction"),0)
P100: Trouble Tickets by Category (editable)
P101: Category | Q101: Count
P102: No Signal / Down | Q102: 92
...

Sheet Financial_Dashboard
A1: FINANCIAL MANAGEMENT DASHBOARD
A2: Revenue • CapEx/OpEx • budget vs actual • cash forecast • grant reimbursement • margin by service line • reporting month set on Exec Dashboard
B4: FINANCIAL KPIs (current reporting month)
B5: REVENUE (MTD) | D5: MRR | F5: ARPU | H5: CAPITAL SPEND (MTD) | J5: OPERATING EXPENSE | L5: LABOR COST
B6: =SUMIFS(Financial_Data!$C$4:$C$1003,Financial_Data!$A$4:$A$1003,Exec_Dashboard!$C$5) | D6: =SUMIFS(Financial_Data!$D$4:$D$1003,Financial_Data!$A$4:$A$1003,Exec_Dashboard!$C$5) | F6: =IF(SUMIFS(Customer_Data!$C$4:$C$1003,Customer_Data!$A$4:$A$1003,Exec_Dashboard!$C$5)=0,0,SUMIFS(Financial_Data!$D$4:$D$1003,Financial_Data!$A$4:$A$1003,Exec_Dashboard!$C$5)/SUMIFS(Customer_Data!$C$4:$C$1003,Customer_Data!$A$4:$A$1003,Exec_Dashboard!$C$5)) | H6: =SUMIFS(Financial_Data!$E$4:$E$1003,Financial_Data!$A$4:$A$1003,Exec_Dashboard!$C$5) | J6: =SUMIFS(Financial_Data!$F$4:$F$1003,Financial_Data!$A$4:$A$1003,Exec_Dashboard!$C$5) | L6: =SUMIFS(Financial_Data!$G$4:$G$1003,Financial_Data!$A$4:$A$1003,Exec_Dashboard!$C$5)
B7: =IF(B6>=SUMIFS(Financial_Data!$J$4:$J$1003,Financial_Data!$A$4:$A$1003,Exec_Dashboard!$C$5),"GREEN",IF(B6>=0.95*SUMIFS(Financial_Data!$J$4:$J$1003,Financial_Data!$A$4:$A$1003,Exec_Dashboard!$C$5),"YELLOW","RED")) | F7: =IF(F6>=75,"GREEN",IF(F6>=65,"YELLOW","RED")) | H7: =IF(H6<=SUMIFS(Financial_Data!$L$4:$L$1003,Financial_Data!$A$4:$A$1003,Exec_Dashboard!$C$5),"GREEN",IF(H6<=1.1*SUMIFS(Financial_Data!$L$4:$L$1003,Financial_Data!$A$4:$A$1003,Exec_Dashboard!$C$5),"YELLOW","RED")) | J7: =IF(J6<=SUMIFS(Financial_Data!$K$4:$K$1003,Financial_Data!$A$4:$A$1003,Exec_Dashboard!$C$5),"GREEN",IF(J6<=1.05*SUMIFS(Financial_Data!$K$4:$K$1003,Financial_Data!$A$4:$A$1003,Exec_Dashboard!$C$5),"YELLOW","RED"))
B10: CONTRACTOR COST | D10: GRANT REIMB (MTD) | F10: BUDGET VAR (REV) | H10: FORECAST VAR (REV) | J10: CASH (END OF MONTH) | L10: 90-DAY CASH NEED
B11: =SUMIFS(Financial_Data!$H$4:$H$1003,Financial_Data!$A$4:$A$1003,Exec_Dashboard!$C$5) | D11: =SUMIFS(Financial_Data!$I$4:$I$1003,Financial_Data!$A$4:$A$1003,Exec_Dashboard!$C$5) | F11: =SUMIFS(Financial_Data!$C$4:$C$1003,Financial_Data!$A$4:$A$1003,Exec_Dashboard!$C$5)-SUMIFS(Financial_Data!$J$4:$J$1003,Financial_Data!$A$4:$A$1003,Exec_Dashboard!$C$5) | H11: =SUMIFS(Financial_Data!$C$4:$C$1003,Financial_Data!$A$4:$A$1003,Exec_Dashboard!$C$5)-SUMIFS(Financial_Data!$M$4:$M$1003,Financial_Data!$A$4:$A$1003,Exec_Dashboard!$C$5) | J11: =SUMIFS(Financial_Data!$N$4:$N$1003,Financial_Data!$A$4:$A$1003,Exec_Dashboard!$C$5) | L11: =3*(SUMIFS(Financial_Data!$F$4:$F$1003,Financial_Data!$A$4:$A$1003,Exec_Dashboard!$C$5)+SUMIFS(Financial_Data!$E$4:$E$1003,Financial_Data!$A$4:$A$1003,Exec_Dashboard!$C$5)+SUMIFS(Financial_Data!$H$4:$H$1003,Financial_Data!$A$4:$A$1003,Exec_Dashboard!$C$5))-3*SUMIFS(Financial_Data!$M$4:$M$1003,Financial_Data!$A$4:$A$1003,Exec_Dashboard!$C$5)-SUM(Grant_Data!$E$4:$E$1003)-SUM(Grant_Data!$F$4:$F$1003)
F12: =IF(F11>=0,"GREEN",IF(F11>=-0.05*SUMIFS(Financial_Data!$J$4:$J$1003,Financial_Data!$A$4:$A$1003,Exec_Dashboard!$C$5),"YELLOW","RED")) | H12: =IF(H11>=-0.03*SUMIFS(Financial_Data!$M$4:$M$1003,Financial_Data!$A$4:$A$1003,Exec_Dashboard!$C$5),"GREEN",IF(H11>=-0.07*SUMIFS(Financial_Data!$M$4:$M$1003,Financial_Data!$A$4:$A$1003,Exec_Dashboard!$C$5),"YELLOW","RED")) | J12: =IF(J11>=3000000,"GREEN",IF(J11>=1500000,"YELLOW","RED")) | L12: =IF(L11<=SUMIFS(Financial_Data!$N$4:$N$1003,Financial_Data!$A$4:$A$1003,Exec_Dashboard!$C$5),"GREEN",IF(L11<=1.5*SUMIFS(Financial_Data!$N$4:$N$1003,Financial_Data!$A$4:$A$1003,Exec_Dashboard!$C$5),"YELLOW","RED"))
B15: COST / INSTALL | D15: COST / HOME PASSED | F15: GROSS MARGIN % | H15: REVENUE YTD | J15: CAPEX YTD | L15: GRANT REIMB YTD
B16: =IF(SUMIFS(Operations_Data!$G$4:$G$1003,Operations_Data!$A$4:$A$1003,Exec_Dashboard!$C$5)=0,0,SUMIFS(Financial_Data!$H$4:$H$1003,Financial_Data!$A$4:$A$1003,Exec_Dashboard!$C$5)/SUMIFS(Operations_Data!$G$4:$G$1003,Operations_Data!$A$4:$A$1003,Exec_Dashboard!$C$5)) | D16: =IF(SUMIFS(Operations_Data!$C$4:$C$1003,Operations_Data!$A$4:$A$1003,Exec_Dashboard!$C$5)=0,0,SUMIFS(Financial_Data!$E$4:$E$1003,Financial_Data!$A$4:$A$1003,Exec_Dashboard!$C$5)/SUMIFS(Operations_Data!$C$4:$C$1003,Operations_Data!$A$4:$A$1003,Exec_Dashboard!$C$5)) | F16: =IF(SUMIFS(Financial_Data!$C$4:$C$1003,Financial_Data!$A$4:$A$1003,Exec_Dashboard!$C$5)=0,0,(SUMIFS(Financial_Data!$C$4:$C$1003,Financial_Data!$A$4:$A$1003,Exec_Dashboard!$C$5)-(SUMIFS(Financial_Data!$F$4:$F$1003,Financial_Data!$A$4:$A$1003,Exec_Dashboard!$C$5)+SUMIFS(Financial_Data!$H$4:$H$1003,Financial_Data!$A$4:$A$1003,Exec_Dashboard!$C$5)))/SUMIFS(Financial_Data!$C$4:$C$1003,Financial_Data!$A$4:$A$1003,Exec_Dashboard!$C$5)) | H16: =SUMIFS(Financial_Data!$C$4:$C$1003,Financial_Data!$B$4:$B$1003,"<="&Exec_Dashboard!$D$5) | J16: =SUMIFS(Financial_Data!$E$4:$E$1003,Financial_Data!$B$4:$B$1003,"<="&Exec_Dashboard!$D$5) | L16: =SUMIFS(Financial_Data!$I$4:$I$1003,Financial_Data!$B$4:$B$1003,"<="&Exec_Dashboard!$D$5)
B17: =IF(B16<=600,"GREEN",IF(B16<=850,"YELLOW","RED")) | D17: =IF(D16<=700,"GREEN",IF(D16<=950,"YELLOW","RED")) | F17: =IF(F16>=0.4,"GREEN",IF(F16>=0.25,"YELLOW","RED"))
B20: FINANCIAL ANALYTICS
P60: Expense by Category (MTD)
P61: Category | Q61: Amount
P62: Labor | Q62: =SUMIFS(Financial_Data!$G$4:$G$1003,Financial_Data!$A$4:$A$1003,Exec_Dashboard!$C$5)
P63: Contractor | Q63: =SUMIFS(Financial_Data!$H$4:$H$1003,Financial_Data!$A$4:$A$1003,Exec_Dashboard!$C$5)
P64: Other OpEx | Q64: =SUMIFS(Financial_Data!$F$4:$F$1003,Financial_Data!$A$4:$A$1003,Exec_Dashboard!$C$5)-SUMIFS(Financial_Data!$G$4:$G$1003,Financial_Data!$A$4:$A$1003,Exec_Dashboard!$C$5)
P65: CapEx | Q65: =SUMIFS(Financial_Data!$E$4:$E$1003,Financial_Data!$A$4:$A$1003,Exec_Dashboard!$C$5)
P70: Revenue & Margin by Product (MTD)
P71: Product | Q71: Revenue | R71: Margin %
P72: Residential Internet | Q72: =SUMIFS(Revenue_Detail!$E$4:$E$1003,Revenue_Detail!$A$4:$A$1003,Exec_Dashboard!$C$5,Revenue_Detail!$C$4:$C$1003,"Residential Internet") | R72: =IF(SUMIFS(Revenue_Detail!$E$4:$E$1003,Revenue_Detail!$A$4:$A$1003,Exec_Dashboard!$C$5,Revenue_Detail!$C$4:$C$1003,"Residential Internet")=0,0,(SUMIFS(Revenue_Detail!$E$4:$E$1003,Revenue_Detail!$A$4:$A$1003,Exec_Dashboard!$C$5,Revenue_Detail!$C$4:$C$1003,"Residential Internet")-SUMIFS(Revenue_Detail!$F$4:$F$1003,Revenue_Detail!$A$4:$A$1003,Exec_Dashboard!$C$5,Revenue_Detail!$C$4:$C$1003,"Residential Internet"))/SUMIFS(Revenue_Detail!$E$4:$E$1003,Revenue_Detail!$A$4:$A$1003,Exec_Dashboard!$C$5,Revenue_Detail!$C$4:$C$1003,"Residential Internet"))
P73: Business Internet | Q73: =SUMIFS(Revenue_Detail!$E$4:$E$1003,Revenue_Detail!$A$4:$A$1003,Exec_Dashboard!$C$5,Revenue_Detail!$C$4:$C$1003,"Business Internet") | R73: =IF(SUMIFS(Revenue_Detail!$E$4:$E$1003,Revenue_Detail!$A$4:$A$1003,Exec_Dashboard!$C$5,Revenue_Detail!$C$4:$C$1003,"Business Internet")=0,0,(SUMIFS(Revenue_Detail!$E$4:$E$1003,Revenue_Detail!$A$4:$A$1003,Exec_Dashboard!$C$5,Revenue_Detail!$C$4:$C$1003,"Business Internet")-SUMIFS(Revenue_Detail!$F$4:$F$1003,Revenue_Detail!$A$4:$A$1003,Exec_Dashboard!$C$5,Revenue_Detail!$C$4:$C$1003,"Business Internet"))/SUMIFS(Revenue_Detail!$E$4:$E$1003,Revenue_Detail!$A$4:$A$1003,Exec_Dashboard!$C$5,Revenue_Detail!$C$4:$C$1003,"Business Internet"))
P74: Enterprise / DIA | Q74: =SUMIFS(Revenue_Detail!$E$4:$E$1003,Revenue_Detail!$A$4:$A$1003,Exec_Dashboard!$C$5,Revenue_Detail!$C$4:$C$1003,"Enterprise / DIA") | R74: =IF(SUMIFS(Revenue_Detail!$E$4:$E$1003,Revenue_Detail!$A$4:$A$1003,Exec_Dashboard!$C$5,Revenue_Detail!$C$4:$C$1003,"Enterprise / DIA")=0,0,(SUMIFS(Revenue_Detail!$E$4:$E$1003,Revenue_Detail!$A$4:$A$1003,Exec_Dashboard!$C$5,Revenue_Detail!$C$4:$C$1003,"Enterprise / DIA")-SUMIFS(Revenue_Detail!$F$4:$F$1003,Revenue_Detail!$A$4:$A$1003,Exec_Dashboard!$C$5,Revenue_Detail!$C$4:$C$1003,"Enterprise / DIA"))/SUMIFS(Revenue_Detail!$E$4:$E$1003,Revenue_Detail!$A$4:$A$1003,Exec_Dashboard!$C$5,Revenue_Detail!$C$4:$C$1003,"Enterprise / DIA"))
P75: Managed WiFi | Q75: =SUMIFS(Revenue_Detail!$E$4:$E$1003,Revenue_Detail!$A$4:$A$1003,Exec_Dashboard!$C$5,Revenue_Detail!$C$4:$C$1003,"Managed WiFi") | R75: =IF(SUMIFS(Revenue_Detail!$E$4:$E$1003,Revenue_Detail!$A$4:$A$1003,Exec_Dashboard!$C$5,Revenue_Detail!$C$4:$C$1003,"Managed WiFi")=0,0,(SUMIFS(Revenue_Detail!$E$4:$E$1003,Revenue_Detail!$A$4:$A$1003,Exec_Dashboard!$C$5,Revenue_Detail!$C$4:$C$1003,"Managed WiFi")-SUMIFS(Revenue_Detail!$F$4:$F$1003,Revenue_Detail!$A$4:$A$1003,Exec_Dashboard!$C$5,Revenue_Detail!$C$4:$C$1003,"Managed WiFi"))/SUMIFS(Revenue_Detail!$E$4:$E$1003,Revenue_Detail!$A$4:$A$1003,Exec_Dashboard!$C$5,Revenue_Detail!$C$4:$C$1003,"Managed WiFi"))
P76: Voice | Q76: =SUMIFS(Revenue_Detail!$E$4:$E$1003,Revenue_Detail!$A$4:$A$1003,Exec_Dashboard!$C$5,Revenue_Detail!$C$4:$C$1003,"Voice") | R76: =IF(SUMIFS(Revenue_Detail!$E$4:$E$1003,Revenue_Detail!$A$4:$A$1003,Exec_Dashboard!$C$5,Revenue_Detail!$C$4:$C$1003,"Voice")=0,0,(SUMIFS(Revenue_Detail!$E$4:$E$1003,Revenue_Detail!$A$4:$A$1003,Exec_Dashboard!$C$5,Revenue_Detail!$C$4:$C$1003,"Voice")-SUMIFS(Revenue_Detail!$F$4:$F$1003,Revenue_Detail!$A$4:$A$1003,Exec_Dashboard!$C$5,Revenue_Detail!$C$4:$C$1003,"Voice"))/SUMIFS(Revenue_Detail!$E$4:$E$1003,Revenue_Detail!$A$4:$A$1003,Exec_Dashboard!$C$5,Revenue_Detail!$C$4:$C$1003,"Voice"))
P77: Construction / Other | Q77: =SUMIFS(Revenue_Detail!$E$4:$E$1003,Revenue_Detail!$A$4:$A$1003,Exec_Dashboard!$C$5,Revenue_Detail!$C$4:$C$1003,"Construction / Other") | R77: =IF(SUMIFS(Revenue_Detail!$E$4:$E$1003,Revenue_Detail!$A$4:$A$1003,Exec_Dashboard!$C$5,Revenue_Detail!$C$4:$C$1003,"Construction / Other")=0,0,(SUMIFS(Revenue_Detail!$E$4:$E$1003,Revenue_Detail!$A$4:$A$1003,Exec_Dashboard!$C$5,Revenue_Detail!$C$4:$C$1003,"Construction / Other")-SUMIFS(Revenue_Detail!$F$4:$F$1003,Revenue_Detail!$A$4:$A$1003,Exec_Dashboard!$C$5,Revenue_Detail!$C$4:$C$1003,"Construction / Other"))/SUMIFS(Revenue_Detail!$E$4:$E$1003,Revenue_Detail!$A$4:$A$1003,Exec_Dashboard!$C$5,Revenue_Detail!$C$4:$C$1003,"Construction / Other"))
P82: Grant Reimbursement Pipeline
P83: Program | Q83: Received | R83: Outstanding
P84: BEAD | Q84: =SUMIFS(Grant_Data!$F$4:$F$1003,Grant_Data!$B$4:$B$1003,"BEAD") | R84: =SUMIFS(Grant_Data!$E$4:$E$1003,Grant_Data!$B$4:$B$1003,"BEAD")-SUMIFS(Grant_Data!$F$4:$F$1003,Grant_Data!$B$4:$B$1003,"BEAD")
P85: CAB | Q85: =SUMIFS(Grant_Data!$F$4:$F$1003,Grant_Data!$B$4:$B$1003,"CAB") | R85: =SUMIFS(Grant_Data!$E$4:$E$1003,Grant_Data!$B$4:$B$1003,"CAB")-SUMIFS(Grant_Data!$F$4:$F$1003,Grant_Data!$B$4:$B$1003,"CAB")
P86: ARPA | Q86: =SUMIFS(Grant_Data!$F$4:$F$1003,Grant_Data!$B$4:$B$1003,"ARPA") | R86: =SUMIFS(Grant_Data!$E$4:$E$1003,Grant_Data!$B$4:$B$1003,"ARPA")-SUMIFS(Grant_Data!$F$4:$F$1003,Grant_Data!$B$4:$B$1003,"ARPA")
P87: State Grant | Q87: =SUMIFS(Grant_Data!$F$4:$F$1003,Grant_Data!$B$4:$B$1003,"State Grant") | R87: =SUMIFS(Grant_Data!$E$4:$E$1003,Grant_Data!$B$4:$B$1003,"State Grant")-SUMIFS(Grant_Data!$F$4:$F$1003,Grant_Data!$B$4:$B$1003,"State Grant")
P88: RDOF | Q88: =SUMIFS(Grant_Data!$F$4:$F$1003,Grant_Data!$B$4:$B$1003,"RDOF") | R88: =SUMIFS(Grant_Data!$E$4:$E$1003,Grant_Data!$B$4:$B$1003,"RDOF")-SUMIFS(Grant_Data!$F$4:$F$1003,Grant_Data!$B$4:$B$1003,"RDOF")
P92: Capital Spend by Project
P93: Project | Q93: Spent
P94: =Project_Data!A4 | Q94: =Project_Data!L4
P95: =Project_Data!A5 | Q95: =Project_Data!L5
P96: =Project_Data!A6 | Q96: =Project_Data!L6
P97: =Project_Data!A7 | Q97: =Project_Data!L7
...

Sheet Board_Report
A1: QUARTERLY BOARD REPORT / MONTHLY COO REPORT
A3: ="Reporting Period: "&Exec_Dashboard!C5&" | Regional Fiber Broadband | Prepared by the COO | CONFIDENTIAL — Board of Directors"
A5: 1. EXECUTIVE SUMMARY
A6: ="For the period ending "&Exec_Dashboard!C5&", the company served "&TEXT(SUMIFS(Customer_Data!$C$4:$C$1003,Customer_Data!$A$4:$A$1003,Exec_Dashboard!$C$5),"#,##0")&" customers across the service area, a net change of "&TEXT(SUMIFS(Customer_Data!$D$4:$D$1003,Customer_Data!$A$4:$A$1003,Exec_Dashboard!$C$5)-SUMIFS(Customer_Data!$E$4:$E$1003,Customer_Data!$A$4:$A$1003,Exec_Dashboard!$C$5),"#,##0")&" connections ("&TEXT(SUMIFS(Customer_Data!$D$4:$D$1003,Customer_Data!$A$4:$A$1003,Exec_Dashboard!$C$5),"#,##0")&" new sales less "&TEXT(SUMIFS(Customer_Data!$E$4:$E$1003,Customer_Data!$A$4:$A$1003,Exec_Dashboard!$C$5),"#,##0")&" disconnects, churn "&TEXT(IF(SUMIFS(Customer_Data!$C$4:$C$1003,Customer_Data!$B$4:$B$1003,Exec_Dashboard!$D$5-1)=0,0,SUMIFS(Customer_Data!$E$4:$E$1003,Customer_Data!$A$4:$A$1003,Exec_Dashboard!$C$5)/SUMIFS(Customer_Data!$C$4:$C$1003,Customer_Data!$B$4:$B$1003,Exec_Dashboard!$D$5-1)),"0.0%")&"). Monthly revenue was "&TEXT(SUMIFS(Financial_Data!$C$4:$C$1003,Financial_Data!$A$4:$A$1003,Exec_Dashboard!$C$5),"$#,##0")&" against a budget of "&TEXT(SUMIFS(Financial_Data!$J$4:$J$1003,Financial_Data!$A$4:$A$1003,Exec_Dashboard!$C$5),"$#,##0")&" (variance "&TEXT(SUMIFS(Financial_Data!$C$4:$C$1003,Financial_Data!$A$4:$A$1003,Exec_Dashboard!$C$5)-SUMIFS(Financial_Data!$J$4:$J$1003,Financial_Data!$A$4:$A$1003,Exec_Dashboard!$C$5),"$#,##0")&"). Homes passed reached "&TEXT(SUMIFS(Customer_Data!$F$4:$F$1003,Customer_Data!$A$4:$A$1003,Exec_Dashboard!$C$5),"#,##0")&". Of "&(COUNTIFS(Project_Data!$F$4:$F$1003,"On Track")+COUNTIFS(Project_Data!$F$4:$F$1003,"At Risk")+COUNTIFS(Project_Data!$F$4:$F$1003,"Behind"))&" active capital projects, "&COUNTIFS(Project_Data!$F$4:$F$1003,"Behind")&" are behind schedule and "&COUNTIFS(Project_Data!$F$4:$F$1003,"At Risk")&" at risk. Installation backlog stands at "&TEXT(SUMIFS(Operations_Data!$F$4:$F$1003,Operations_Data!$B$4:$B$1003,"<="&Exec_Dashboard!$D$5)-SUMIFS(Operations_Data!$G$4:$G$1003,Operations_Data!$B$4:$B$1003,"<="&Exec_Dashboard!$D$5),"#,##0")&" orders with an average install time of "&TEXT(AVERAGEIFS(Operations_Data!$H$4:$H$1003,Operations_Data!$A$4:$A$1003,Exec_Dashboard!$C$5),"0.0")&" days. End-of-month cash was "&TEXT(SUMIFS(Financial_Data!$N$4:$N$1003,Financial_Data!$A$4:$A$1003,Exec_Dashboard!$C$5),"$#,##0")&". "&COUNTIFS(Risk_Register!$F$4:$F$1003,">=15")&" risk(s) are red and "&COUNTIFS(Board_Actions!$I$4:$I$1003,"Yes",Board_Actions!$H$4:$H$1003,"<>Complete")&" decision(s) require board attention."
A11: 2. WHAT IS GOING WELL / WHAT IS BEHIND / WHAT NEEDS EXECUTIVE ATTENTION
A12: ✅ Going Well | D12: ⚠️ Behind | F12: 🚩 Needs Executive Attention
A13: • Pembroke Core Ring & Lumberton MDU on/ahead of plan | D13: • Scotland RDOF build behind — grant drawdown at risk | F13: • Approve revolver draw to bridge BEAD reimbursement timing
A14: • ARPU trending up; margin healthy on residential & business | D14: • Columbus BEAD Zone 2 design rework slipping Milestone 1 | F14: • Authorize 2nd construction contractor (Scotland + Columbus)
A15: • BEAD Zone 1 drawdowns paid in full; strong grant execution | D15: • Install backlog rising vs crew capacity in Robeson | F15: • Approve install-crew headcount add to clear backlog
A16: • Avg days-to-install improving month over month | D16: • Make-ready / pole-attachment delays from utility | F16: • Ratify HOA / bulk pricing policy
A18: 3. FINANCIAL PERFORMANCE
A19: Metric | C19: Actual | D19: Budget | E19: Variance
A20: Revenue (MTD) | C20: =SUMIFS(Financial_Data!$C$4:$C$1003,Financial_Data!$A$4:$A$1003,Exec_Dashboard!$C$5) | D20: =SUMIFS(Financial_Data!$J$4:$J$1003,Financial_Data!$A$4:$A$1003,Exec_Dashboard!$C$5) | E20: =SUMIFS(Financial_Data!$C$4:$C$1003,Financial_Data!$A$4:$A$1003,Exec_Dashboard!$C$5)-SUMIFS(Financial_Data!$J$4:$J$1003,Financial_Data!$A$4:$A$1003,Exec_Dashboard!$C$5)
A21: Revenue (YTD) | C21: =SUMIFS(Financial_Data!$C$4:$C$1003,Financial_Data!$B$4:$B$1003,"<="&Exec_Dashboard!$D$5)
A22: MRR | C22: =SUMIFS(Financial_Data!$D$4:$D$1003,Financial_Data!$A$4:$A$1003,Exec_Dashboard!$C$5)
A23: Capital Spend (MTD) | C23: =SUMIFS(Financial_Data!$E$4:$E$1003,Financial_Data!$A$4:$A$1003,Exec_Dashboard!$C$5) | D23: =SUMIFS(Financial_Data!$L$4:$L$1003,Financial_Data!$A$4:$A$1003,Exec_Dashboard!$C$5) | E23: =SUMIFS(Financial_Data!$E$4:$E$1003,Financial_Data!$A$4:$A$1003,Exec_Dashboard!$C$5)-SUMIFS(Financial_Data!$L$4:$L$1003,Financial_Data!$A$4:$A$1003,Exec_Dashboard!$C$5)
A24: Operating Expense (MTD) | C24: =SUMIFS(Financial_Data!$F$4:$F$1003,Financial_Data!$A$4:$A$1003,Exec_Dashboard!$C$5) | D24: =SUMIFS(Financial_Data!$K$4:$K$1003,Financial_Data!$A$4:$A$1003,Exec_Dashboard!$C$5) | E24: =SUMIFS(Financial_Data!$F$4:$F$1003,Financial_Data!$A$4:$A$1003,Exec_Dashboard!$C$5)-SUMIFS(Financial_Data!$K$4:$K$1003,Financial_Data!$A$4:$A$1003,Exec_Dashboard!$C$5)
A25: Grant Reimb (YTD) | C25: =SUMIFS(Financial_Data!$I$4:$I$1003,Financial_Data!$B$4:$B$1003,"<="&Exec_Dashboard!$D$5)
A26: Cash (End of Month) | C26: =SUMIFS(Financial_Data!$N$4:$N$1003,Financial_Data!$A$4:$A$1003,Exec_Dashboard!$C$5)
A28: 4. CUSTOMER GROWTH & OPERATIONAL PERFORMANCE
A29: Customer | C29: Value | E29: Operations | H29: Value
A30: Total Customers | C30: =SUMIFS(Customer_Data!$C$4:$C$1003,Customer_Data!$A$4:$A$1003,Exec_Dashboard!$C$5) | E30: Installs Completed (MTD) | H30: =SUMIFS(Operations_Data!$G$4:$G$1003,Operations_Data!$A$4:$A$1003,Exec_Dashboard!$C$5)
A31: New Sales (MTD) | C31: =SUMIFS(Customer_Data!$D$4:$D$1003,Customer_Data!$A$4:$A$1003,Exec_Dashboard!$C$5) | E31: Install Backlog | H31: =SUMIFS(Operations_Data!$F$4:$F$1003,Operations_Data!$B$4:$B$1003,"<="&Exec_Dashboard!$D$5)-SUMIFS(Operations_Data!$G$4:$G$1003,Operations_Data!$B$4:$B$1003,"<="&Exec_Dashboard!$D$5)
A32: Disconnects (MTD) | C32: =SUMIFS(Customer_Data!$E$4:$E$1003,Customer_Data!$A$4:$A$1003,Exec_Dashboard!$C$5) | E32: Avg Days to Install | H32: =AVERAGEIFS(Operations_Data!$H$4:$H$1003,Operations_Data!$A$4:$A$1003,Exec_Dashboard!$C$5)
A33: Net Adds (MTD) | C33: =SUMIFS(Customer_Data!$D$4:$D$1003,Customer_Data!$A$4:$A$1003,Exec_Dashboard!$C$5)-SUMIFS(Customer_Data!$E$4:$E$1003,Customer_Data!$A$4:$A$1003,Exec_Dashboard!$C$5) | E33: Trouble Tickets (MTD) | H33: =SUMIFS(Operations_Data!$I$4:$I$1003,Operations_Data!$A$4:$A$1003,Exec_Dashboard!$C$5)
A34: Churn Rate | C34: =IF(SUMIFS(Customer_Data!$C$4:$C$1003,Customer_Data!$B$4:$B$1003,Exec_Dashboard!$D$5-1)=0,0,SUMIFS(Customer_Data!$E$4:$E$1003,Customer_Data!$A$4:$A$1003,Exec_Dashboard!$C$5)/SUMIFS(Customer_Data!$C$4:$C$1003,Customer_Data!$B$4:$B$1003,Exec_Dashboard!$D$5-1)) | E34: Outages (MTD) | H34: =SUMIFS(Operations_Data!$K$4:$K$1003,Operations_Data!$A$4:$A$1003,Exec_Dashboard!$C$5)
A35: Homes Passed | C35: =SUMIFS(Customer_Data!$F$4:$F$1003,Customer_Data!$A$4:$A$1003,Exec_Dashboard!$C$5) | E35: Active Projects | H35: =(COUNTIFS(Project_Data!$F$4:$F$1003,"On Track")+COUNTIFS(Project_Data!$F$4:$F$1003,"At Risk")+COUNTIFS(Project_Data!$F$4:$F$1003,"Behind"))
A36: Take Rate | C36: =IF(SUMIFS(Customer_Data!$F$4:$F$1003,Customer_Data!$A$4:$A$1003,Exec_Dashboard!$C$5)=0,0,SUMIFS(Customer_Data!$C$4:$C$1003,Customer_Data!$A$4:$A$1003,Exec_Dashboard!$C$5)/SUMIFS(Customer_Data!$F$4:$F$1003,Customer_Data!$A$4:$A$1003,Exec_Dashboard!$C$5)) | E36: Projects Behind / At Risk | H36: =COUNTIFS(Project_Data!$F$4:$F$1003,"Behind")+COUNTIFS(Project_Data!$F$4:$F$1003,"At Risk")
A38: 5. MAJOR CAPITAL PROJECT UPDATES
A39: Project | C39: County | D39: Status | E39: % Complete | F39: Capital Spent | G39: Blocker / Note
A40: =Project_Data!A4 | C40: =Project_Data!B4 | D40: =Project_Data!F4 | E40: =Project_Data!E4 | F40: =Project_Data!L4 | G40: =Project_Data!R4
A41: =Project_Data!A5 | C41: =Project_Data!B5 | D41: =Project_Data!F5 | E41: =Project_Data!E5 | F41: =Project_Data!L5 | G41: =Project_Data!R5
A42: =Project_Data!A6 | C42: =Project_Data!B6 | D42: =Project_Data!F6 | E42: =Project_Data!E6 | F42: =Project_Data!L6 | G42: =Project_Data!R6
A43: =Project_Data!A7 | C43: =Project_Data!B7 | D43: =Project_Data!F7 | E43: =Project_Data!E7 | F43: =Project_Data!L7 | G43: =Project_Data!R7
A44: =Project_Data!A8 | C44: =Project_Data!B8 | D44: =Project_Data!F8 | E44: =Project_Data!E8 | F44: =Project_Data!L8 | G44: =Project_Data!R8
A45: =Project_Data!A9 | C45: =Project_Data!B9 | D45: =Project_Data!F9 | E45: =Project_Data!E9 | F45: =Project_Data!L9 | G45: =Project_Data!R9
A46: =Project_Data!A10 | C46: =Project_Data!B10 | D46: =Project_Data!F10 | E46: =Project_Data!E10 | F46: =Project_Data!L10 | G46: =Project_Data!R10
A47: =Project_Data!A11 | C47: =Project_Data!B11 | D47: =Project_Data!F11 | E47: =Project_Data!E11 | F47: =Project_Data!L11 | G47: =Project_Data!R11
A48: =Project_Data!A12 | C48: =Project_Data!B12 | D48: =Project_Data!F12 | E48: =Project_Data!E12 | F48: =Project_Data!L12 | G48: =Project_Data!R12
A49: =Project_Data!A13 | C49: =Project_Data!B13 | D49: =Project_Data!F13 | E49: =Project_Data!E13 | F49: =Project_Data!L13 | G49: =Project_Data!R13
...

Sheet Customer_Data
A1: CUSTOMER DATA — Monthly Subscriber Roll-Up
A2: Enter ONE row per month. Total Customers = end-of-month subscriber count. Homes Passed = cumulative. Update weekly/at month close.
A3: Month | B3: Period | C3: Total Customers | D3: New Sales | E3: Disconnects | F3: Homes Passed (cum)
A4: Jul-2025 | B4: 1 | C4: 4619 | D4: 523 | E4: 84 | F4: 18725
A5: Aug-2025 | B5: 2 | C5: 4948 | D5: 430 | E5: 101 | F5: 19853
A6: Sep-2025 | B6: 3 | C6: 5260 | D6: 395 | E6: 83 | F6: 21445
A7: Oct-2025 | B7: 4 | C7: 5678 | D7: 499 | E7: 81 | F7: 22949
A8: Nov-2025 | B8: 5 | C8: 6072 | D8: 468 | E8: 74 | F8: 23879
A9: Dec-2025 | B9: 6 | C9: 6358 | D9: 383 | E9: 97 | F9: 25017
A10: Jan-2026 | B10: 7 | C10: 6774 | D10: 489 | E10: 73 | F10: 26491
A11: Feb-2026 | B11: 8 | C11: 7061 | D11: 410 | E11: 123 | F11: 27616
A12: Mar-2026 | B12: 9 | C12: 7430 | D12: 474 | E12: 105 | F12: 28522
A13: Apr-2026 | B13: 10 | C13: 7706 | D13: 400 | E13: 124 | F13: 29770
A14: May-2026 | B14: 11 | C14: 8048 | D14: 431 | E14: 89 | F14: 30890
A15: Jun-2026 | B15: 12 | C15: 8411 | D15: 446 | E15: 83 | F15: 31884

Sheet Sales_Data
A1: SALES DATA — Connects & Activity (one row per county / segment / month)
A2: Add rows as deals close. Sales = connects. New MRR = added recurring $. Use dropdowns for County / Segment / Channel / Campaign / Rep.
A3: Month | B3: Period | C3: County | D3: Segment | E3: Channel | F3: Campaign | G3: Rep | H3: Leads | I3: Qualified | J3: Sales (units) | K3: New MRR ($) | L3: Door Knocks
A4: Jul-2025 | B4: 1 | C4: Robeson | D4: Residential | E4: Website | F4: Referral Rewards | G4: James Carter | H4: 195 | I4: 135 | J4: 107 | K4: 8453 | L4: 16
A5: Jul-2025 | B5: 1 | C5: Hoke | D5: Residential | E5: HOA/Developer | F5: Referral Rewards | G5: Derek Oxendine | H5: 158 | I5: 119 | J5: 91 | K5: 7189 | L5: 0
A6: Jul-2025 | B6: 1 | C6: Cumberland | D6: Residential | E6: Event | F6: Spring Fiber Push | G6: Maria Lopez | H6: 206 | I6: 112 | J6: 91 | K6: 7189 | L6: 16
A7: Jul-2025 | B7: 1 | C7: Scotland | D7: Residential | E7: Website | F7: Spring Fiber Push | G7: James Carter | H7: 166 | I7: 100 | J7: 69 | K7: 5451 | L7: 10
A8: Jul-2025 | B8: 1 | C8: Bladen | D8: Residential | E8: Event | F8: Referral Rewards | G8: Sarah Locklear | H8: 179 | I8: 79 | J8: 71 | K8: 5609 | L8: 19
A9: Jul-2025 | B9: 1 | C9: Columbus | D9: Business | E9: Door-to-Door | F9: BEAD Awareness | G9: Tanya Hunt | H9: 153 | I9: 110 | J9: 95 | K9: 17100 | L9: 530
A10: Aug-2025 | B10: 2 | C10: Robeson | D10: Residential | E10: Referral | F10: Referral Rewards | G10: Maria Lopez | H10: 171 | I10: 87 | J10: 74 | K10: 5846 | L10: 53
A11: Aug-2025 | B11: 2 | C11: Hoke | D11: Residential | E11: Door-to-Door | F11: Referral Rewards | G11: James Carter | H11: 138 | I11: 88 | J11: 64 | K11: 5056 | L11: 529
A12: Aug-2025 | B12: 2 | C12: Cumberland | D12: Residential | E12: HOA/Developer | F12: Business Connect | G12: Sarah Locklear | H12: 127 | I12: 83 | J12: 75 | K12: 5925 | L12: 4
A13: Aug-2025 | B13: 2 | C13: Scotland | D13: Business | E13: HOA/Developer | F13: BEAD Awareness | G13: Sarah Locklear | H13: 166 | I13: 89 | J13: 79 | K13: 14220 | L13: 37
A14: Aug-2025 | B14: 2 | C14: Bladen | D14: Residential | E14: Referral | F14: BEAD Awareness | G14: Maria Lopez | H14: 165 | I14: 89 | J14: 62 | K14: 4898 | L14: 57
A15: Aug-2025 | B15: 2 | C15: Columbus | D15: Business | E15: Door-to-Door | F15: Referral Rewards | G15: James Carter | H15: 142 | I15: 99 | J15: 76 | K15: 13680 | L15: 331
... A75: Jun-2026 | B75: 12 | C75: Columbus | D75: Residential | E75: HOA/Developer | F75: BEAD Awareness | G75: Tanya Hunt | H75: 141 | I75: 102 | J75: 85 | K75: 6715 | L75: 3

Sheet Pipeline
A1: PIPELINE — Open & Recently-Closed Opportunities
A2: Value = annual recurring $ (ARR). Set Stage via dropdown. Closed-Lost rows require a Lost Reason. Enterprise/DIA, HOA/Developer, Bulk are Opp Types.
A3: Opp ID | B3: Name | C3: County | D3: Segment | E3: Type | F3: Stage | G3: Value (ARR $) | H3: Rep | I3: Close Month | J3: Lost Reason
A4: OPP-1001 | B4: Lumberton Business Park | C4: Robeson | D4: Business | E4: Standard | F4: Closed-Won | G4: 19873 | H4: Sarah Locklear | I4: May-2026
A5: OPP-1002 | B5: Pembroke Town Center Bulk | C5: Robeson | D5: Business | E5: Bulk Agreement | F5: Prospect | G5: 37780 | H5: Tanya Hunt | I5: Jun-2026
A6: OPP-1003 | B6: UNCP Campus DIA | C6: Robeson | D6: Enterprise | E6: Enterprise/DIA | F6: Closed-Lost | G6: 165515 | H6: Sarah Locklear | I6: Jun-2026 | J6: Timing
A7: OPP-1004 | B7: Raeford Logistics DIA | C7: Hoke | D7: Enterprise | E7: Enterprise/DIA | F7: Proposal | G7: 81087 | H7: Derek Oxendine | I7: Jun-2026
A8: OPP-1005 | B8: Maxton Industrial | C8: Robeson | D8: Business | E8: Standard | F8: Proposal | G8: 30123 | H8: Maria Lopez | I8: Jan-2026
A9: OPP-1006 | B9: Highland Trace HOA | C9: Cumberland | D9: Residential | E9: HOA/Developer | F9: Closed-Lost | G9: 30002 | H9: Sarah Locklear | I9: Mar-2026 | J9: Lost Contact
A10: OPP-1007 | B10: Saddlebrook Developer | C10: Hoke | D10: Residential | E10: HOA/Developer | F10: Qualified | G10: 68832 | H10: Maria Lopez | I10: Feb-2026
A11: OPP-1008 | B11: St. Pauls Clinic Group | C11: Robeson | D11: Business | E11: Standard | F11: Proposal | G11: 39834 | H11: Derek Oxendine | I11: Mar-2026
A12: OPP-1009 | B12: Laurinburg Logistics | C12: Scotland | D12: Enterprise | E12: Enterprise/DIA | F12: Closed-Lost | G12: 107576 | H12: Derek Oxendine | I12: Jun-2026 | J12: Price
A13: OPP-1010 | B13: Elizabethtown Retail | C13: Bladen | D13: Business | E13: Standard | F13: Qualified | G13: 39802 | H13: Tanya Hunt | I13: Mar-2026
A14: OPP-1011 | B14: Whiteville School District | C14: Columbus | D14: Enterprise | E14: Enterprise/DIA | F14: Prospect | G14: 235671 | H14: James Carter | I14: Mar-2026
A15: OPP-1012 | B15: Red Springs Apartments Bulk | C15: Robeson | D15: Residential | E15: Bulk Agreement | F15: Negotiation | G15: 41977 | H15: Tanya Hunt | I15: Jun-2026
A16: OPP-1013 | B16: Fayetteville Tech Park | C16: Cumberland | D16: Enterprise | E16: Enterprise/DIA | F16: Closed-Won | G16: 164976 | H16: Sarah Locklear | I16: Mar-2026
A17: OPP-1014 | B17: Shannon Farms Developer | C17: Robeson | D17: Residential | E17: HOA/Developer | F17: Prospect | G17: 44807 | H17: Tanya Hunt | I17: Mar-2026
A18: OPP-1015 | B18: Hope Mills Plaza | C18: Cumberland | D18: Business | E18: Standard | F18: Closed-Lost | G18: 16597 | H18: Derek Oxendine | I18: Mar-2026 | J18: Lost Contact
A19: OPP-1016 | B19: Rowland Manufacturing | C19: Robeson | D19: Business | E19: Standard | F19: Proposal | G19: 44559 | H19: Maria Lopez | I19: Feb-2026
A20: OPP-1017 | B20: Tar Heel Cold Storage | C20: Bladen | D20: Enterprise | E20: Enterprise/DIA | F20: Qualified | G20: 195905 | H20: Derek Oxendine | I20: Jun-2026
A21: OPP-1018 | B21: Parkton HOA Phase 2 | C21: Robeson | D21: Residential | E21: HOA/Developer | F21: Negotiation | G21: 43969 | H21: James Carter | I21: Mar-2026
A22: OPP-1019 | B22: Lumber River Medical | C22: Robeson | D22: Business | E22: Standard | F22: Prospect | G22: 44993 | H22: Tanya Hunt | I22: Apr-2026
A23: OPP-1020 | B23: Scotland Health DIA | C23: Scotland | D23: Enterprise | E23: Enterprise/DIA | F23: Prospect | G23: 187064 | H23: Sarah Locklear | I23: Feb-2026
A24: OPP-1021 | B24: Bladenboro Bulk MDU | C24: Bladen | D24: Residential | E24: Bulk Agreement | F24: Prospect | G24: 61516 | H24: Sarah Locklear | I24: Jan-2026
A25: OPP-1022 | B25: Chadbourn Town Hall | C25: Columbus | D25: Business | E25: Standard | F25: Prospect | G25: 35738 | H25: Maria Lopez | I25: Apr-2026
A26: OPP-1023 | B26: Aberdeen Distribution | C26: Hoke | D26: Enterprise | E26: Enterprise/DIA | F26: Negotiation | G26: 90793 | H26: James Carter | I26: Apr-2026
A27: OPP-1024 | B27: McColl Crossing HOA | C27: Scotland | D27: Residential | E27: HOA/Developer | F27: Negotiation | G27: 76122 | H27: Sarah Locklear | I27: Jun-2026
A28: OPP-1025 | B28: Fairmont Business Row | C28: Robeson | D28: Business | E28: Standard | F28: Proposal | G28: 26919 | H28: Derek Oxendine | I28: Apr-2026

Sheet Operations_Data
A1: OPERATIONS DATA — Monthly Build / Install / Service
A2: One row per month. Homes Passed Added = new this month. Avg Days to Install = order-to-activation. Repeat Tickets = re-opened within 30 days.
A3: Month | B3: Period | C3: Homes Passed Added | D3: Footage Built | E3: Drops Completed | F3: Installs Scheduled | G3: Installs Completed | H3: Avg Days to Install | I3: Trouble Tickets | J3: Repeat Tickets | K3: Outages | L3: Activations | M3: Splices Completed
A4: Jul-2025 | B4: 1 | C4: 1419 | D4: 51035 | E4: 574 | F4: 621 | G4: 534 | H4: 10.3 | I4: 315 | J4: 48 | K4: 5 | L4: 524 | M4: 245
A5: Aug-2025 | B5: 2 | C5: 919 | D5: 45331 | E5: 450 | F5: 477 | G5: 391 | H5: 7.9 | I5: 241 | J5: 36 | K5: 1 | L5: 389 | M5: 244
A6: Sep-2025 | B6: 3 | C6: 970 | D6: 46241 | E6: 487 | F6: 531 | G6: 407 | H6: 12.6 | I6: 222 | J6: 22 | K6: 5 | L6: 394 | M6: 174
A7: Oct-2025 | B7: 4 | C7: 1452 | D7: 51182 | E7: 545 | F7: 553 | G7: 474 | H7: 12.7 | I7: 275 | J7: 31 | K7: 5 | L7: 460 | M7: 150
A8: Nov-2025 | B8: 5 | C8: 1153 | D8: 52725 | E8: 506 | F8: 567 | G8: 484 | H8: 9.6 | I8: 238 | J8: 30 | K8: 1 | L8: 482 | M8: 135
A9: Dec-2025 | B9: 6 | C9: 1134 | D9: 42417 | E9: 408 | F9: 390 | G9: 346 | H9: 5.7 | I9: 240 | J9: 24 | K9: 4 | L9: 340 | M9: 258
A10: Jan-2026 | B10: 7 | C10: 1035 | D10: 68976 | E10: 574 | F10: 634 | G10: 494 | H10: 10.7 | I10: 228 | J10: 19 | K10: 6 | L10: 481 | M10: 210
A11: Feb-2026 | B11: 8 | C11: 1333 | D11: 64941 | E11: 427 | F11: 534 | G11: 401 | H11: 9.5 | I11: 205 | J11: 17 | K11: 6 | L11: 391 | M11: 147
A12: Mar-2026 | B12: 9 | C12: 1154 | D12: 50556 | E12: 559 | F12: 590 | G12: 482 | H12: 5.5 | I12: 226 | J12: 23 | K12: 2 | L12: 480 | M12: 233
A13: Apr-2026 | B13: 10 | C13: 1463 | D13: 44416 | E13: 506 | F13: 540 | G13: 417 | H13: 10.1 | I13: 203 | J13: 31 | K13: 2 | L13: 412 | M13: 224
A14: May-2026 | B14: 11 | C14: 1397 | D14: 69546 | E14: 465 | F14: 529 | G14: 438 | H14: 5.2 | I14: 180 | J14: 28 | K14: 3 | L14: 424 | M14: 193
A15: Jun-2026 | B15: 12 | C15: 1333 | D15: 69894 | E15: 514 | F15: 521 | G15: 457 | H15: 5.3 | I15: 194 | J15: 24 | K15: 5 | L15: 456 | M15: 200

Sheet Project_Data
A1: PROJECT DATA — Capital Build Projects
A2: One row per capital project. % Complete 0-1. Status drives RYG. Permitting / Make-Ready / Splicing use Build Phase dropdown. Contractor Score 0-10.
A3: Project | B3: County | C3: Type | D3: Grant Program | E3: % Complete | F3: Status | G3: Homes Passed Target | H3: Homes Passed Actual | I3: Footage Target | J3: Footage Built | K3: Capital Budget | L3: Capital Spent | M3: Permitting | N3: Make-Ready | O3: Splicing | P3: Contractor | Q3: Contractor Score | R3: Blocker / Note
A4: Robeson BEAD Zone 1 | B4: Robeson | C4: Greenfield | D4: BEAD | E4: 0.78 | F4: On Track | G4: 3200 | H4: 2496 | I4: 165000 | J4: 128700 | K4: 4100000 | L4: 3050000 | M4: Complete | N4: Complete | O4: In Progress | P4: FiberBuild Co | Q4: 8.6
