Workbook

Sheet Executive Dashboard
A1: RIVR TECH — 2027 REVENUE FORECAST DASHBOARD
A2: LREMC Technologies, LLC d/b/a RIVR Tech · Rural broadband & fiber · Robeson, Hoke, Scotland, Cumberland & surrounding NC counties
B3: Active scenario: | C3: ='Key Assumptions'!$B$4 -> Base | F3: Hoke County project (2027): | H3: ='Consolidated Revenue'!N26 -> 684000 | J3: (calibrated to H1-2026 actuals)
B5: 2027 TOTAL REVENUE | E5: RESIDENTIAL REVENUE | H5: BUSINESS REVENUE | K5: DARK FIBER REVENUE | N5: DEC MRR
B6: ='Consolidated Revenue'!N33 -> 5162584.3 | E6: ='Consolidated Revenue'!N10 -> 3891845.9 | H6: ='Consolidated Revenue'!N16 -> 567598.38 | K6: ='Consolidated Revenue'!N23 -> 19140 | N6: ='Consolidated Revenue'!M36 -> 434711.56
B8: DEC ARR RUN RATE | E8: ENDING RES SUBS | H8: ENDING BUS CUST | K8: ACTIVE DF CONTRACTS | N8: RES NET ADDS
B9: ='Consolidated Revenue'!M37 -> 5216538.8 | E9: ='Residential Forecast'!M12 -> 4072 | H9: ='Business Forecast'!M13 -> 274 | K9: =COUNTIF('Dark Fiber Forecast'!AE8:AE32,"GREEN")+COUNTIF('Dark Fiber Forecast'!AE8:AE32,"YELLOW*")+COUNTIF('Dark Fiber Forecast'!AE8:AE32,"RED*") -> 1 | N9: ='Residential Forecast'!M12-'Residential Forecast'!B6 -> 24
B11: BUS NET ADDS | E11: AVG RES ARPU | H11: AVG BUS ARPU | K11: RES CHURN % | N11: BUS CHURN %
B12: ='Business Forecast'!M13-'Business Forecast'!B6 -> 25 | E12: ='Residential Forecast'!N28 -> 75.11 | H12: ='Business Forecast'!N39 -> 160.915 | K12: ='Key Assumptions'!$B$18*'Key Assumptions'!$C$12 -> 0.015 | N12: ='Key Assumptions'!$B$38*'Key Assumptions'!$F$12 -> 0.01
A60: Chart data (auto)
A61: Residential | B61: ='Consolidated Revenue'!N10 -> 3891845.9
A62: Business | B62: ='Consolidated Revenue'!N16 -> 567598.38
A63: Dark Fiber | B63: ='Consolidated Revenue'!N23 -> 19140
A64: Project/Other | B64: ='Consolidated Revenue'!N26 -> 684000
A65: Conservative | B65: ='Scenario Analysis'!N19 -> 4901645.2
A66: Base | B66: ='Scenario Analysis'!N35 -> 5162584.3
A67: Aggressive | B67: ='Scenario Analysis'!N51 -> 5425057.9

Sheet Key Assumptions
A1: KEY ASSUMPTIONS — RIVR Tech 2027 Revenue Forecast
A2: All blue cells are editable inputs. Yellow = key assumption / management input required. Do not overwrite grey formula cells.
A3: SCENARIO SELECTION | L3: LEGEND
A4: Active Scenario (select) | B4: Base | L4: Editable input
A5: Scenario index (auto) | B5: =MATCH($B$4,$A$8:$A$10,0) -> 1 | L5: Key assumption / fill-in
L6: Calculated (do not edit)
A7: Scenario | B7: Res Adds | C7: Res Churn | D7: Res ARPU | E7: Bus Adds | F7: Bus Churn | G7: Bus ARPU | H7: DF Recur | I7: DF Timing(mo) | J7: Install/Constr | L7: Cross-sheet link
A8: Base | B8: 1 | C8: 1 | D8: 1 | E8: 1 | F8: 1 | G8: 1 | H8: 1 | I8: 0 | J8: 1
A9: Conservative | B9: 0.85 | C9: 1.2 | D9: 0.97 | E9: 0.85 | F9: 1.2 | G9: 0.97 | H9: 0.9 | I9: 1 | J9: 0.8
A10: Aggressive | B10: 1.15 | C10: 0.85 | D10: 1.03 | E10: 1.15 | F10: 0.85 | G10: 1.03 | H10: 1.1 | I10: -1 | J10: 1.2
A12: ACTIVE MULTIPLIERS (auto) | B12: =INDEX(B8:B10,$B$5) -> 1 | C12: =INDEX(C8:C10,$B$5) -> 1 | D12: =INDEX(D8:D10,$B$5) -> 1 | E12: =INDEX(E8:E10,$B$5) -> 1 | F12: =INDEX(F8:F10,$B$5) -> 1 | G12: =INDEX(G8:G10,$B$5) -> 1 | H12: =INDEX(H8:H10,$B$5) -> 1 | I12: =INDEX(I8:I10,$B$5) -> 0 | J12: =INDEX(J8:J10,$B$5) -> 1
A14: RESIDENTIAL ASSUMPTIONS
A16: Beginning residential subscribers (12/31/2026) | B16: =ROUND('2026 Actuals (H1)'!E6/B21,0) -> 4048 | C16: ← calibrated from actuals
A17: Monthly gross additions | B17: 60
A18: Monthly churn % | B18: 0.015
A19: Monthly other disconnects (non-churn) | B19: 5
A20: Monthly reconnects | B20: 8
A21: Residential ARPU ($/mo) | B21: 74
A22: ARPU increase month (1-12) | B22: 7
A23: ARPU increase % | B23: 0.03
A24: Installation revenue per new customer | B24: 99
A25: Upgrade revenue per customer | B25: 25
A26: % customers purchasing upgrades (monthly) | B26: 0.02
A27: Promotional discount % of recurring | B27: 0.02
A28: Bad-debt / collection adj % of gross | B28: 0.01
A29: Other residential revenue ($/mo, fixed) | B29: ='2026 Actuals (H1)'!E8+'2026 Actuals (H1)'!E9 -> 13305.833
A30: Voice / additional svc revenue ($/cust/mo) | B30: =ROUND('2026 Actuals (H1)'!E7/B16,2) -> 1.96
A31: Revenue recognition convention | B31: Average
A33: BUSINESS ASSUMPTIONS
A35: Beginning business customers (12/31/2026) | B35: =ROUND('2026 Actuals (H1)'!E13/B41,0) -> 249 | C35: ← calibrated from actuals
A36: Monthly gross additions - small business | B36: 4
A37: Monthly gross additions - enterprise | B37: 1
A38: Monthly churn % | B38: 0.01
A39: Monthly other disconnects (non-churn) | B39: 2
A40: Monthly reconnects | B40: 2
A41: Business ARPU ($/mo) | B41: 149
A42: ARPU increase month (1-12) | B42: 7
A43: ARPU increase % | B43: 0.03
A44: Installation & construction rev per new cust | B44: 500
A45: Static IP revenue ($/cust/mo) | B45: 0
...

Sheet 2026 Actuals (H1)
A1: 2026 ACTUALS — Income Statement (H1, QTR ending June 30, 2026)
A2: Source data from RIVR Tech income statement. Blue = actuals as reported; grey = derived (YTD, monthly run-rate, annualized). Feeds the 2027 model calibration.
B4: Qtr 1 | C4: Qtr 2 | D4: YTD | E4: Monthly Avg | F4: Annualized
A5: OPERATING REVENUE — RESIDENTIAL
A6: Residential Broadband | B6: 937587 | C6: 859936 | D6: =B6+C6 -> 1797523 | E6: =D6/6 -> 299587.17 | F6: =E6*12 -> 3595046
A7: Residential Voice | B7: 23659 | C7: 24039 | D7: =B7+C7 -> 47698 | E7: =D7/6 -> 7949.6667 | F7: =E7*12 -> 95396
A8: Residential Wifi | B8: 721 | C8: 714 | D8: =B8+C8 -> 1435 | E8: =D8/6 -> 239.16667 | F8: =E8*12 -> 2870
A9: Residential Other | B9: 36481 | C9: 41919 | D9: =B9+C9 -> 78400 | E9: =D9/6 -> 13066.667 | F9: =E9*12 -> 156800
A10: Less ACP Credits | B10: 0 | C10: 0 | D10: =B10+C10 -> 0 | E10: =D10/6 -> 0 | F10: =E10*12 -> 0
A11: Total Residential | B11: =B6+B7+B8+B9-B10 -> 998448 | C11: =C6+C7+C8+C9-C10 -> 926608 | D11: =B11+C11 -> 1925056 | E11: =D11/6 -> 320842.67 | F11: =E11*12 -> 3850112
A12: OPERATING REVENUE — BUSINESS
A13: Business Broadband | B13: 109308 | C13: 113631 | D13: =B13+C13 -> 222939 | E13: =D13/6 -> 37156.5 | F13: =E13*12 -> 445878
A14: Business Voice | B14: 7167 | C14: 7289 | D14: =B14+C14 -> 14456 | E14: =D14/6 -> 2409.3333 | F14: =E14*12 -> 28912
A15: Business Wifi | B15: 0 | C15: 0 | D15: =B15+C15 -> 0 | E15: =D15/6 -> 0 | F15: =E15*12 -> 0
A16: Business Other | B16: -277 | C16: -830 | D16: =B16+C16 -> -1107 | E16: =D16/6 -> -184.5 | F16: =E16*12 -> -2214
A17: Total Business | B17: =B13+B14+B15+B16 -> 116198 | C17: =C13+C14+C15+C16 -> 120090 | D17: =B17+C17 -> 236288 | E17: =D17/6 -> 39381.333 | F17: =E17*12 -> 472576
A18: Dark Fiber | B18: 6960 | C18: 2610 | D18: =B18+C18 -> 9570 | E18: =D18/6 -> 1595 | F18: =E18*12 -> 19140
A19: Total Operating Revenue | B19: =B11+B17+B18 -> 1121606 | C19: =C11+C17+C18 -> 1049308 | D19: =B19+C19 -> 2170914 | E19: =D19/6 -> 361819 | F19: =E19*12 -> 4341828
A21: EXPENSES
A22: Cost of Goods Sold | B22: 198002 | C22: 123244 | D22: =B22+C22 -> 321246 | E22: =D22/6 -> 53541 | F22: =E22*12 -> 642492
A23: LREMC Intercompany Expenses | B23: 10483 | C23: 179793 | D23: =B23+C23 -> 190276 | E23: =D23/6 -> 31712.667 | F23: =E23*12 -> 380552
A24: Engineering & Operations | B24: 193141 | C24: 239129 | D24: =B24+C24 -> 432270 | E24: =D24/6 -> 72045 | F24: =E24*12 -> 864540
A25: Marketing | B25: 75988 | C25: 83218 | D25: =B25+C25 -> 159206 | E25: =D25/6 -> 26534.333 | F25: =E25*12 -> 318412
A26: Sales and Customer Support | B26: 59317 | C26: 57351 | D26: =B26+C26 -> 116668 | E26: =D26/6 -> 19444.667 | F26: =E26*12 -> 233336
A27: General and Admin | B27: 311772 | C27: 436254 | D27: =B27+C27 -> 748026 | E27: =D27/6 -> 124671 | F27: =E27*12 -> 1496052
A28: Accounting | B28: 26972 | C28: 35185 | D28: =B28+C28 -> 62157 | E28: =D28/6 -> 10359.5 | F28: =E28*12 -> 124314
A29: HR Support | B29: 36322 | C29: 42959 | D29: =B29+C29 -> 79281 | E29: =D29/6 -> 13213.5 | F29: =E29*12 -> 158562
A30: IT Support | B30: 9495 | C30: 10026 | D30: =B30+C30 -> 19521 | E30: =D30/6 -> 3253.5 | F30: =E30*12 -> 39042
A31: Depreciation and Amortization | B31: 82166 | C31: 99236 | D31: =B31+C31 -> 181402 | E31: =D31/6 -> 30233.667 | F31: =E31*12 -> 362804
A32: Taxes | B32: 4188 | C32: 2865 | D32: =B32+C32 -> 7053 | E32: =D32/6 -> 1175.5 | F32: =E32*12 -> 14106
A33: Total Expenses | B33: =SUM(B22:B32) -> 1007846 | C33: =SUM(C22:C32) -> 1309260 | D33: =B33+C33 -> 2317106 | E33: =D33/6 -> 386184.33 | F33: =E33*12 -> 4634212
A34: Operating Income (loss) | B34: =B19-B33 -> 113760 | C34: =C19-C33 -> -259952 | D34: =B34+C34 -> -146192 | E34: =D34/6 -> -24365.333 | F34: =E34*12 -> -292384
A36: NONOPERATING REVENUE (EXPENSE)
A37: Grant Income | B37: 196019 | C37: 196019 | D37: =B37+C37 -> 392038
A38: BTAP Revenue | B38: 44566 | C38: 6120 | D38: =B38+C38 -> 50686
A39: CAB Revenue | B39: 0 | C39: 48171 | D39: =B39+C39 -> 48171
A40: Other Income | B40: -1500 | C40: 0 | D40: =B40+C40 -> -1500
A41: CAB Grant Expense | B41: -3622 | C41: -2304 | D41: =B41+C41 -> -5926
A42: BTAP Grant Expense | B42: 0 | C42: 0 | D42: =B42+C42 -> 0
A43: BEAD Grant Expense | B43: 114241 | C43: 3032 | D43: =B43+C43 -> 117273
...

Sheet Residential Forecast
A1: RESIDENTIAL BROADBAND FORECAST — 2027
A2: Monthly customer roll-forward and revenue. Grey = formulas (do not edit); edit assumptions on Key Assumptions.
A3: Metric | B3: 46388 | C3: 46419 | D3: 46447 | E3: 46478 | F3: 46508 | G3: 46539 | H3: 46569 | I3: 46600 | J3: 46631 | K3: 46661 | L3: 46692 | M3: 46722 | N3: FY 2027
A4: Month # | B4: 1 | C4: 2 | D4: 3 | E4: 4 | F4: 5 | G4: 6 | H4: 7 | I4: 8 | J4: 9 | K4: 10 | L4: 11 | M4: 12
A5: CUSTOMER MOVEMENT
A6: Beginning subscribers | B6: ='Key Assumptions'!$B$16 -> 4048 | C6: =B12 -> 4050 | D6: =C12 -> 4052 | E6: =D12 -> 4054 | F6: =E12 -> 4056 | G6: =F12 -> 4058 | H6: =G12 -> 4060 | I6: =H12 -> 4062 | J6: =I12 -> 4064 | ... M6: =L12 -> 4070 | N6: =B6 -> 4048
A7: Gross additions | B7: =ROUND('Key Assumptions'!$B$17*'Key Assumptions'!$B$12,0) -> 60 | C7: =ROUND('Key Assumptions'!$B$17*'Key Assumptions'!$B$12,0) -> 60 | D7: =ROUND('Key Assumptions'!$B$17*'Key Assumptions'!$B$12,0) -> 60 | E7: =ROUND('Key Assumptions'!$B$17*'Key Assumptions'!$B$12,0) -> 60 | F7: =ROUND('Key Assumptions'!$B$17*'Key Assumptions'!$B$12,0) -> 60 | G7: =ROUND('Key Assumptions'!$B$17*'Key Assumptions'!$B$12,0) -> 60 | H7: =ROUND('Key Assumptions'!$B$17*'Key Assumptions'!$B$12,0) -> 60 | I7: =ROUND('Key Assumptions'!$B$17*'Key Assumptions'!$B$12,0) -> 60 | ... M7: =ROUND('Key Assumptions'!$B$17*'Key Assumptions'!$B$12,0) -> 60 | N7: =SUM(B7:M7) -> 720
A8: Reconnects | B8: ='Key Assumptions'!$B$20 -> 8 | C8: ='Key Assumptions'!$B$20 -> 8 | D8: ='Key Assumptions'!$B$20 -> 8 | E8: ='Key Assumptions'!$B$20 -> 8 | F8: ='Key Assumptions'!$B$20 -> 8 | G8: ='Key Assumptions'!$B$20 -> 8 | H8: ='Key Assumptions'!$B$20 -> 8 | I8: ='Key Assumptions'!$B$20 -> 8 | ... M8: ='Key Assumptions'!$B$20 -> 8 | N8: =SUM(B8:M8) -> 96
A9: Disconnects from churn | B9: =ROUND(B6*'Key Assumptions'!$B$18*'Key Assumptions'!$C$12,0) -> 61 | C9: =ROUND(C6*'Key Assumptions'!$B$18*'Key Assumptions'!$C$12,0) -> 61 | D9: =ROUND(D6*'Key Assumptions'!$B$18*'Key Assumptions'!$C$12,0) -> 61 | E9: =ROUND(E6*'Key Assumptions'!$B$18*'Key Assumptions'!$C$12,0) -> 61 | F9: =ROUND(F6*'Key Assumptions'!$B$18*'Key Assumptions'!$C$12,0) -> 61 | G9: =ROUND(G6*'Key Assumptions'!$B$18*'Key Assumptions'!$C$12,0) -> 61 | H9: =ROUND(H6*'Key Assumptions'!$B$18*'Key Assumptions'!$C$12,0) -> 61 | I9: =ROUND(I6*'Key Assumptions'!$B$18*'Key Assumptions'!$C$12,0) -> 61 | ... M9: =ROUND(M6*'Key Assumptions'!$B$18*'Key Assumptions'!$C$12,0) -> 61 | N9: =SUM(B9:M9) -> 732
A10: Other disconnects | B10: ='Key Assumptions'!$B$19 -> 5 | C10: ='Key Assumptions'!$B$19 -> 5 | D10: ='Key Assumptions'!$B$19 -> 5 | E10: ='Key Assumptions'!$B$19 -> 5 | F10: ='Key Assumptions'!$B$19 -> 5 | G10: ='Key Assumptions'!$B$19 -> 5 | H10: ='Key Assumptions'!$B$19 -> 5 | I10: ='Key Assumptions'!$B$19 -> 5 | ... M10: ='Key Assumptions'!$B$19 -> 5 | N10: =SUM(B10:M10) -> 60
A11: Net additions | B11: =B7+B8-B9-B10 -> 2 | C11: =C7+C8-C9-C10 -> 2 | D11: =D7+D8-D9-D10 -> 2 | E11: =E7+E8-E9-E10 -> 2 | F11: =F7+F8-F9-F10 -> 2 | G11: =G7+G8-G9-G10 -> 2 | H11: =H7+H8-H9-H10 -> 2 | I11: =I7+I8-I9-I10 -> 2 | ... M11: =M7+M8-M9-M10 -> 2 | N11: =SUM(B11:M11) -> 24
A12: Ending subscribers | B12: =MAX(0,B6+B11) -> 4050 | C12: =MAX(0,C6+C11) -> 4052 | D12: =MAX(0,D6+D11) -> 4054 | E12: =MAX(0,E6+E11) -> 4056 | F12: =MAX(0,F6+F11) -> 4058 | G12: =MAX(0,G6+G11) -> 4060 | H12: =MAX(0,H6+H11) -> 4062 | I12: =MAX(0,I6+I11) -> 4064 | ... M12: =MAX(0,M6+M11) -> 4072 | N12: =M12 -> 4072
A13: Average billable subscribers | B13: =IF('Key Assumptions'!$B$31="Average",(B6+B12)/2,IF('Key Assumptions'!$B$31="Beginning",B6,B12)) -> 4049 | C13: =IF('Key Assumptions'!$B$31="Average",(C6+C12)/2,IF('Key Assumptions'!$B$31="Beginning",C6,C12)) -> 4051 | D13: =IF('Key Assumptions'!$B$31="Average",(D6+D12)/2,IF('Key Assumptions'!$B$31="Beginning",D6,D12)) -> 4053 | E13: =IF('Key Assumptions'!$B$31="Average",(E6+E12)/2,IF('Key Assumptions'!$B$31="Beginning",E6,E12)) -> 4055 | F13: =IF('Key Assumptions'!$B$31="Average",(F6+F12)/2,IF('Key Assumptions'!$B$31="Beginning",F6,F12)) -> 4057 | G13: =IF('Key Assumptions'!$B$31="Average",(G6+G12)/2,IF('Key Assumptions'!$B$31="Beginning",G6,G12)) -> 4059 | H13: =IF('Key Assumptions'!$B$31="Average",(H6+H12)/2,IF('Key Assumptions'!$B$31="Beginning",H6,H12)) -> 4061 | I13: =IF('Key Assumptions'!$B$31="Average",(I6+I12)/2,IF('Key Assumptions'!$B$31="Beginning",I6,I12)) -> 4063 | ... M13: =IF('Key Assumptions'!$B$31="Average",(M6+M12)/2,IF('Key Assumptions'!$B$31="Beginning",M6,M12)) -> 4071 | N13: =AVERAGE(B13:M13) -> 4060
A14: REVENUE
A15: Standard recurring broadband revenue | B15: =B13*('Key Assumptions'!$B$21*IF(B4>='Key Assumptions'!$B$22,1+'Key Assumptions'!$B$23,1)*'Key Assumptions'!$D$12) -> 299626 | C15: =C13*('Key Assumptions'!$B$21*IF(C4>='Key Assumptions'!$B$22,1+'Key Assumptions'!$B$23,1)*'Key Assumptions'!$D$12) -> 299774 | D15: =D13*('Key Assumptions'!$B$21*IF(D4>='Key Assumptions'!$B$22,1+'Key Assumptions'!$B$23,1)*'Key Assumptions'!$D$12) -> 299922 | E15: =E13*('Key Assumptions'!$B$21*IF(E4>='Key Assumptions'!$B$22,1+'Key Assumptions'!$B$23,1)*'Key Assumptions'!$D$12) -> 300070 | F15: =F13*('Key Assumptions'!$B$21*IF(F4>='Key Assumptions'!$B$22,1+'Key Assumptions'!$B$23,1)*'Key Assumptions'!$D$12) -> 300218 | G15: =G13*('Key Assumptions'!$B$21*IF(G4>='Key Assumptions'!$B$22,1+'Key Assumptions'!$B$23,1)*'Key Assumptions'!$D$12) -> 300366 | H15: =H13*('Key Assumptions'!$B$21*IF(H4>='Key Assumptions'!$B$22,1+'Key Assumptions'!$B$23,1)*'Key Assumptions'!$D$12) -> 309529.42 | I15: =I13*('Key Assumptions'!$B$21*IF(I4>='Key Assumptions'!$B$22,1+'Key Assumptions'!$B$23,1)*'Key Assumptions'!$D$12) -> 309681.86 | ... M15: =M13*('Key Assumptions'!$B$21*IF(M4>='Key Assumptions'!$B$22,1+'Key Assumptions'!$B$23,1)*'Key Assumptions'!$D$12) -> 310291.62 | N15: =SUM(B15:M15) -> 3659439.1
A16: Upgrade revenue | B16: =B13*'Key Assumptions'!$B$26*'Key Assumptions'!$B$25 -> 2024.5 | C16: =C13*'Key Assumptions'!$B$26*'Key Assumptions'!$B$25 -> 2025.5 | D16: =D13*'Key Assumptions'!$B$26*'Key Assumptions'!$B$25 -> 2026.5 | E16: =E13*'Key Assumptions'!$B$26*'Key Assumptions'!$B$25 -> 2027.5 | F16: =F13*'Key Assumptions'!$B$26*'Key Assumptions'!$B$25 -> 2028.5 | G16: =G13*'Key Assumptions'!$B$26*'Key Assumptions'!$B$25 -> 2029.5 | H16: =H13*'Key Assumptions'!$B$26*'Key Assumptions'!$B$25 -> 2030.5 | I16: =I13*'Key Assumptions'!$B$26*'Key Assumptions'!$B$25 -> 2031.5 | ... M16: =M13*'Key Assumptions'!$B$26*'Key Assumptions'!$B$25 -> 2035.5 | N16: =SUM(B16:M16) -> 24360
A17: Installation revenue | B17: =B7*'Key Assumptions'!$B$24*'Key Assumptions'!$J$12 -> 5940 | C17: =C7*'Key Assumptions'!$B$24*'Key Assumptions'!$J$12 -> 5940 | D17: =D7*'Key Assumptions'!$B$24*'Key Assumptions'!$J$12 -> 5940 | E17: =E7*'Key Assumptions'!$B$24*'Key Assumptions'!$J$12 -> 5940 | F17: =F7*'Key Assumptions'!$B$24*'Key Assumptions'!$J$12 -> 5940 | G17: =G7*'Key Assumptions'!$B$24*'Key Assumptions'!$J$12 -> 5940 | H17: =H7*'Key Assumptions'!$B$24*'Key Assumptions'!$J$12 -> 5940 | I17: =I7*'Key Assumptions'!$B$24*'Key Assumptions'!$J$12 -> 5940 | ... M17: =M7*'Key Assumptions'!$B$24*'Key Assumptions'!$J$12 -> 5940 | N17: =SUM(B17:M17) -> 71280
A18: Voice / additional service revenue | B18: =B13*'Key Assumptions'!$B$30 -> 7936.04 | C18: =C13*'Key Assumptions'!$B$30 -> 7939.96 | D18: =D13*'Key Assumptions'!$B$30 -> 7943.88 | E18: =E13*'Key Assumptions'!$B$30 -> 7947.8 | F18: =F13*'Key Assumptions'!$B$30 -> 7951.72 | G18: =G13*'Key Assumptions'!$B$30 -> 7955.64 | H18: =H13*'Key Assumptions'!$B$30 -> 7959.56 | I18: =I13*'Key Assumptions'!$B$30 -> 7963.48 | ... M18: =M13*'Key Assumptions'!$B$30 -> 7979.16 | N18: =SUM(B18:M18) -> 95491.2
A19: Other residential revenue | B19: ='Key Assumptions'!$B$29 -> 13305.833 | C19: ='Key Assumptions'!$B$29 -> 13305.833 | D19: ='Key Assumptions'!$B$29 -> 13305.833 | E19: ='Key Assumptions'!$B$29 -> 13305.833 | F19: ='Key Assumptions'!$B$29 -> 13305.833 | G19: ='Key Assumptions'!$B$29 -> 13305.833 | H19: ='Key Assumptions'!$B$29 -> 13305.833 | I19: ='Key Assumptions'!$B$29 -> 13305.833 | ... M19: ='Key Assumptions'!$B$29 -> 13305.833 | N19: =SUM(B19:M19) -> 159670
A20: Residential recurring revenue | B20: =B15+B18+B19 -> 320867.87 | C20: =C15+C18+C19 -> 321019.79 | D20: =D15+D18+D19 -> 321171.71 | E20: =E15+E18+E19 -> 321323.63 | F20: =F15+F18+F19 -> 321475.55 | G20: =G15+G18+G19 -> 321627.47 | H20: =H15+H18+H19 -> 330794.81 | I20: =I15+I18+I19 -> 330951.17 | ... M20: =M15+M18+M19 -> 331576.61 | N20: =SUM(B20:M20) -> 3914600.3
A21: Residential one-time revenue | B21: =B16+B17 -> 7964.5 | C21: =C16+C17 -> 7965.5 | D21: =D16+D17 -> 7966.5 | E21: =E16+E17 -> 7967.5 | F21: =F16+F17 -> 7968.5 | G21: =G16+G17 -> 7969.5 | H21: =H16+H17 -> 7970.5 | I21: =I16+I17 -> 7971.5 | ... M21: =M16+M17 -> 7975.5 | N21: =SUM(B21:M21) -> 95640
A22: Gross residential revenue | B22: =B20+B21 -> 328832.37 | C22: =C20+C21 -> 328985.29 | D22: =D20+D21 -> 329138.21 | E22: =E20+E21 -> 329291.13 | F22: =F20+F21 -> 329444.05 | G22: =G20+G21 -> 329596.97 | H22: =H20+H21 -> 338765.31 | I22: =I20+I21 -> 338922.67 | ... M22: =M20+M21 -> 339552.11 | N22: =SUM(B22:M22) -> 4010240.3
A23: Promotional discounts | B23: =-B20*'Key Assumptions'!$B$27 -> -6417.3575 | C23: =-C20*'Key Assumptions'!$B$27 -> -6420.3959 | D23: =-D20*'Key Assumptions'!$B$27 -> -6423.4343 | E23: =-E20*'Key Assumptions'!$B$27 -> -6426.4727 | F23: =-F20*'Key Assumptions'!$B$27 -> -6429.5111 | G23: =-G20*'Key Assumptions'!$B$27 -> -6432.5495 | H23: =-H20*'Key Assumptions'!$B$27 -> -6615.8963 | I23: =-I20*'Key Assumptions'!$B$27 -> -6619.0235 | ... M23: =-M20*'Key Assumptions'!$B$27 -> -6631.5323 | N23: =SUM(B23:M23) -> -78292.006
A24: Bad-debt adjustment | B24: =-B22*'Key Assumptions'!$B$28 -> -3288.3237 | C24: =-C22*'Key Assumptions'!$B$28 -> -3289.8529 | D24: =-D22*'Key Assumptions'!$B$28 -> -3291.3821 | E24: =-E22*'Key Assumptions'!$B$28 -> -3292.9113 | F24: =-F22*'Key Assumptions'!$B$28 -> -3294.4405 | G24: =-G22*'Key Assumptions'!$B$28 -> -3295.9697 | H24: =-H22*'Key Assumptions'!$B$28 -> -3387.6531 | I24: =-I22*'Key Assumptions'!$B$28 -> -3389.2267 | ... M24: =-M22*'Key Assumptions'!$B$28 -> -3395.5211 | N24: =SUM(B24:M24) -> -40102.403
A25: Net residential revenue | B25: =B22+B23+B24 -> 319126.69 | C25: =C22+C23+C24 -> 319275.04 | D25: =D22+D23+D24 -> 319423.4 | E25: =E22+E23+E24 -> 319571.75 | F25: =F22+F23+F24 -> 319720.1 | G25: =G22+G23+G24 -> 319868.45 | H25: =H22+H23+H24 -> 328761.76 | I25: =I22+I23+I24 -> 328914.42 | ... M25: =M22+M23+M24 -> 329525.06 | N25: =SUM(B25:M25) -> 3891845.9
A26: Residential MRR | B26: =B20+B23 -> 314450.52 | C26: =C20+C23 -> 314599.4 | D26: =D20+D23 -> 314748.28 | E26: =E20+E23 -> 314897.16 | F26: =F20+F23 -> 315046.04 | G26: =G20+G23 -> 315194.92 | H26: =H20+H23 -> 324178.92 | I26: =I20+I23 -> 324332.15 | ... M26: =M20+M23 -> 324945.08 | N26: =M26 -> 324945.08
A27: Residential ARR run rate | B27: =B26*12 -> 3773406.2 | C27: =C26*12 -> 3775192.8 | D27: =D26*12 -> 3776979.3 | E27: =E26*12 -> 3778765.9 | F27: =F26*12 -> 3780552.5 | G27: =G26*12 -> 3782339.1 | H27: =H26*12 -> 3890147 | I27: =I26*12 -> 3891985.8 | ... M27: =M26*12 -> 3899341 | N27: =M27 -> 3899341
A28: Effective residential ARPU | B28: =IFERROR(B15/B13,0) -> 74 | C28: =IFERROR(C15/C13,0) -> 74 | D28: =IFERROR(D15/D13,0) -> 74 | E28: =IFERROR(E15/E13,0) -> 74 | F28: =IFERROR(F15/F13,0) -> 74 | G28: =IFERROR(G15/G13,0) -> 74 | H28: =IFERROR(H15/H13,0) -> 76.22 | I28: =IFERROR(I15/I13,0) -> 76.22 | ... M28: =IFERROR(M15/M13,0) -> 76.22 | N28: =AVERAGE(B28:M28) -> 75.11

Sheet Business Forecast
A1: BUSINESS BROADBAND FORECAST — 2027
A2: Recurring separated from construction/installation one-time revenue. Grey = formulas; edit assumptions on Key Assumptions.
A3: Metric | B3: 46388 | C3: 46419 | D3: 46447 | E3: 46478 | F3: 46508 | G3: 46539 | H3: 46569 | I3: 46600 | J3: 46631 | K3: 46661 | L3: 46692 | M3: 46722 | N3: FY 2027
A4: Month # | B4: 1 | C4: 2 | D4: 3 | E4: 4 | F4: 5 | G4: 6 | H4: 7 | I4: 8 | J4: 9 | K4: 10 | L4: 11 | M4: 12
A5: CUSTOMER MOVEMENT
A6: Beginning business customers | B6: ='Key Assumptions'!$B$35 -> 249 | C6: =B13 -> 252 | D6: =C13 -> 254 | E6: =D13 -> 256 | F6: =E13 -> 258 | G6: =F13 -> 260 | H6: =G13 -> 262 | I6: =H13 -> 264 | J6: =I13 -> 266 | ... M6: =L13 -> 272 | N6: =B6 -> 249
A7: New small-business customers | B7: =ROUND('Key Assumptions'!$B$36*'Key Assumptions'!$E$12,0) -> 4 | C7: =ROUND('Key Assumptions'!$B$36*'Key Assumptions'!$E$12,0) -> 4 | D7: =ROUND('Key Assumptions'!$B$36*'Key Assumptions'!$E$12,0) -> 4 | E7: =ROUND('Key Assumptions'!$B$36*'Key Assumptions'!$E$12,0) -> 4 | F7: =ROUND('Key Assumptions'!$B$36*'Key Assumptions'!$E$12,0) -> 4 | G7: =ROUND('Key Assumptions'!$B$36*'Key Assumptions'!$E$12,0) -> 4 | H7: =ROUND('Key Assumptions'!$B$36*'Key Assumptions'!$E$12,0) -> 4 | I7: =ROUND('Key Assumptions'!$B$36*'Key Assumptions'!$E$12,0) -> 4 | ... M7: =ROUND('Key Assumptions'!$B$36*'Key Assumptions'!$E$12,0) -> 4 | N7: =SUM(B7:M7) -> 48
A8: New enterprise customers | B8: =ROUND('Key Assumptions'!$B$37*'Key Assumptions'!$E$12,0) -> 1 | C8: =ROUND('Key Assumptions'!$B$37*'Key Assumptions'!$E$12,0) -> 1 | D8: =ROUND('Key Assumptions'!$B$37*'Key Assumptions'!$E$12,0) -> 1 | E8: =ROUND('Key Assumptions'!$B$37*'Key Assumptions'!$E$12,0) -> 1 | F8: =ROUND('Key Assumptions'!$B$37*'Key Assumptions'!$E$12,0) -> 1 | G8: =ROUND('Key Assumptions'!$B$37*'Key Assumptions'!$E$12,0) -> 1 | H8: =ROUND('Key Assumptions'!$B$37*'Key Assumptions'!$E$12,0) -> 1 | I8: =ROUND('Key Assumptions'!$B$37*'Key Assumptions'!$E$12,0) -> 1 | ... M8: =ROUND('Key Assumptions'!$B$37*'Key Assumptions'!$E$12,0) -> 1 | N8: =SUM(B8:M8) -> 12
A9: Reconnects | B9: ='Key Assumptions'!$B$40 -> 2 | C9: ='Key Assumptions'!$B$40 -> 2 | D9: ='Key Assumptions'!$B$40 -> 2 | E9: ='Key Assumptions'!$B$40 -> 2 | F9: ='Key Assumptions'!$B$40 -> 2 | G9: ='Key Assumptions'!$B$40 -> 2 | H9: ='Key Assumptions'!$B$40 -> 2 | I9: ='Key Assumptions'!$B$40 -> 2 | ... M9: ='Key Assumptions'!$B$40 -> 2 | N9: =SUM(B9:M9) -> 24
A10: Churn disconnects | B10: =ROUND(B6*'Key Assumptions'!$B$38*'Key Assumptions'!$F$12,0) -> 2 | C10: =ROUND(C6*'Key Assumptions'!$B$38*'Key Assumptions'!$F$12,0) -> 3 | D10: =ROUND(D6*'Key Assumptions'!$B$38*'Key Assumptions'!$F$12,0) -> 3 | E10: =ROUND(E6*'Key Assumptions'!$B$38*'Key Assumptions'!$F$12,0) -> 3 | F10: =ROUND(F6*'Key Assumptions'!$B$38*'Key Assumptions'!$F$12,0) -> 3 | G10: =ROUND(G6*'Key Assumptions'!$B$38*'Key Assumptions'!$F$12,0) -> 3 | H10: =ROUND(H6*'Key Assumptions'!$B$38*'Key Assumptions'!$F$12,0) -> 3 | I10: =ROUND(I6*'Key Assumptions'!$B$38*'Key Assumptions'!$F$12,0) -> 3 | ... M10: =ROUND(M6*'Key Assumptions'!$B$38*'Key Assumptions'!$F$12,0) -> 3 | N10: =SUM(B10:M10) -> 35
A11: Other disconnects | B11: ='Key Assumptions'!$B$39 -> 2 | C11: ='Key Assumptions'!$B$39 -> 2 | D11: ='Key Assumptions'!$B$39 -> 2 | E11: ='Key Assumptions'!$B$39 -> 2 | F11: ='Key Assumptions'!$B$39 -> 2 | G11: ='Key Assumptions'!$B$39 -> 2 | H11: ='Key Assumptions'!$B$39 -> 2 | I11: ='Key Assumptions'!$B$39 -> 2 | ... M11: ='Key Assumptions'!$B$39 -> 2 | N11: =SUM(B11:M11) -> 24
A12: Net additions | B12: =B7+B8+B9-B10-B11 -> 3 | C12: =C7+C8+C9-C10-C11 -> 2 | D12: =D7+D8+D9-D10-D11 -> 2 | E12: =E7+E8+E9-E10-E11 -> 2 | F12: =F7+F8+F9-F10-F11 -> 2 | G12: =G7+G8+G9-G10-G11 -> 2 | H12: =H7+H8+H9-H10-H11 -> 2 | I12: =I7+I8+I9-I10-I11 -> 2 | ... M12: =M7+M8+M9-M10-M11 -> 2 | N12: =SUM(B12:M12) -> 25
A13: Ending business customers | B13: =MAX(0,B6+B12) -> 252 | C13: =MAX(0,C6+C12) -> 254 | D13: =MAX(0,D6+D12) -> 256 | E13: =MAX(0,E6+E12) -> 258 | F13: =MAX(0,F6+F12) -> 260 | G13: =MAX(0,G6+G12) -> 262 | H13: =MAX(0,H6+H12) -> 264 | I13: =MAX(0,I6+I12) -> 266 | ... M13: =MAX(0,M6+M12) -> 274 | N13: =M13 -> 274
A14: Average billable business customers | B14: =IF('Key Assumptions'!$B$56="Average",(B6+B13)/2,IF('Key Assumptions'!$B$56="Beginning",B6,B13)) -> 250.5 | C14: =IF('Key Assumptions'!$B$56="Average",(C6+C13)/2,IF('Key Assumptions'!$B$56="Beginning",C6,C13)) -> 253 | D14: =IF('Key Assumptions'!$B$56="Average",(D6+D13)/2,IF('Key Assumptions'!$B$56="Beginning",D6,D13)) -> 255 | E14: =IF('Key Assumptions'!$B$56="Average",(E6+E13)/2,IF('Key Assumptions'!$B$56="Beginning",E6,E13)) -> 257 | F14: =IF('Key Assumptions'!$B$56="Average",(F6+F13)/2,IF('Key Assumptions'!$B$56="Beginning",F6,F13)) -> 259 | G14: =IF('Key Assumptions'!$B$56="Average",(G6+G13)/2,IF('Key Assumptions'!$B$56="Beginning",G6,G13)) -> 261 | H14: =IF('Key Assumptions'!$B$56="Average",(H6+H13)/2,IF('Key Assumptions'!$B$56="Beginning",H6,H13)) -> 263 | I14: =IF('Key Assumptions'!$B$56="Average",(I6+I13)/2,IF('Key Assumptions'!$B$56="Beginning",I6,I13)) -> 265 | ... M14: =IF('Key Assumptions'!$B$56="Average",(M6+M13)/2,IF('Key Assumptions'!$B$56="Beginning",M6,M13)) -> 273 | N14: =AVERAGE(B14:M14) -> 261.95833
A15: Beginning enterprise customers | B15: ='Key Assumptions'!$B$57 -> 0 | C15: =B16 -> 1 | D15: =C16 -> 2 | E15: =D16 -> 3 | F15: =E16 -> 4 | G15: =F16 -> 5 | H15: =G16 -> 6 | I15: =H16 -> 7 | J15: =I16 -> 8 | ... M15: =L16 -> 11 | N15: =B15 -> 0
A16: Ending enterprise customers | B16: =MAX(0,B15+B8-ROUND(B15*'Key Assumptions'!$B$38*'Key Assumptions'!$F$12,0)) -> 1 | C16: =MAX(0,C15+C8-ROUND(C15*'Key Assumptions'!$B$38*'Key Assumptions'!$F$12,0)) -> 2 | D16: =MAX(0,D15+D8-ROUND(D15*'Key Assumptions'!$B$38*'Key Assumptions'!$F$12,0)) -> 3 | E16: =MAX(0,E15+E8-ROUND(E15*'Key Assumptions'!$B$38*'Key Assumptions'!$F$12,0)) -> 4 | F16: =MAX(0,F15+F8-ROUND(F15*'Key Assumptions'!$B$38*'Key Assumptions'!$F$12,0)) -> 5 | G16: =MAX(0,G15+G8-ROUND(G15*'Key Assumptions'!$B$38*'Key Assumptions'!$F$12,0)) -> 6 | H16: =MAX(0,H15+H8-ROUND(H15*'Key Assumptions'!$B$38*'Key Assumptions'!$F$12,0)) -> 7 | I16: =MAX(0,I15+I8-ROUND(I15*'Key Assumptions'!$B$38*'Key Assumptions'!$F$12,0)) -> 8 | ... M16: =MAX(0,M15+M8-ROUND(M15*'Key Assumptions'!$B$38*'Key Assumptions'!$F$12,0)) -> 12 | N16: =M16 -> 12
A17: Average enterprise customers | B17: =(B15+B16)/2 -> 0.5 | C17: =(C15+C16)/2 -> 1.5 | D17: =(D15+D16)/2 -> 2.5 | E17: =(E15+E16)/2 -> 3.5 | F17: =(F15+F16)/2 -> 4.5 | G17: =(G15+G16)/2 -> 5.5 | H17: =(H15+H16)/2 -> 6.5 | I17: =(I15+I16)/2 -> 7.5 | ... M17: =(M15+M16)/2 -> 11.5 | N17: =AVERAGE(B17:M17) -> 6
A18: RECURRING REVENUE
A19: Standard business broadband | B19: =B14*('Key Assumptions'!$B$41*IF(B4>='Key Assumptions'!$B$42,1+'Key Assumptions'!$B$43,1)*'Key Assumptions'!$G$12) -> 37324.5 | C19: =C14*('Key Assumptions'!$B$41*IF(C4>='Key Assumptions'!$B$42,1+'Key Assumptions'!$B$43,1)*'Key Assumptions'!$G$12) -> 37697 | D19: =D14*('Key Assumptions'!$B$41*IF(D4>='Key Assumptions'!$B$42,1+'Key Assumptions'!$B$43,1)*'Key Assumptions'!$G$12) -> 37995 | E19: =E14*('Key Assumptions'!$B$41*IF(E4>='Key Assumptions'!$B$42,1+'Key Assumptions'!$B$43,1)*'Key Assumptions'!$G$12) -> 38293 | F19: =F14*('Key Assumptions'!$B$41*IF(F4>='Key Assumptions'!$B$42,1+'Key Assumptions'!$B$43,1)*'Key Assumptions'!$G$12) -> 38591 | G19: =G14*('Key Assumptions'!$B$41*IF(G4>='Key Assumptions'!$B$42,1+'Key Assumptions'!$B$43,1)*'Key Assumptions'!$G$12) -> 38889 | H19: =H14*('Key Assumptions'!$B$41*IF(H4>='Key Assumptions'!$B$42,1+'Key Assumptions'!$B$43,1)*'Key Assumptions'!$G$12) -> 40362.61 | I19: =I14*('Key Assumptions'!$B$41*IF(I4>='Key Assumptions'!$B$42,1+'Key Assumptions'!$B$43,1)*'Key Assumptions'!$G$12) -> 40669.55 | ... M19: =M14*('Key Assumptions'!$B$41*IF(M4>='Key Assumptions'!$B$42,1+'Key Assumptions'!$B$43,1)*'Key Assumptions'!$G$12) -> 41897.31 | N19: =SUM(B19:M19) -> 475569.26
A20: Enterprise & DIA circuits | B20: =B17*'Key Assumptions'!$B$48 -> 0 | C20: =C17*'Key Assumptions'!$B$48 -> 0 | D20: =D17*'Key Assumptions'!$B$48 -> 0 | E20: =E17*'Key Assumptions'!$B$48 -> 0 | F20: =F17*'Key Assumptions'!$B$48 -> 0 | G20: =G17*'Key Assumptions'!$B$48 -> 0 | H20: =H17*'Key Assumptions'!$B$48 -> 0 | I20: =I17*'Key Assumptions'!$B$48 -> 0 | ... M20: =M17*'Key Assumptions'!$B$48 -> 0 | N20: =SUM(B20:M20) -> 0
A21: Static IP revenue | B21: =B14*'Key Assumptions'!$B$45 -> 0 | C21: =C14*'Key Assumptions'!$B$45 -> 0 | D21: =D14*'Key Assumptions'!$B$45 -> 0 | E21: =E14*'Key Assumptions'!$B$45 -> 0 | F21: =F14*'Key Assumptions'!$B$45 -> 0 | G21: =G14*'Key Assumptions'!$B$45 -> 0 | H21: =H14*'Key Assumptions'!$B$45 -> 0 | I21: =I14*'Key Assumptions'!$B$45 -> 0 | ... M21: =M14*'Key Assumptions'!$B$45 -> 0 | N21: =SUM(B21:M21) -> 0
A22: Managed Wi-Fi / router revenue | B22: =B14*'Key Assumptions'!$B$46 -> 0 | C22: =C14*'Key Assumptions'!$B$46 -> 0 | D22: =D14*'Key Assumptions'!$B$46 -> 0 | E22: =E14*'Key Assumptions'!$B$46 -> 0 | F22: =F14*'Key Assumptions'!$B$46 -> 0 | G22: =G14*'Key Assumptions'!$B$46 -> 0 | H22: =H14*'Key Assumptions'!$B$46 -> 0 | I22: =I14*'Key Assumptions'!$B$46 -> 0 | ... M22: =M14*'Key Assumptions'!$B$46 -> 0 | N22: =SUM(B22:M22) -> 0
A23: Voice revenue | B23: =B14*'Key Assumptions'!$B$47 -> 2424.84 | C23: =C14*'Key Assumptions'!$B$47 -> 2449.04 | D23: =D14*'Key Assumptions'!$B$47 -> 2468.4 | E23: =E14*'Key Assumptions'!$B$47 -> 2487.76 | F23: =F14*'Key Assumptions'!$B$47 -> 2507.12 | G23: =G14*'Key Assumptions'!$B$47 -> 2526.48 | H23: =H14*'Key Assumptions'!$B$47 -> 2545.84 | I23: =I14*'Key Assumptions'!$B$47 -> 2565.2 | ... M23: =M14*'Key Assumptions'!$B$47 -> 2642.64 | N23: =SUM(B23:M23) -> 30429.08
A24: Other recurring business revenue | B24: =B14*'Key Assumptions'!$B$49 -> 0 | C24: =C14*'Key Assumptions'!$B$49 -> 0 | D24: =D14*'Key Assumptions'!$B$49 -> 0 | E24: =E14*'Key Assumptions'!$B$49 -> 0 | F24: =F14*'Key Assumptions'!$B$49 -> 0 | G24: =G14*'Key Assumptions'!$B$49 -> 0 | H24: =H14*'Key Assumptions'!$B$49 -> 0 | I24: =I14*'Key Assumptions'!$B$49 -> 0 | ... M24: =M14*'Key Assumptions'!$B$49 -> 0 | N24: =SUM(B24:M24) -> 0
A25: Total business recurring revenue | B25: =SUM(B19:B24) -> 39749.34 | C25: =SUM(C19:C24) -> 40146.04 | D25: =SUM(D19:D24) -> 40463.4 | E25: =SUM(E19:E24) -> 40780.76 | F25: =SUM(F19:F24) -> 41098.12 | G25: =SUM(G19:G24) -> 41415.48 | H25: =SUM(H19:H24) -> 42908.45 | I25: =SUM(I19:I24) -> 43234.75 | ... M25: =SUM(M19:M24) -> 44539.95 | N25: =SUM(B25:M25) -> 505998.34
A26: ONE-TIME REVENUE
A27: Installation charges | B27: =(B7+B8)*'Key Assumptions'!$B$44*'Key Assumptions'!$J$12 -> 2500 | C27: =(C7+C8)*'Key Assumptions'!$B$44*'Key Assumptions'!$J$12 -> 2500 | D27: =(D7+D8)*'Key Assumptions'!$B$44*'Key Assumptions'!$J$12 -> 2500 | E27: =(E7+E8)*'Key Assumptions'!$B$44*'Key Assumptions'!$J$12 -> 2500 | F27: =(F7+F8)*'Key Assumptions'!$B$44*'Key Assumptions'!$J$12 -> 2500 | G27: =(G7+G8)*'Key Assumptions'!$B$44*'Key Assumptions'!$J$12 -> 2500 | H27: =(H7+H8)*'Key Assumptions'!$B$44*'Key Assumptions'!$J$12 -> 2500 | I27: =(I7+I8)*'Key Assumptions'!$B$44*'Key Assumptions'!$J$12 -> 2500 | ... M27: =(M7+M8)*'Key Assumptions'!$B$44*'Key Assumptions'!$J$12 -> 2500 | N27: =SUM(B27:M27) -> 30000
A28: Aid-to-construction revenue | B28: =(B7+B8)*'Key Assumptions'!$B$50*'Key Assumptions'!$J$12 -> 1250 | C28: =(C7+C8)*'Key Assumptions'!$B$50*'Key Assumptions'!$J$12 -> 1250 | D28: =(D7+D8)*'Key Assumptions'!$B$50*'Key Assumptions'!$J$12 -> 1250 | E28: =(E7+E8)*'Key Assumptions'!$B$50*'Key Assumptions'!$J$12 -> 1250 | F28: =(F7+F8)*'Key Assumptions'!$B$50*'Key Assumptions'!$J$12 -> 1250 | G28: =(G7+G8)*'Key Assumptions'!$B$50*'Key Assumptions'!$J$12 -> 1250 | H28: =(H7+H8)*'Key Assumptions'!$B$50*'Key Assumptions'!$J$12 -> 1250 | I28: =(I7+I8)*'Key Assumptions'!$B$50*'Key Assumptions'!$J$12 -> 1250 | ... M28: =(M7+M8)*'Key Assumptions'!$B$50*'Key Assumptions'!$J$12 -> 1250 | N28: =SUM(B28:M28) -> 15000
A29: Activation charges | B29: =(B7+B8)*'Key Assumptions'!$B$51 -> 500 | C29: =(C7+C8)*'Key Assumptions'!$B$51 -> 500 | D29: =(D7+D8)*'Key Assumptions'!$B$51 -> 500 | E29: =(E7+E8)*'Key Assumptions'!$B$51 -> 500 | F29: =(F7+F8)*'Key Assumptions'!$B$51 -> 500 | G29: =(G7+G8)*'Key Assumptions'!$B$51 -> 500 | H29: =(H7+H8)*'Key Assumptions'!$B$51 -> 500 | I29: =(I7+I8)*'Key Assumptions'!$B$51 -> 500 | ... M29: =(M7+M8)*'Key Assumptions'!$B$51 -> 500 | N29: =SUM(B29:M29) -> 6000
A30: Professional services | B30: ='Key Assumptions'!$B$52 -> 1500 | C30: ='Key Assumptions'!$B$52 -> 1500 | D30: ='Key Assumptions'!$B$52 -> 1500 | E30: ='Key Assumptions'!$B$52 -> 1500 | F30: ='Key Assumptions'!$B$52 -> 1500 | G30: ='Key Assumptions'!$B$52 -> 1500 | H30: ='Key Assumptions'!$B$52 -> 1500 | I30: ='Key Assumptions'!$B$52 -> 1500 | ... M30: ='Key Assumptions'!$B$52 -> 1500 | N30: =SUM(B30:M30) -> 18000
A31: Other nonrecurring revenue | B31: ='Key Assumptions'!$B$53 -> 500 | C31: ='Key Assumptions'!$B$53 -> 500 | D31: ='Key Assumptions'!$B$53 -> 500 | E31: ='Key Assumptions'!$B$53 -> 500 | F31: ='Key Assumptions'!$B$53 -> 500 | G31: ='Key Assumptions'!$B$53 -> 500 | H31: ='Key Assumptions'!$B$53 -> 500 | I31: ='Key Assumptions'!$B$53 -> 500 | ... M31: ='Key Assumptions'!$B$53 -> 500 | N31: =SUM(B31:M31) -> 6000
A32: Total business one-time revenue | B32: =SUM(B27:B31) -> 6250 | C32: =SUM(C27:C31) -> 6250 | D32: =SUM(D27:D31) -> 6250 | E32: =SUM(E27:E31) -> 6250 | F32: =SUM(F27:F31) -> 6250 | G32: =SUM(G27:G31) -> 6250 | H32: =SUM(H27:H31) -> 6250 | I32: =SUM(I27:I31) -> 6250 | ... M32: =SUM(M27:M31) -> 6250 | N32: =SUM(B32:M32) -> 75000
A33: ADJUSTMENTS & TOTALS
A34: Promotional discounts | B34: =-B25*'Key Assumptions'!$B$54 -> -596.2401 | C34: =-C25*'Key Assumptions'!$B$54 -> -602.1906 | D34: =-D25*'Key Assumptions'!$B$54 -> -606.951 | E34: =-E25*'Key Assumptions'!$B$54 -> -611.7114 | F34: =-F25*'Key Assumptions'!$B$54 -> -616.4718 | G34: =-G25*'Key Assumptions'!$B$54 -> -621.2322 | H34: =-H25*'Key Assumptions'!$B$54 -> -643.62675 | I34: =-I25*'Key Assumptions'!$B$54 -> -648.52125 | ... M34: =-M25*'Key Assumptions'!$B$54 -> -668.09925 | N34: =SUM(B34:M34) -> -7589.9751
A35: Bad-debt adjustment | B35: =-(B25+B32)*'Key Assumptions'!$B$55 -> -459.9934 | C35: =-(C25+C32)*'Key Assumptions'!$B$55 -> -463.9604 | D35: =-(D25+D32)*'Key Assumptions'!$B$55 -> -467.134 | E35: =-(E25+E32)*'Key Assumptions'!$B$55 -> -470.3076 | F35: =-(F25+F32)*'Key Assumptions'!$B$55 -> -473.4812 | G35: =-(G25+G32)*'Key Assumptions'!$B$55 -> -476.6548 | H35: =-(H25+H32)*'Key Assumptions'!$B$55 -> -491.5845 | I35: =-(I25+I32)*'Key Assumptions'!$B$55 -> -494.8475 | ... M35: =-(M25+M32)*'Key Assumptions'!$B$55 -> -507.8995 | N35: =SUM(B35:M35) -> -5809.9834
A36: Net business revenue | B36: =B25+B32+B34+B35 -> 44943.106 | C36: =C25+C32+C34+C35 -> 45329.889 | D36: =D25+D32+D34+D35 -> 45639.315 | E36: =E25+E32+E34+E35 -> 45948.741 | F36: =F25+F32+F34+F35 -> 46258.167 | G36: =G25+G32+G34+G35 -> 46567.593 | H36: =H25+H32+H34+H35 -> 48023.239 | I36: =I25+I32+I34+I35 -> 48341.381 | ... M36: =M25+M32+M34+M35 -> 49613.951 | N36: =SUM(B36:M36) -> 567598.38
A37: Business MRR | B37: =B25+B34 -> 39153.1 | C37: =C25+C34 -> 39543.849 | D37: =D25+D34 -> 39856.449 | E37: =E25+E34 -> 40169.049 | F37: =F25+F34 -> 40481.648 | G37: =G25+G34 -> 40794.248 | H37: =H25+H34 -> 42264.823 | I37: =I25+I34 -> 42586.229 | ... M37: =M25+M34 -> 43871.851 | N37: =M37 -> 43871.851
A38: Business ARR run rate | B38: =B37*12 -> 469837.2 | C38: =C37*12 -> 474526.19 | D38: =D37*12 -> 478277.39 | E38: =E37*12 -> 482028.58 | F38: =F37*12 -> 485779.78 | G38: =G37*12 -> 489530.97 | H38: =H37*12 -> 507177.88 | I38: =I37*12 -> 511034.74 | ... M38: =M37*12 -> 526462.21 | N38: =M38 -> 526462.21
A39: Effective business ARPU | B39: =IFERROR(B25/B14,0) -> 158.68 | C39: =IFERROR(C25/C14,0) -> 158.68 | D39: =IFERROR(D25/D14,0) -> 158.68 | E39: =IFERROR(E25/E14,0) -> 158.68 | F39: =IFERROR(F25/F14,0) -> 158.68 | G39: =IFERROR(G25/G14,0) -> 158.68 | H39: =IFERROR(H25/H14,0) -> 163.15 | I39: =IFERROR(I25/I14,0) -> 163.15 | ... M39: =IFERROR(M25/M14,0) -> 163.15 | N39: =AVERAGE(B39:M39) -> 160.915

Sheet Dark Fiber Forecast
A1: DARK FIBER & FIBER INFRASTRUCTURE FORECAST — 2027
A2: Each contract from Key Assumptions is recognized only during its active period (start/end dates). IRU treatment per contract method — CFO/accountant review required.
A4: Month first-day → | Q4: 46388 | R4: 46419 | S4: 46447 | T4: 46478 | U4: 46508 | V4: 46539 | W4: 46569 | X4: 46600 | Y4: 46631 | Z4: 46661 | AA4: 46692 | AB4: 46722
A5: Month end (EOM) → | Q5: =EOMONTH(Q4,0) -> 46418 | R5: =EOMONTH(R4,0) -> 46446 | S5: =EOMONTH(S4,0) -> 46477 | T5: =EOMONTH(T4,0) -> 46507 | U5: =EOMONTH(U4,0) -> 46538 | V5: =EOMONTH(V4,0) -> 46568 | W5: =EOMONTH(W4,0) -> 46599 | X5: =EOMONTH(X4,0) -> 46630 | ... AB5: =EOMONTH(AB4,0) -> 46752
A7: # | B7: Contract | C7: Eff Start | D7: End | E7: MRC | F7: Esc% | G7: EscDate | H7: O&M/mo | I7: Constr | J7: Activ | K7: IRU Pay | L7: IRU Term | M7: IRU Method | N7: IRU SL/mo | Q7: Jan-27 | R7: Feb-27 | S7: Mar-27 | T7: Apr-27 | U7: May-27 | V7: Jun-27 | W7: Jul-27 | X7: Aug-27 | Y7: Sep-27 | Z7: Oct-27 | AA7: Nov-27 | AB7: Dec-27 | AC7: Annual | AD7: Remaining Value | AE7: Expiration
A8: ='Key Assumptions'!A66 -> 1 | B8: ='Key Assumptions'!B66 -> PLACEHOLDER — Current dark fiber book (H1 2026 run-rate) | C8: =IF('Key Assumptions'!H66="",0,EDATE('Key Assumptions'!H66,'Key Assumptions'!$I$12)) -> 45292 | D8: =IF('Key Assumptions'!I66="",0,'Key Assumptions'!I66) -> 47848 | E8: =N('Key Assumptions'!J66) -> 1595 | F8: =N('Key Assumptions'!K66) -> 0 | G8: =IF('Key Assumptions'!L66="",0,'Key Assumptions'!L66) -> 46388 | H8: =IF('Key Assumptions'!R66="",IF(E8>0,E8*'Key Assumptions'!$B$61,0),'Key Assumptions'!R66) -> 0 | I8: =N('Key Assumptions'!M66) -> 0 | J8: =N('Key Assumptions'!N66) -> 0 | K8: =N('Key Assumptions'!O66) -> 0 | L8: =N('Key Assumptions'!P66) -> 0 | M8: =IF('Key Assumptions'!Q66="",'Key Assumptions'!$B$60,'Key Assumptions'!Q66) | N8: =IF($M8="Straight-line",IFERROR($K8/($L8*12),0),0) -> 0 | Q8: =IF(AND($C8>0,$C8<=Q$5,$D8>=Q$4),$E8*(1+$F8*(Q$4>=$G8))*'Key Assumptions'!$H$12+$H8+IF($M8="Straight-line",$N8,0),0)+IF(AND($M8="Upfront",$C8>=Q$4,$C8<=Q$5),$K8,0)+IF(AND($C8>0,$C8>=Q$4,$C8<=Q$5),$I8+$J8,0) -> 1595 | R8: =IF(AND($C8>0,$C8<=R$5,$D8>=R$4),$E8*(1+$F8*(R$4>=$G8))*'Key Assumptions'!$H$12+$H8+IF($M8="Straight-line",$N8,0),0)+IF(AND($M8="Upfront",$C8>=R$4,$C8<=R$5),$K8,0)+IF(AND($C8>0,$C8>=R$4,$C8<=R$5),$I8+$J8,0) -> 1595 | S8: =IF(AND($C8>0,$C8<=S$5,$D8>=S$4),$E8*(1+$F8*(S$4>=$G8))*'Key Assumptions'!$H$12+$H8+IF($M8="Straight-line",$N8,0),0)+IF(AND($M8="Upfront",$C8>=S$4,$C8<=S$5),$K8,0)+IF(AND($C8>0,$C8>=S$4,$C8<=S$5),$I8+$J8,0) -> 1595 | T8: =IF(AND($C8>0,$C8<=T$5,$D8>=T$4),$E8*(1+$F8*(T$4>=$G8))*'Key Assumptions'!$H$12+$H8+IF($M8="Straight-line",$N8,0),0)+IF(AND($M8="Upfront",$C8>=T$4,$C8<=T$5),$K8,0)+IF(AND($C8>0,$C8>=T$4,$C8<=T$5),$I8+$J8,0) -> 1595 | U8: =IF(AND($C8>0,$C8<=U$5,$D8>=U$4),$E8*(1+$F8*(U$4>=$G8))*'Key Assumptions'!$H$12+$H8+IF($M8="Straight-line",$N8,0),0)+IF(AND($M8="Upfront",$C8>=U$4,$C8<=U$5),$K8,0)+IF(AND($C8>0,$C8>=U$4,$C8<=U$5),$I8+$J8,0) -> 1595 | V8: =IF(AND($C8>0,$C8<=V$5,$D8>=V$4),$E8*(1+$F8*(V$4>=$G8))*'Key Assumptions'!$H$12+$H8+IF($M8="Straight-line",$N8,0),0)+IF(AND($M8="Upfront",$C8>=V$4,$C8<=V$5),$K8,0)+IF(AND($C8>0,$C8>=V$4,$C8<=V$5),$I8+$J8,0) -> 1595 | W8: =IF(AND($C8>0,$C8<=W$5,$D8>=W$4),$E8*(1+$F8*(W$4>=$G8))*'Key Assumptions'!$H$12+$H8+IF($M8="Straight-line",$N8,0),0)+IF(AND($M8="Upfront",$C8>=W$4,$C8<=W$5),$K8,0)+IF(AND($C8>0,$C8>=W$4,$C8<=W$5),$I8+$J8,0) -> 1595 | X8: =IF(AND($C8>0,$C8<=X$5,$D8>=X$4),$E8*(1+$F8*(X$4>=$G8))*'Key Assumptions'!$H$12+$H8+IF($M8="Straight-line",$N8,0),0)+IF(AND($M8="Upfront",$C8>=X$4,$C8<=X$5),$K8,0)+IF(AND($C8>0,$C8>=X$4,$C8<=X$5),$I8+$J8,0) -> 1595 | ... AB8: =IF(AND($C8>0,$C8<=AB$5,$D8>=AB$4),$E8*(1+$F8*(AB$4>=$G8))*'Key Assumptions'!$H$12+$H8+IF($M8="Straight-line",$N8,0),0)+IF(AND($M8="Upfront",$C8>=AB$4,$C8<=AB$5),$K8,0)+IF(AND($C8>0,$C8>=AB$4,$C8<=AB$5),$I8+$J8,0) -> 1595 | AC8: =SUM(Q8:AB8) -> 19140 | AD8: =IF($D8>0,$E8*MAX(0,(YEAR($D8)-2027)*12+(MONTH($D8)-12)),0) -> 57420 | AE8: =IF('Key Assumptions'!B66="","",IF($D8<DATE(2027,12,31),"EXPIRED",IF($D8-DATE(2027,12,31)<=90,"RED <90d",IF($D8-DATE(2027,12,31)<=180,"YELLOW <180d","GREEN")))) -> GREEN
A9: ='Key Assumptions'!A67 -> 2 | B9: ='Key Assumptions'!B67 -> 0 | C9: =IF('Key Assumptions'!H67="",0,EDATE('Key Assumptions'!H67,'Key Assumptions'!$I$12)) -> 0 | D9: =IF('Key Assumptions'!I67="",0,'Key Assumptions'!I67) -> 0 | E9: =N('Key Assumptions'!J67) -> 0 | F9: =N('Key Assumptions'!K67) -> 0 | G9: =IF('Key Assumptions'!L67="",0,'Key Assumptions'!L67) -> 0 | H9: =IF('Key Assumptions'!R67="",IF(E9>0,E9*'Key Assumptions'!$B$61,0),'Key Assumptions'!R67) -> 0 | I9: =N('Key Assumptions'!M67) -> 0 | J9: =N('Key Assumptions'!N67) -> 0 | K9: =N('Key Assumptions'!O67) -> 0 | L9: =N('Key Assumptions'!P67) -> 0 | M9: =IF('Key Assumptions'!Q67="",'Key Assumptions'!$B$60,'Key Assumptions'!Q67) -> Straight-line | N9: =IF($M9="Straight-line",IFERROR($K9/($L9*12),0),0) -> 0 | Q9: =IF(AND($C9>0,$C9<=Q$5,$D9>=Q$4),$E9*(1+$F9*(Q$4>=$G9))*'Key Assumptions'!$H$12+$H9+IF($M9="Straight-line",$N9,0),0)+IF(AND($M9="Upfront",$C9>=Q$4,$C9<=Q$5),$K9,0)+IF(AND($C9>0,$C9>=Q$4,$C9<=Q$5),$I9+$J9,0) -> 0 | R9: =IF(AND($C9>0,$C9<=R$5,$D9>=R$4),$E9*(1+$F9*(R$4>=$G9))*'Key Assumptions'!$H$12+$H9+IF($M9="Straight-line",$N9,0),0)+IF(AND($M9="Upfront",$C9>=R$4,$C9<=R$5),$K9,0)+IF(AND($C9>0,$C9>=R$4,$C9<=R$5),$I9+$J9,0) -> 0 | S9: =IF(AND($C9>0,$C9<=S$5,$D9>=S$4),$E9*(1+$F9*(S$4>=$G9))*'Key Assumptions'!$H$12+$H9+IF($M9="Straight-line",$N9,0),0)+IF(AND($M9="Upfront",$C9>=S$4,$C9<=S$5),$K9,0)+IF(AND($C9>0,$C9>=S$4,$C9<=S$5),$I9+$J9,0) -> 0 | T9: =IF(AND($C9>0,$C9<=T$5,$D9>=T$4),$E9*(1+$F9*(T$4>=$G9))*'Key Assumptions'!$H$12+$H9+IF($M9="Straight-line",$N9,0),0)+IF(AND($M9="Upfront",$C9>=T$4,$C9<=T$5),$K9,0)+IF(AND($C9>0,$C9>=T$4,$C9<=T$5),$I9+$J9,0) -> 0 | U9: =IF(AND($C9>0,$C9<=U$5,$D9>=U$4),$E9*(1+$F9*(U$4>=$G9))*'Key Assumptions'!$H$12+$H9+IF($M9="Straight-line",$N9,0),0)+IF(AND($M9="Upfront",$C9>=U$4,$C9<=U$5),$K9,0)+IF(AND($C9>0,$C9>=U$4,$C9<=U$5),$I9+$J9,0) -> 0 | V9: =IF(AND($C9>0,$C9<=V$5,$D9>=V$4),$E9*(1+$F9*(V$4>=$G9))*'Key Assumptions'!$H$12+$H9+IF($M9="Straight-line",$N9,0),0)+IF(AND($M9="Upfront",$C9>=V$4,$C9<=V$5),$K9,0)+IF(AND($C9>0,$C9>=V$4,$C9<=V$5),$I9+$J9,0) -> 0 | W9: =IF(AND($C9>0,$C9<=W$5,$D9>=W$4),$E9*(1+$F9*(W$4>=$G9))*'Key Assumptions'!$H$12+$H9+IF($M9="Straight-line",$N9,0),0)+IF(AND($M9="Upfront",$C9>=W$4,$C9<=W$5),$K9,0)+IF(AND($C9>0,$C9>=W$4,$C9<=W$5),$I9+$J9,0) -> 0 | X9: =IF(AND($C9>0,$C9<=X$5,$D9>=X$4),$E9*(1+$F9*(X$4>=$G9))*'Key Assumptions'!$H$12+$H9+IF($M9="Straight-line",$N9,0),0)+IF(AND($M9="Upfront",$C9>=X$4,$C9<=X$5),$K9,0)+IF(AND($C9>0,$C9>=X$4,$C9<=X$5),$I9+$J9,0) -> 0 | ... AB9: =IF(AND($C9>0,$C9<=AB$5,$D9>=AB$4),$E9*(1+$F9*(AB$4>=$G9))*'Key Assumptions'!$H$12+$H9+IF($M9="Straight-line",$N9,0),0)+IF(AND($M9="Upfront",$C9>=AB$4,$C9<=AB$5),$K9,0)+IF(AND($C9>0,$C9>=AB$4,$C9<=AB$5),$I9+$J9,0) -> 0 | AC9: =SUM(Q9:AB9) -> 0 | AD9: =IF($D9>0,$E9*MAX(0,(YEAR($D9)-2027)*12+(MONTH($D9)-12)),0) -> 0 | AE9: =IF('Key Assumptions'!B67="","",IF($D9<DATE(2027,12,31),"EXPIRED",IF($D9-DATE(2027,12,31)<=90,"RED <90d",IF($D9-DATE(2027,12,31)<=180,"YELLOW <180d","GREEN"))))
A10: ='Key Assumptions'!A68 -> 3 | B10: ='Key Assumptions'!B68 -> 0 | C10: =IF('Key Assumptions'!H68="",0,EDATE('Key Assumptions'!H68,'Key Assumptions'!$I$12)) -> 0 | D10: =IF('Key Assumptions'!I68="",0,'Key Assumptions'!I68) -> 0 | E10: =N('Key Assumptions'!J68) -> 0 | F10: =N('Key Assumptions'!K68) -> 0 | G10: =IF('Key Assumptions'!L68="",0,'Key Assumptions'!L68) -> 0 | H10: =IF('Key Assumptions'!R68="",IF(E10>0,E10*'Key Assumptions'!$B$61,0),'Key Assumptions'!R68) -> 0 | I10: =N('Key Assumptions'!M68) -> 0 | J10: =N('Key Assumptions'!N68) -> 0 | K10: =N('Key Assumptions'!O68) -> 0 | L10: =N('Key Assumptions'!P68) -> 0 | M10: =IF('Key Assumptions'!Q68="",'Key Assumptions'!$B$60,'Key Assumptions'!Q68) -> Straight-line | N10: =IF($M10="Straight-line",IFERROR($K10/($L10*12),0),0) -> 0 | Q10: =IF(AND($C10>0,$C10<=Q$5,$D10>=Q$4),$E10*(1+$F10*(Q$4>=$G10))*'Key Assumptions'!$H$12+$H10+IF($M10="Straight-line",$N10,0),0)+IF(AND($M10="Upfront",$C10>=Q$4,$C10<=Q$5),$K10,0)+IF(AND($C10>0,$C10>=Q$4,$C10<=Q$5),$I10+$J10,0) -> 0 | R10: =IF(AND($C10>0,$C10<=R$5,$D10>=R$4),$E10*(1+$F10*(R$4>=$G10))*'Key Assumptions'!$H$12+$H10+IF($M10="Straight-line",$N10,0),0)+IF(AND($M10="Upfront",$C10>=R$4,$C10<=R$5),$K10,0)+IF(AND($C10>0,$C10>=R$4,$C10<=R$5),$I10+$J10,0) -> 0 | S10: =IF(AND($C10>0,$C10<=S$5,$D10>=S$4),$E10*(1+$F10*(S$4>=$G10))*'Key Assumptions'!$H$12+$H10+IF($M10="Straight-line",$N10,0),0)+IF(AND($M10="Upfront",$C10>=S$4,$C10<=S$5),$K10,0)+IF(AND($C10>0,$C10>=S$4,$C10<=S$5),$I10+$J10,0) -> 0 | T10: =IF(AND($C10>0,$C10<=T$5,$D10>=T$4),$E10*(1+$F10*(T$4>=$G10))*'Key Assumptions'!$H$12+$H10+IF($M10="Straight-line",$N10,0),0)+IF(AND($M10="Upfront",$C10>=T$4,$C10<=T$5),$K10,0)+IF(AND($C10>0,$C10>=T$4,$C10<=T$5),$I10+$J10,0) -> 0 | U10: =IF(AND($C10>0,$C10<=U$5,$D10>=U$4),$E10*(1+$F10*(U$4>=$G10))*'Key Assumptions'!$H$12+$H10+IF($M10="Straight-line",$N10,0),0)+IF(AND($M10="Upfront",$C10>=U$4,$C10<=U$5),$K10,0)+IF(AND($C10>0,$C10>=U$4,$C10<=U$5),$I10+$J10,0) -> 0 | V10: =IF(AND($C10>0,$C10<=V$5,$D10>=V$4),$E10*(1+$F10*(V$4>=$G10))*'Key Assumptions'!$H$12+$H10+IF($M10="Straight-line",$N10,0),0)+IF(AND($M10="Upfront",$C10>=V$4,$C10<=V$5),$K10,0)+IF(AND($C10>0,$C10>=V$4,$C10<=V$5),$I10+$J10,0) -> 0 | W10: =IF(AND($C10>0,$C10<=W$5,$D10>=W$4),$E10*(1+$F10*(W$4>=$G10))*'Key Assumptions'!$H$12+$H10+IF($M10="Straight-line",$N10,0),0)+IF(AND($M10="Upfront",$C10>=W$4,$C10<=W$5),$K10,0)+IF(AND($C10>0,$C10>=W$4,$C10<=W$5),$I10+$J10,0) -> 0 | X10: =IF(AND($C10>0,$C10<=X$5,$D10>=X$4),$E10*(1+$F10*(X$4>=$G10))*'Key Assumptions'!$H$12+$H10+IF($M10="Straight-line",$N10,0),0)+IF(AND($M10="Upfront",$C10>=X$4,$C10<=X$5),$K10,0)+IF(AND($C10>0,$C10>=X$4,$C10<=X$5),$I10+$J10,0) -> 0 | ... AB10: =IF(AND($C10>0,$C10<=AB$5,$D10>=AB$4),$E10*(1+$F10*(AB$4>=$G10))*'Key Assumptions'!$H$12+$H10+IF($M10="Straight-line",$N10,0),0)+IF(AND($M10="Upfront",$C10>=AB$4,$C10<=AB$5),$K10,0)+IF(AND($C10>0,$C10>=AB$4,$C10<=AB$5),$I10+$J10,0) -> 0 | AC10: =SUM(Q10:AB10) -> 0 | AD10: =IF($D10>0,$E10*MAX(0,(YEAR($D10)-2027)*12+(MONTH($D10)-12)),0) -> 0 | AE10: =IF('Key Assumptions'!B68="","",IF($D10<DATE(2027,12,31),"EXPIRED",IF($D10-DATE(2027,12,31)<=90,"RED <90d",IF($D10-DATE(2027,12,31)<=180,"YELLOW <180d","GREEN"))))
A11: ='Key Assumptions'!A69 -> 4 | B11: ='Key Assumptions'!B69 -> 0 | C11: =IF('Key Assumptions'!H69="",0,EDATE('Key Assumptions'!H69,'Key Assumptions'!$I$12)) -> 0 | D11: =IF('Key Assumptions'!I69="",0,'Key Assumptions'!I69) -> 0 | E11: =N('Key Assumptions'!J69) -> 0 | F11: =N('Key Assumptions'!K69) -> 0 | G11: =IF('Key Assumptions'!L69="",0,'Key Assumptions'!L69) -> 0 | H11: =IF('Key Assumptions'!R69="",IF(E11>0,E11*'Key Assumptions'!$B$61,0),'Key Assumptions'!R69) -> 0 | I11: =N('Key Assumptions'!M69) -> 0 | J11: =N('Key Assumptions'!N69) -> 0 | K11: =N('Key Assumptions'!O69) -> 0 | L11: =N('Key Assumptions'!P69) -> 0 | M11: =IF('Key Assumptions'!Q69="",'Key Assumptions'!$B$60,'Key Assumptions'!Q69) -> Straight-line | N11: =IF($M11="Straight-line",IFERROR($K11/($L11*12),0),0) -> 0 | Q11: =IF(AND($C11>0,$C11<=Q$5,$D11>=Q$4),$E11*(1+$F11*(Q$4>=$G11))*'Key Assumptions'!$H$12+$H11+IF($M11="Straight-line",$N11,0),0)+IF(AND($M11="Upfront",$C11>=Q$4,$C11<=Q$5),$K11,0)+IF(AND($C11>0,$C11>=Q$4,$C11<=Q$5),$I11+$J11,0) -> 0 | R11: =IF(AND($C11>0,$C11<=R$5,$D11>=R$4),$E11*(1+$F11*(R$4>=$G11))*'Key Assumptions'!$H$12+$H11+IF($M11="Straight-line",$N11,0),0)+IF(AND($M11="Upfront",$C11>=R$4,$C11<=R$5),$K11,0)+IF(AND($C11>0,$C11>=R$4,$C11<=R$5),$I11+$J11,0) -> 0 | S11: =IF(AND($C11>0,$C11<=S$5,$D11>=S$4),$E11*(1+$F11*(S$4>=$G11))*'Key Assumptions'!$H$12+$H11+IF($M11="Straight-line",$N11,0),0)+IF(AND($M11="Upfront",$C11>=S$4,$C11<=S$5),$K11,0)+IF(AND($C11>0,$C11>=S$4,$C11<=S$5),$I11+$J11,0) -> 0 | T11: =IF(AND($C11>0,$C11<=T$5,$D11>=T$4),$E11*(1+$F11*(T$4>=$G11))*'Key Assumptions'!$H$12+$H11+IF($M11="Straight-line",$N11,0),0)+IF(AND($M11="Upfront",$C11>=T$4,$C11<=T$5),$K11,0)+IF(AND($C11>0,$C11>=T$4,$C11<=T$5),$I11+$J11,0) -> 0 | U11: =IF(AND($C11>0,$C11<=U$5,$D11>=U$4),$E11*(1+$F11*(U$4>=$G11))*'Key Assumptions'!$H$12+$H11+IF($M11="Straight-line",$N11,0),0)+IF(AND($M11="Upfront",$C11>=U$4,$C11<=U$5),$K11,0)+IF(AND($C11>0,$C11>=U$4,$C11<=U$5),$I11+$J11,0) -> 0 | V11: =IF(AND($C11>0,$C11<=V$5,$D11>=V$4),$E11*(1+$F11*(V$4>=$G11))*'Key Assumptions'!$H$12+$H11+IF($M11="Straight-line",$N11,0),0)+IF(AND($M11="Upfront",$C11>=V$4,$C11<=V$5),$K11,0)+IF(AND($C11>0,$C11>=V$4,$C11<=V$5),$I11+$J11,0) -> 0 | W11: =IF(AND($C11>0,$C11<=W$5,$D11>=W$4),$E11*(1+$F11*(W$4>=$G11))*'Key Assumptions'!$H$12+$H11+IF($M11="Straight-line",$N11,0),0)+IF(AND($M11="Upfront",$C11>=W$4,$C11<=W$5),$K11,0)+IF(AND($C11>0,$C11>=W$4,$C11<=W$5),$I11+$J11,0) -> 0 | X11: =IF(AND($C11>0,$C11<=X$5,$D11>=X$4),$E11*(1+$F11*(X$4>=$G11))*'Key Assumptions'!$H$12+$H11+IF($M11="Straight-line",$N11,0),0)+IF(AND($M11="Upfront",$C11>=X$4,$C11<=X$5),$K11,0)+IF(AND($C11>0,$C11>=X$4,$C11<=X$5),$I11+$J11,0) -> 0 | ... AB11: =IF(AND($C11>0,$C11<=AB$5,$D11>=AB$4),$E11*(1+$F11*(AB$4>=$G11))*'Key Assumptions'!$H$12+$H11+IF($M11="Straight-line",$N11,0),0)+IF(AND($M11="Upfront",$C11>=AB$4,$C11<=AB$5),$K11,0)+IF(AND($C11>0,$C11>=AB$4,$C11<=AB$5),$I11+$J11,0) -> 0 | AC11: =SUM(Q11:AB11) -> 0 | AD11: =IF($D11>0,$E11*MAX(0,(YEAR($D11)-2027)*12+(MONTH($D11)-12)),0) -> 0 | AE11: =IF('Key Assumptions'!B69="","",IF($D11<DATE(2027,12,31),"EXPIRED",IF($D11-DATE(2027,12,31)<=90,"RED <90d",IF($D11-DATE(2027,12,31)<=180,"YELLOW <180d","GREEN"))))
A12: ='Key Assumptions'!A70 -> 5 | B12: ='Key Assumptions'!B70 -> 0 | C12: =IF('Key Assumptions'!H70="",0,EDATE('Key Assumptions'!H70,'Key Assumptions'!$I$12)) -> 0 | D12: =IF('Key Assumptions'!I70="",0,'Key Assumptions'!I70) -> 0 | E12: =N('Key Assumptions'!J70) -> 0 | F12: =N('Key Assumptions'!K70) -> 0 | G12: =IF('Key Assumptions'!L70="",0,'Key Assumptions'!L70) -> 0 | H12: =IF('Key Assumptions'!R70="",IF(E12>0,E12*'Key Assumptions'!$B$61,0),'Key Assumptions'!R70) -> 0 | I12: =N('Key Assumptions'!M70) -> 0 | J12: =N('Key Assumptions'!N70) -> 0 | K12: =N('Key Assumptions'!O70) -> 0 | L12: =N('Key Assumptions'!P70) -> 0 | M12: =IF('Key Assumptions'!Q70="",'Key Assumptions'!$B$60,'Key Assumptions'!Q70) -> Straight-line | N12: =IF($M12="Straight-line",IFERROR($K12/($L12*12),0),0) -> 0 | Q12: =IF(AND($C12>0,$C12<=Q$5,$D12>=Q$4),$E12*(1+$F12*(Q$4>=$G12))*'Key Assumptions'!$H$12+$H12+IF($M12="Straight-line",$N12,0),0)+IF(AND($M12="Upfront",$C12>=Q$4,$C12<=Q$5),$K12,0)+IF(AND($C12>0,$C12>=Q$4,$C12<=Q$5),$I12+$J12,0) -> 0 | R12: =IF(AND($C12>0,$C12<=R$5,$D12>=R$4),$E12*(1+$F12*(R$4>=$G12))*'Key Assumptions'!$H$12+$H12+IF($M12="Straight-line",$N12,0),0)+IF(AND($M12="Upfront",$C12>=R$4,$C12<=R$5),$K12,0)+IF(AND($C12>0,$C12>=R$4,$C12<=R$5),$I12+$J12,0) -> 0 | S12: =IF(AND($C12>0,$C12<=S$5,$D12>=S$4),$E12*(1+$F12*(S$4>=$G12))*'Key Assumptions'!$H$12+$H12+IF($M12="Straight-line",$N12,0),0)+IF(AND($M12="Upfront",$C12>=S$4,$C12<=S$5),$K12,0)+IF(AND($C12>0,$C12>=S$4,$C12<=S$5),$I12+$J12,0) -> 0 | T12: =IF(AND($C12>0,$C12<=T$5,$D12>=T$4),$E12*(1+$F12*(T$4>=$G12))*'Key Assumptions'!$H$12+$H12+IF($M12="Straight-line",$N12,0),0)+IF(AND($M12="Upfront",$C12>=T$4,$C12<=T$5),$K12,0)+IF(AND($C12>0,$C12>=T$4,$C12<=T$5),$I12+$J12,0) -> 0 | U12: =IF(AND($C12>0,$C12<=U$5,$D12>=U$4),$E12*(1+$F12*(U$4>=$G12))*'Key Assumptions'!$H$12+$H12+IF($M12="Straight-line",$N12,0),0)+IF(AND($M12="Upfront",$C12>=U$4,$C12<=U$5),$K12,0)+IF(AND($C12>0,$C12>=U$4,$C12<=U$5),$I12+$J12,0) -> 0 | V12: =IF(AND($C12>0,$C12<=V$5,$D12>=V$4),$E12*(1+$F12*(V$4>=$G12))*'Key Assumptions'!$H$12+$H12+IF($M12="Straight-line",$N12,0),0)+IF(AND($M12="Upfront",$C12>=V$4,$C12<=V$5),$K12,0)+IF(AND($C12>0,$C12>=V$4,$C12<=V$5),$I12+$J12,0) -> 0 | W12: =IF(AND($C12>0,$C12<=W$5,$D12>=W$4),$E12*(1+$F12*(W$4>=$G12))*'Key Assumptions'!$H$12+$H12+IF($M12="Straight-line",$N12,0),0)+IF(AND($M12="Upfront",$C12>=W$4,$C12<=W$5),$K12,0)+IF(AND($C12>0,$C12>=W$4,$C12<=W$5),$I12+$J12,0) -> 0 | X12: =IF(AND($C12>0,$C12<=X$5,$D12>=X$4),$E12*(1+$F12*(X$4>=$G12))*'Key Assumptions'!$H$12+$H12+IF($M12="Straight-line",$N12,0),0)+IF(AND($M12="Upfront",$C12>=X$4,$C12<=X$5),$K12,0)+IF(AND($C12>0,$C12>=X$4,$C12<=X$5),$I12+$J12,0) -> 0 | ... AB12: =IF(AND($C12>0,$C12<=AB$5,$D12>=AB$4),$E12*(1+$F12*(AB$4>=$G12))*'Key Assumptions'!$H$12+$H12+IF($M12="Straight-line",$N12,0),0)+IF(AND($M12="Upfront",$C12>=AB$4,$C12<=AB$5),$K12,0)+IF(AND($C12>0,$C12>=AB$4,$C12<=AB$5),$I12+$J12,0) -> 0 | AC12: =SUM(Q12:AB12) -> 0 | AD12: =IF($D12>0,$E12*MAX(0,(YEAR($D12)-2027)*12+(MONTH($D12)-12)),0) -> 0 | AE12: =IF('Key Assumptions'!B70="","",IF($D12<DATE(2027,12,31),"EXPIRED",IF($D12-DATE(2027,12,31)<=90,"RED <90d",IF($D12-DATE(2027,12,31)<=180,"YELLOW <180d","GREEN"))))
A13: ='Key Assumptions'!A71 -> 6 | B13: ='Key Assumptions'!B71 -> 0 | C13: =IF('Key Assumptions'!H71="",0,EDATE('Key Assumptions'!H71,'Key Assumptions'!$I$12)) -> 0 | D13: =IF('Key Assumptions'!I71="",0,'Key Assumptions'!I71) -> 0 | E13: =N('Key Assumptions'!J71) -> 0 | F13: =N('Key Assumptions'!K71) -> 0 | G13: =IF('Key Assumptions'!L71="",0,'Key Assumptions'!L71) -> 0 | H13: =IF('Key Assumptions'!R71="",IF(E13>0,E13*'Key Assumptions'!$B$61,0),'Key Assumptions'!R71) -> 0 | I13: =N('Key Assumptions'!M71) -> 0 | J13: =N('Key Assumptions'!N71) -> 0 | K13: =N('Key Assumptions'!O71) -> 0 | L13: =N('Key Assumptions'!P71) -> 0 | M13: =IF('Key Assumptions'!Q71="",'Key Assumptions'!$B$60,'Key Assumptions'!Q71) -> Straight-line | N13: =IF($M13="Straight-line",IFERROR($K13/($L13*12),0),0) -> 0 | Q13: =IF(AND($C13>0,$C13<=Q$5,$D13>=Q$4),$E13*(1+$F13*(Q$4>=$G13))*'Key Assumptions'!$H$12+$H13+IF($M13="Straight-line",$N13,0),0)+IF(AND($M13="Upfront",$C13>=Q$4,$C13<=Q$5),$K13,0)+IF(AND($C13>0,$C13>=Q$4,$C13<=Q$5),$I13+$J13,0) -> 0 | R13: =IF(AND($C13>0,$C13<=R$5,$D13>=R$4),$E13*(1+$F13*(R$4>=$G13))*'Key Assumptions'!$H$12+$H13+IF($M13="Straight-line",$N13,0),0)+IF(AND($M13="Upfront",$C13>=R$4,$C13<=R$5),$K13,0)+IF(AND($C13>0,$C13>=R$4,$C13<=R$5),$I13+$J13,0) -> 0 | S13: =IF(AND($C13>0,$C13<=S$5,$D13>=S$4),$E13*(1+$F13*(S$4>=$G13))*'Key Assumptions'!$H$12+$H13+IF($M13="Straight-line",$N13,0),0)+IF(AND($M13="Upfront",$C13>=S$4,$C13<=S$5),$K13,0)+IF(AND($C13>0,$C13>=S$4,$C13<=S$5),$I13+$J13,0) -> 0 | T13: =IF(AND($C13>0,$C13<=T$5,$D13>=T$4),$E13*(1+$F13*(T$4>=$G13))*'Key Assumptions'!$H$12+$H13+IF($M13="Straight-line",$N13,0),0)+IF(AND($M13="Upfront",$C13>=T$4,$C13<=T$5),$K13,0)+IF(AND($C13>0,$C13>=T$4,$C13<=T$5),$I13+$J13,0) -> 0 | U13: =IF(AND($C13>0,$C13<=U$5,$D13>=U$4),$E13*(1+$F13*(U$4>=$G13))*'Key Assumptions'!$H$12+$H13+IF($M13="Straight-line",$N13,0),0)+IF(AND($M13="Upfront",$C13>=U$4,$C13<=U$5),$K13,0)+IF(AND($C13>0,$C13>=U$4,$C13<=U$5),$I13+$J13,0) -> 0 | V13: =IF(AND($C13>0,$C13<=V$5,$D13>=V$4),$E13*(1+$F13*(V$4>=$G13))*'Key Assumptions'!$H$12+$H13+IF($M13="Straight-line",$N13,0),0)+IF(AND($M13="Upfront",$C13>=V$4,$C13<=V$5),$K13,0)+IF(AND($C13>0,$C13>=V$4,$C13<=V$5),$I13+$J13,0) -> 0 | W13: =IF(AND($C13>0,$C13<=W$5,$D13>=W$4),$E13*(1+$F13*(W$4>=$G13))*'Key Assumptions'!$H$12+$H13+IF($M13="Straight-line",$N13,0),0)+IF(AND($M13="Upfront",$C13>=W$4,$C13<=W$5),$K13,0)+IF(AND($C13>0,$C13>=W$4,$C13<=W$5),$I13+$J13,0) -> 0 | X13: =IF(AND($C13>0,$C13<=X$5,$D13>=X$4),$E13*(1+$F13*(X$4>=$G13))*'Key Assumptions'!$H$12+$H13+IF($M13="Straight-line",$N13,0),0)+IF(AND($M13="Upfront",$C13>=X$4,$C13<=X$5),$K13,0)+IF(AND($C13>0,$C13>=X$4,$C13<=X$5),$I13+$J13,0) -> 0 | ... AB13: =IF(AND($C13>0,$C13<=AB$5,$D13>=AB$4),$E13*(1+$F13*(AB$4>=$G13))*'Key Assumptions'!$H$12+$H13+IF($M13="Straight-line",$N13,0),0)+IF(AND($M13="Upfront",$C13>=AB$4,$C13<=AB$5),$K13,0)+IF(AND($C13>0,$C13>=AB$4,$C13<=AB$5),$I13+$J13,0) -> 0 | AC13: =SUM(Q13:AB13) -> 0 | AD13: =IF($D13>0,$E13*MAX(0,(YEAR($D13)-2027)*12+(MONTH($D13)-12)),0) -> 0 | AE13: =IF('Key Assumptions'!B71="","",IF($D13<DATE(2027,12,31),"EXPIRED",IF($D13-DATE(2027,12,31)<=90,"RED <90d",IF($D13-DATE(2027,12,31)<=180,"YELLOW <180d","GREEN"))))
