Workbook

Sheet Instructions
A1: INSTRUCTIONS — READ FIRST
A2: DRAFT FOR DISCUSSION – SUBJECT TO LEGAL, GRANT AND FINANCIAL REVIEW
B5: Deliverable 10 — 30-Year Editable Financial Model
B6: Lumbee Tribe of North Carolina & LREMC Technologies, LLC d/b/a RIVR Tech
B7: TBCP grant-funded hybrid broadband network — southeastern North Carolina.
B9: DRAFT / PLACEHOLDER WARNING
B10: Every dollar figure, rate, and count in this workbook is a PLACEHOLDER for negotiation. The model is a working draft — subject to legal, grant, and financial review. Do NOT rely on any output as a final term. Replace the amber input cells with negotiated values.
B12: COLOR LEGEND
B13: • AMBER = INPUT — edit these. All assumptions live on the Assumptions sheet.
B14: • BLUE = FORMULA — do not edit; these compute from inputs.
B15: • GREEN = OUTPUT / RESULT — headline numbers and NPV/IRR.
B16: The model is designed to be used WITHOUT editing any formula — change inputs only.
B18: THE THREE SWITCHES (all on the Assumptions sheet, top block)
B19: • Scenario switch — type 1 (Low), 2 (Base), or 3 (High). Drives every scenario-dependent driver (take rate, ARPU, churn, bad debt, inflation, construction cost) via CHOOSE.
... B40: This file is generated by a script and stores formulas (not cached results). Open it in Excel / LibreOffice and allow calculation (F9) so every blue/green cell evaluates.
A42: Legend: | B42: INPUT (edit these) | C42: FORMULA (do not edit) | D42: OUTPUT / RESULT

Sheet Dashboard
A1: EXECUTIVE DASHBOARD
A2: DRAFT FOR DISCUSSION – SUBJECT TO LEGAL, GRANT AND FINANCIAL REVIEW
A3: Active scenario / term / option, headline outputs, and formula-check roll-up. All values are live formulas.
A4: Legend: | B4: INPUT (edit these) | C4: FORMULA (do not edit) | D4: OUTPUT / RESULT
B6: ACTIVE SETTINGS | E6: INDIVIDUAL CHECKS
B7: Scenario | C7: =Assumptions!$D$7 | E7: Construction_Budget | F7: =Construction_Budget!F21
B8: IRU term (years) | C8: =Assumptions!$C$8 | E8: Grant_Funding | F8: =Grant_Funding!F16
B9: Revenue-share option | C9: =Assumptions!$C$10 | E9: Grant_Funding | F9: =Grant_Funding!F17
B10: TBCP grant amount | C10: =Assumptions!$C$29 | E10: Homes_Passed | F10: =Homes_Passed!F38
B11: Homes passed (total) | C11: =Assumptions!$C$30 | E11: Take_Rate_Customers | F11: =Take_Rate_Customers!F38
B12: Discount rate (NPV) | C12: =Assumptions!$C$44 | E12: Revenue | F12: =Revenue!F38
E13: Operating_Expenses | F13: =Operating_Expenses!F38
B14: HEADLINE OUTPUTS (active case) | E14: Capital_Replacement | F14: =Capital_Replacement!F38
B15: Year-30 gross revenue | C15: =Revenue!$I$36 | E15: Revenue_Share_Options | F15: =Revenue_Share_Options!F38
B16: Total Tribal receipts (undiscounted) | C16: =Tribal_Economics!$B$39 | E16: Annual_Cash_Flow | F16: =Annual_Cash_Flow!F38
B17: Tribal NPV | C17: =Tribal_Economics!$B$38 | E17: Consolidated_Project | F17: =Consolidated_Project!F41
B18: RIVR Tech NPV | C18: =RIVR_Tech_Economics!$B$39 | E18: Case_Engine | F18: =Case_Engine!F112
B19: RIVR Tech IRR | C19: =RIVR_Tech_Economics!$B$40
B20: RIVR payback (year) | C20: =RIVR_Tech_Economics!$B$41
B21: Project NPV | C21: =Consolidated_Project!$B$38
B22: Project IRR | C22: =Consolidated_Project!$B$39
B24: FORMULA-CHECK ROLL-UP
B25: Checks passing | C25: =--(Construction_Budget!F21="PASS")+--(Grant_Funding!F16="PASS")+--(Grant_Funding!F17="PASS")+--(Homes_Passed!F38="PASS")+--(Take_Rate_Customers!F38="PASS")+--(Revenue!F38="PASS")+--(Operating_Expenses!F38="PASS")+--(Capital_Replacement!F38="PASS")+--(Revenue_Share_Options!F38="PASS")+--(Annual_Cash_Flow!F38="PASS")+--(Consolidated_Project!F41="PASS")+--(Case_Engine!F112="PASS")
B26: Total checks | C26: 12
B27: OVERALL STATUS | C27: =IF((--(Construction_Budget!F21="PASS")+--(Grant_Funding!F16="PASS")+--(Grant_Funding!F17="PASS")+--(Homes_Passed!F38="PASS")+--(Take_Rate_Customers!F38="PASS")+--(Revenue!F38="PASS")+--(Operating_Expenses!F38="PASS")+--(Capital_Replacement!F38="PASS")+--(Revenue_Share_Options!F38="PASS")+--(Annual_Cash_Flow!F38="PASS")+--(Consolidated_Project!F41="PASS")+--(Case_Engine!F112="PASS"))=12,"ALL CHECKS PASS","REVIEW — SEE FAILED CHECKS")

Sheet Assumptions
A1: ASSUMPTIONS — All Editable Input Drivers
A2: DRAFT FOR DISCUSSION – SUBJECT TO LEGAL, GRANT AND FINANCIAL REVIEW
A3: Amber cells are INPUTS you may edit. Blue cells are FORMULAS (do not edit).
A4: Legend: | B4: INPUT (edit these) | C4: FORMULA (do not edit) | D4: OUTPUT / RESULT
B6: MODEL SWITCHES
B7: Scenario switch (1 = Low, 2 = Base, 3 = High) | C7: 2 | D7: =CHOOSE($C$7,"LOW","BASE","HIGH") | G7: Drives every scenario-dependent driver via CHOOSE.
B8: IRU term switch (20 / 25 / 30 years — recommend 30) | C8: 30 | G8: Analysis horizon for NPV/IRR. Revenue & payments beyond term = 0.
B9: Revenue-share option switch (1=A 2=B 3=C 4=D 5=E) | C9: 4 | D9: =CHOOSE($C$9,"A","B","C","D","E") | G9: Recommended: D (Hybrid). All five computed side-by-side.
B10: Active option name | C10: =CHOOSE($C$9,"A — Fixed Annual","B — % Gross Revenue","C — % Operating Cash Flow","D — Hybrid (Base + Share)","E — Holiday then Stepped")
B12: SCENARIO-DEPENDENT DRIVERS
B13: Driver | C13: Low | D13: Base | E13: High | F13: Active | G13: Units / Notes
B14: Terminal take rate (net penetration) | C14: 0.35 | D14: 0.45 | E14: 0.55 | F14: =CHOOSE($C$7,$C$14,$D$14,$E$14) | G14: % of homes passed
B15: Take-rate ramp (years to terminal) | C15: 6 | D15: 5 | E15: 4 | F15: =CHOOSE($C$7,$C$15,$D$15,$E$15) | G15: years
B16: Residential ARPU (monthly) | C16: 65 | D16: 75 | E16: 85 | F16: =CHOOSE($C$7,$C$16,$D$16,$E$16) | G16: $/sub/month
B17: Business ARPU (monthly) | C17: 200 | D17: 250 | E17: 300 | F17: =CHOOSE($C$7,$C$17,$D$17,$E$17) | G17: $/sub/month
B18: Enterprise ARPU (monthly) | C18: 800 | D18: 1000 | E18: 1200 | F18: =CHOOSE($C$7,$C$18,$D$18,$E$18) | G18: $/sub/month
B19: Voice ARPU (monthly) | C19: 30 | D19: 35 | E19: 40 | F19: =CHOOSE($C$7,$C$19,$D$19,$E$19) | G19: $/sub/month
B20: Enterprise subscribers at maturity | C20: 15 | D20: 25 | E20: 40 | F20: =CHOOSE($C$7,$C$20,$D$20,$E$20) | G20: count
B21: Wholesale revenue at maturity (annual) | C21: 300000 | D21: 500000 | E21: 750000 | F21: =CHOOSE($C$7,$C$21,$D$21,$E$21) | G21: $/year
B22: Annual customer churn | C22: 0.18 | D22: 0.14 | E22: 0.1 | F22: =CHOOSE($C$7,$C$22,$D$22,$E$22) | G22: % per year
B23: Bad debt | C23: 0.025 | D23: 0.015 | E23: 0.01 | F23: =CHOOSE($C$7,$C$23,$D$23,$E$23) | G23: % of recurring rev
B24: Operating-cost inflation | C24: 0.035 | D24: 0.03 | E24: 0.025 | F24: =CHOOSE($C$7,$C$24,$D$24,$E$24) | G24: % per year
B25: Construction cost factor | C25: 1.15 | D25: 1 | E25: 0.9 | F25: =CHOOSE($C$7,$C$25,$D$25,$E$25) | G25: x on budget (High=cheaper)
B27: SINGLE INPUTS (not case-varying)
B28: Input | C28: Value | G28: Units / Notes
B29: TBCP grant amount (funds Tribal Assets) | C29: 25000000 | G29: $ (placeholder $25M)
B30: Homes passed (total) | C30: 8500 | G30: premises (placeholder 8,500)
B31: Build-out period | C31: 3 | G31: years to complete homes passed
B32: Business penetration | C32: 0.04 | G32: % of homes passed
B33: Voice attach rate | C33: 0.4 | G33: % of residential subs
B34: Installation fee (one-time) | C34: 100 | G34: $/new connect
B35: ARPU / price escalation | C35: 0.02 | G35: % per year (set 0 to disable)
B36: Network operations cost | C36: 120 | G36: $/subscriber/year
B37: Network maintenance | C37: 0.03 | G37: % of construction cost/yr
B38: Staffing headcount | C38: 12 | G38: FTEs
B39: Loaded cost per FTE | C39: 85000 | G39: $/FTE/year
B40: Marketing | C40: 0.06 | G40: % of gross revenue
... B46: Reserved-capacity value to Lumbee Tribe | C46: 150000 | G46: $/yr in-kind (memo)
B48: REVENUE-SHARE OPTION INPUTS
B49: Option A — fixed annual payment | C49: 500000 | G49: $/yr (escalated)
...

Sheet Construction_Budget
A1: CONSTRUCTION BUDGET — Capital Line Items (Year 0)
A2: DRAFT FOR DISCUSSION – SUBJECT TO LEGAL, GRANT AND FINANCIAL REVIEW
A3: Qty x Unit Cost = Extended. Construction cost factor (scenario) applied to the total.
B5: Capital Line Item | C5: Quantity | D5: Unit Cost | E5: Extended | F5: Notes
B6: Outside-plant (OSP) fiber | C6: 250 | D6: 45000 | E6: =$C6*$D6 | F6: route miles x $/mi
B7: Conduit / directional bore | C7: 80 | D7: 30000 | E7: =$C7*$D7 | F7: miles x $/mi
B8: Electronics (OLT / aggregation / core) | C8: 1 | D8: 4000000 | E8: =$C8*$D8 | F8: lump — basis for replacement cycle
B9: Fiber huts / cabinets / power | C9: 25 | D9: 60000 | E9: =$C9*$D9 | F9: sites x $/site
B10: Service drops | C10: 3825 | D10: 650 | E10: =$C10*$D10 | F10: connects x $/drop
B11: Engineering & design | C11: 1 | D11: 1500000 | E11: =$C11*$D11 | F11: lump
B12: Permitting, make-ready & pole attach | C12: 1 | D12: 1200000 | E12: =$C12*$D12 | F12: lump
B13: Subtotal (direct construction) | E13: =SUM($E6:$E12)
B14: Contingency | C14: 0.1 | E14: =$C14*$E13
B15: Subtotal + contingency | E15: =$E13+$E14
B16: Construction cost factor (active scenario) | E16: =Assumptions!$F$25
B17: TOTAL CONSTRUCTION COST | E17: =$E15*$E16
B19: Electronics replacement basis (factored) | E19: =Construction_Budget!$E$8*Construction_Budget!$E$16
B21: CHECK: no #REF / all line items numeric | F21: =IF(ISNUMBER($E17),"PASS","FAIL")

Sheet Grant_Funding
A1: GRANT FUNDING — Sources & Uses
A2: DRAFT FOR DISCUSSION – SUBJECT TO LEGAL, GRANT AND FINANCIAL REVIEW
A3: TBCP funds the Tribal Assets. TBCP does not require non-federal match. Sources must equal Uses.
B5: Sources & Uses | C5: Amount | D5: Notes
B6: SOURCES
B7: TBCP federal grant | C7: =Assumptions!$C$29 | D7: Placeholder $25,000,000 — funds Tribal Assets
B8: Non-federal match (not required by TBCP) | C8: 0 | D8: Editable — TBCP Round 3 requires no match
B9: TOTAL SOURCES | C9: =SUM($C7:$C8)
B11: USES
B12: Total construction cost | C12: =Construction_Budget!$E$17 | D12: From Construction_Budget
B13: Surplus / (funding gap) plug | C13: =$C9-$C12 | D13: Positive = surplus for contingency; negative = gap (flag)
B14: TOTAL USES | C14: =SUM($C12:$C13)
B16: CHECK: Sources = Uses (reconciles) | F16: =IF(ABS($C9-$C14)<1,"PASS","FAIL")
B17: CHECK: Uses do not exceed grant sources (no funding gap) | F17: =IF($C9>=$C12,"PASS","FAIL — FUNDING GAP")

Sheet Homes_Passed
A1: HOMES PASSED — Build-out Schedule
A2: DRAFT FOR DISCUSSION – SUBJECT TO LEGAL, GRANT AND FINANCIAL REVIEW
A3: Year 0 = construction. Serviceable homes ramp over the build-out period.
A5: Year | B5: Homes Passed (cum.) | C5: New Homes Passed | D5: % Complete
A6: 0 | B6: 0 | C6: =$B6-0 | D6: =$B6/Assumptions!$C$30
A7: 1 | B7: =Assumptions!$C$30*MIN(1,$A7/Assumptions!$C$31) | C7: =$B7-$B6 | D7: =$B7/Assumptions!$C$30
A8: 2 | B8: =Assumptions!$C$30*MIN(1,$A8/Assumptions!$C$31) | C8: =$B8-$B7 | D8: =$B8/Assumptions!$C$30
A9: 3 | B9: =Assumptions!$C$30*MIN(1,$A9/Assumptions!$C$31) | C9: =$B9-$B8 | D9: =$B9/Assumptions!$C$30
A10: 4 | B10: =Assumptions!$C$30*MIN(1,$A10/Assumptions!$C$31) | C10: =$B10-$B9 | D10: =$B10/Assumptions!$C$30
A11: 5 | B11: =Assumptions!$C$30*MIN(1,$A11/Assumptions!$C$31) | C11: =$B11-$B10 | D11: =$B11/Assumptions!$C$30
A12: 6 | B12: =Assumptions!$C$30*MIN(1,$A12/Assumptions!$C$31) | C12: =$B12-$B11 | D12: =$B12/Assumptions!$C$30
A13: 7 | B13: =Assumptions!$C$30*MIN(1,$A13/Assumptions!$C$31) | C13: =$B13-$B12 | D13: =$B13/Assumptions!$C$30
A14: 8 | B14: =Assumptions!$C$30*MIN(1,$A14/Assumptions!$C$31) | C14: =$B14-$B13 | D14: =$B14/Assumptions!$C$30
A15: 9 | B15: =Assumptions!$C$30*MIN(1,$A15/Assumptions!$C$31) | C15: =$B15-$B14 | D15: =$B15/Assumptions!$C$30
A16: 10 | B16: =Assumptions!$C$30*MIN(1,$A16/Assumptions!$C$31) | C16: =$B16-$B15 | D16: =$B16/Assumptions!$C$30
A17: 11 | B17: =Assumptions!$C$30*MIN(1,$A17/Assumptions!$C$31) | C17: =$B17-$B16 | D17: =$B17/Assumptions!$C$30
A18: 12 | B18: =Assumptions!$C$30*MIN(1,$A18/Assumptions!$C$31) | C18: =$B18-$B17 | D18: =$B18/Assumptions!$C$30
... A36: 30 | B36: =Assumptions!$C$30*MIN(1,$A36/Assumptions!$C$31) | C36: =$B36-$B35 | D36: =$B36/Assumptions!$C$30
B38: CHECK: homes passed never exceed total (Assumptions) | F38: =IF(MAX($B6:$B36)<=Assumptions!$C$30+0.5,"PASS","FAIL")

Sheet Take_Rate_Customers
A1: TAKE RATE & CUSTOMERS
A2: DRAFT FOR DISCUSSION – SUBJECT TO LEGAL, GRANT AND FINANCIAL REVIEW
A3: Net penetration ramps to terminal. Gross adds (incl. churn replacement) drive install revenue.
A5: Year | B5: Take Rate | C5: Residential Subs | D5: Business Subs | E5: Enterprise Subs | F5: Voice Subs | G5: Total Premise Subs | H5: Gross Adds
A6: 0 | B6: 0 | C6: 0 | D6: 0 | E6: 0 | F6: 0 | G6: 0 | H6: 0
A7: 1 | B7: =Assumptions!$F$14*MIN(1,$A7/Assumptions!$F$15) | C7: =Homes_Passed!$B$7*$B7 | D7: =Homes_Passed!$B$7*Assumptions!$C$32 | E7: =Assumptions!$F$20*MIN(1,$A7/Assumptions!$F$15) | F7: =$C7*Assumptions!$C$33 | G7: =$C7+$D7+$E7 | H7: =MAX(0,$G7-0)+0*Assumptions!$F$22
A8: 2 | B8: =Assumptions!$F$14*MIN(1,$A8/Assumptions!$F$15) | C8: =Homes_Passed!$B$8*$B8 | D8: =Homes_Passed!$B$8*Assumptions!$C$32 | E8: =Assumptions!$F$20*MIN(1,$A8/Assumptions!$F$15) | F8: =$C8*Assumptions!$C$33 | G8: =$C8+$D8+$E8 | H8: =MAX(0,$G8-$G7)+$G7*Assumptions!$F$22
A9: 3 | B9: =Assumptions!$F$14*MIN(1,$A9/Assumptions!$F$15) | C9: =Homes_Passed!$B$9*$B9 | D9: =Homes_Passed!$B$9*Assumptions!$C$32 | E9: =Assumptions!$F$20*MIN(1,$A9/Assumptions!$F$15) | F9: =$C9*Assumptions!$C$33 | G9: =$C9+$D9+$E9 | H9: =MAX(0,$G9-$G8)+$G8*Assumptions!$F$22
A10: 4 | B10: =Assumptions!$F$14*MIN(1,$A10/Assumptions!$F$15) | C10: =Homes_Passed!$B$10*$B10 | D10: =Homes_Passed!$B$10*Assumptions!$C$32 | E10: =Assumptions!$F$20*MIN(1,$A10/Assumptions!$F$15) | F10: =$C10*Assumptions!$C$33 | G10: =$C10+$D10+$E10 | H10: =MAX(0,$G10-$G9)+$G9*Assumptions!$F$22
A11: 5 | B11: =Assumptions!$F$14*MIN(1,$A11/Assumptions!$F$15) | C11: =Homes_Passed!$B$11*$B11 | D11: =Homes_Passed!$B$11*Assumptions!$C$32 | E11: =Assumptions!$F$20*MIN(1,$A11/Assumptions!$F$15) | F11: =$C11*Assumptions!$C$33 | G11: =$C11+$D11+$E11 | H11: =MAX(0,$G11-$G10)+$G10*Assumptions!$F$22
A12: 6 | B12: =Assumptions!$F$14*MIN(1,$A12/Assumptions!$F$15) | C12: =Homes_Passed!$B$12*$B12 | D12: =Homes_Passed!$B$12*Assumptions!$C$32 | E12: =Assumptions!$F$20*MIN(1,$A12/Assumptions!$F$15) | F12: =$C12*Assumptions!$C$33 | G12: =$C12+$D12+$E12 | H12: =MAX(0,$G12-$G11)+$G11*Assumptions!$F$22
A13: 7 | B13: =Assumptions!$F$14*MIN(1,$A13/Assumptions!$F$15) | C13: =Homes_Passed!$B$13*$B13 | D13: =Homes_Passed!$B$13*Assumptions!$C$32 | E13: =Assumptions!$F$20*MIN(1,$A13/Assumptions!$F$15) | F13: =$C13*Assumptions!$C$33 | G13: =$C13+$D13+$E13 | H13: =MAX(0,$G13-$G12)+$G12*Assumptions!$F$22
A14: 8 | B14: =Assumptions!$F$14*MIN(1,$A14/Assumptions!$F$15) | C14: =Homes_Passed!$B$14*$B14 | D14: =Homes_Passed!$B$14*Assumptions!$C$32 | E14: =Assumptions!$F$20*MIN(1,$A14/Assumptions!$F$15) | F14: =$C14*Assumptions!$C$33 | G14: =$C14+$D14+$E14 | H14: =MAX(0,$G14-$G13)+$G13*Assumptions!$F$22
A15: 9 | B15: =Assumptions!$F$14*MIN(1,$A15/Assumptions!$F$15) | C15: =Homes_Passed!$B$15*$B15 | D15: =Homes_Passed!$B$15*Assumptions!$C$32 | E15: =Assumptions!$F$20*MIN(1,$A15/Assumptions!$F$15) | F15: =$C15*Assumptions!$C$33 | G15: =$C15+$D15+$E15 | H15: =MAX(0,$G15-$G14)+$G14*Assumptions!$F$22
A16: 10 | B16: =Assumptions!$F$14*MIN(1,$A16/Assumptions!$F$15) | C16: =Homes_Passed!$B$16*$B16 | D16: =Homes_Passed!$B$16*Assumptions!$C$32 | E16: =Assumptions!$F$20*MIN(1,$A16/Assumptions!$F$15) | F16: =$C16*Assumptions!$C$33 | G16: =$C16+$D16+$E16 | H16: =MAX(0,$G16-$G15)+$G15*Assumptions!$F$22
A17: 11 | B17: =Assumptions!$F$14*MIN(1,$A17/Assumptions!$F$15) | C17: =Homes_Passed!$B$17*$B17 | D17: =Homes_Passed!$B$17*Assumptions!$C$32 | E17: =Assumptions!$F$20*MIN(1,$A17/Assumptions!$F$15) | F17: =$C17*Assumptions!$C$33 | G17: =$C17+$D17+$E17 | H17: =MAX(0,$G17-$G16)+$G16*Assumptions!$F$22
A18: 12 | B18: =Assumptions!$F$14*MIN(1,$A18/Assumptions!$F$15) | C18: =Homes_Passed!$B$18*$B18 | D18: =Homes_Passed!$B$18*Assumptions!$C$32 | E18: =Assumptions!$F$20*MIN(1,$A18/Assumptions!$F$15) | F18: =$C18*Assumptions!$C$33 | G18: =$C18+$D18+$E18 | H18: =MAX(0,$G18-$G17)+$G17*Assumptions!$F$22
A19: 13 | B19: =Assumptions!$F$14*MIN(1,$A19/Assumptions!$F$15) | C19: =Homes_Passed!$B$19*$B19 | D19: =Homes_Passed!$B$19*Assumptions!$C$32 | E19: =Assumptions!$F$20*MIN(1,$A19/Assumptions!$F$15) | F19: =$C19*Assumptions!$C$33 | G19: =$C19+$D19+$E19 | H19: =MAX(0,$G19-$G18)+$G18*Assumptions!$F$22
A20: 14 | B20: =Assumptions!$F$14*MIN(1,$A20/Assumptions!$F$15) | C20: =Homes_Passed!$B$20*$B20 | D20: =Homes_Passed!$B$20*Assumptions!$C$32 | E20: =Assumptions!$F$20*MIN(1,$A20/Assumptions!$F$15) | F20: =$C20*Assumptions!$C$33 | G20: =$C20+$D20+$E20 | H20: =MAX(0,$G20-$G19)+$G19*Assumptions!$F$22
A21: 15 | B21: =Assumptions!$F$14*MIN(1,$A21/Assumptions!$F$15) | C21: =Homes_Passed!$B$21*$B21 | D21: =Homes_Passed!$B$21*Assumptions!$C$32 | E21: =Assumptions!$F$20*MIN(1,$A21/Assumptions!$F$15) | F21: =$C21*Assumptions!$C$33 | G21: =$C21+$D21+$E21 | H21: =MAX(0,$G21-$G20)+$G20*Assumptions!$F$22
A22: 16 | B22: =Assumptions!$F$14*MIN(1,$A22/Assumptions!$F$15) | C22: =Homes_Passed!$B$22*$B22 | D22: =Homes_Passed!$B$22*Assumptions!$C$32 | E22: =Assumptions!$F$20*MIN(1,$A22/Assumptions!$F$15) | F22: =$C22*Assumptions!$C$33 | G22: =$C22+$D22+$E22 | H22: =MAX(0,$G22-$G21)+$G21*Assumptions!$F$22
A23: 17 | B23: =Assumptions!$F$14*MIN(1,$A23/Assumptions!$F$15) | C23: =Homes_Passed!$B$23*$B23 | D23: =Homes_Passed!$B$23*Assumptions!$C$32 | E23: =Assumptions!$F$20*MIN(1,$A23/Assumptions!$F$15) | F23: =$C23*Assumptions!$C$33 | G23: =$C23+$D23+$E23 | H23: =MAX(0,$G23-$G22)+$G22*Assumptions!$F$22
A24: 18 | B24: =Assumptions!$F$14*MIN(1,$A24/Assumptions!$F$15) | C24: =Homes_Passed!$B$24*$B24 | D24: =Homes_Passed!$B$24*Assumptions!$C$32 | E24: =Assumptions!$F$20*MIN(1,$A24/Assumptions!$F$15) | F24: =$C24*Assumptions!$C$33 | G24: =$C24+$D24+$E24 | H24: =MAX(0,$G24-$G23)+$G23*Assumptions!$F$22
A25: 19 | B25: =Assumptions!$F$14*MIN(1,$A25/Assumptions!$F$15) | C25: =Homes_Passed!$B$25*$B25 | D25: =Homes_Passed!$B$25*Assumptions!$C$32 | E25: =Assumptions!$F$20*MIN(1,$A25/Assumptions!$F$15) | F25: =$C25*Assumptions!$C$33 | G25: =$C25+$D25+$E25 | H25: =MAX(0,$G25-$G24)+$G24*Assumptions!$F$22
A26: 20 | B26: =Assumptions!$F$14*MIN(1,$A26/Assumptions!$F$15) | C26: =Homes_Passed!$B$26*$B26 | D26: =Homes_Passed!$B$26*Assumptions!$C$32 | E26: =Assumptions!$F$20*MIN(1,$A26/Assumptions!$F$15) | F26: =$C26*Assumptions!$C$33 | G26: =$C26+$D26+$E26 | H26: =MAX(0,$G26-$G25)+$G25*Assumptions!$F$22
A27: 21 | B27: =Assumptions!$F$14*MIN(1,$A27/Assumptions!$F$15) | C27: =Homes_Passed!$B$27*$B27 | D27: =Homes_Passed!$B$27*Assumptions!$C$32 | E27: =Assumptions!$F$20*MIN(1,$A27/Assumptions!$F$15) | F27: =$C27*Assumptions!$C$33 | G27: =$C27+$D27+$E27 | H27: =MAX(0,$G27-$G26)+$G26*Assumptions!$F$22
A28: 22 | B28: =Assumptions!$F$14*MIN(1,$A28/Assumptions!$F$15) | C28: =Homes_Passed!$B$28*$B28 | D28: =Homes_Passed!$B$28*Assumptions!$C$32 | E28: =Assumptions!$F$20*MIN(1,$A28/Assumptions!$F$15) | F28: =$C28*Assumptions!$C$33 | G28: =$C28+$D28+$E28 | H28: =MAX(0,$G28-$G27)+$G27*Assumptions!$F$22
A29: 23 | B29: =Assumptions!$F$14*MIN(1,$A29/Assumptions!$F$15) | C29: =Homes_Passed!$B$29*$B29 | D29: =Homes_Passed!$B$29*Assumptions!$C$32 | E29: =Assumptions!$F$20*MIN(1,$A29/Assumptions!$F$15) | F29: =$C29*Assumptions!$C$33 | G29: =$C29+$D29+$E29 | H29: =MAX(0,$G29-$G28)+$G28*Assumptions!$F$22
A30: 24 | B30: =Assumptions!$F$14*MIN(1,$A30/Assumptions!$F$15) | C30: =Homes_Passed!$B$30*$B30 | D30: =Homes_Passed!$B$30*Assumptions!$C$32 | E30: =Assumptions!$F$20*MIN(1,$A30/Assumptions!$F$15) | F30: =$C30*Assumptions!$C$33 | G30: =$C30+$D30+$E30 | H30: =MAX(0,$G30-$G29)+$G29*Assumptions!$F$22
A31: 25 | B31: =Assumptions!$F$14*MIN(1,$A31/Assumptions!$F$15) | C31: =Homes_Passed!$B$31*$B31 | D31: =Homes_Passed!$B$31*Assumptions!$C$32 | E31: =Assumptions!$F$20*MIN(1,$A31/Assumptions!$F$15) | F31: =$C31*Assumptions!$C$33 | G31: =$C31+$D31+$E31 | H31: =MAX(0,$G31-$G30)+$G30*Assumptions!$F$22
A32: 26 | B32: =Assumptions!$F$14*MIN(1,$A32/Assumptions!$F$15) | C32: =Homes_Passed!$B$32*$B32 | D32: =Homes_Passed!$B$32*Assumptions!$C$32 | E32: =Assumptions!$F$20*MIN(1,$A32/Assumptions!$F$15) | F32: =$C32*Assumptions!$C$33 | G32: =$C32+$D32+$E32 | H32: =MAX(0,$G32-$G31)+$G31*Assumptions!$F$22
A33: 27 | B33: =Assumptions!$F$14*MIN(1,$A33/Assumptions!$F$15) | C33: =Homes_Passed!$B$33*$B33 | D33: =Homes_Passed!$B$33*Assumptions!$C$32 | E33: =Assumptions!$F$20*MIN(1,$A33/Assumptions!$F$15) | F33: =$C33*Assumptions!$C$33 | G33: =$C33+$D33+$E33 | H33: =MAX(0,$G33-$G32)+$G32*Assumptions!$F$22
A34: 28 | B34: =Assumptions!$F$14*MIN(1,$A34/Assumptions!$F$15) | C34: =Homes_Passed!$B$34*$B34 | D34: =Homes_Passed!$B$34*Assumptions!$C$32 | E34: =Assumptions!$F$20*MIN(1,$A34/Assumptions!$F$15) | F34: =$C34*Assumptions!$C$33 | G34: =$C34+$D34+$E34 | H34: =MAX(0,$G34-$G33)+$G33*Assumptions!$F$22
A35: 29 | B35: =Assumptions!$F$14*MIN(1,$A35/Assumptions!$F$15) | C35: =Homes_Passed!$B$35*$B35 | D35: =Homes_Passed!$B$35*Assumptions!$C$32 | E35: =Assumptions!$F$20*MIN(1,$A35/Assumptions!$F$15) | F35: =$C35*Assumptions!$C$33 | G35: =$C35+$D35+$E35 | H35: =MAX(0,$G35-$G34)+$G34*Assumptions!$F$22
A36: 30 | B36: =Assumptions!$F$14*MIN(1,$A36/Assumptions!$F$15) | C36: =Homes_Passed!$B$36*$B36 | D36: =Homes_Passed!$B$36*Assumptions!$C$32 | E36: =Assumptions!$F$20*MIN(1,$A36/Assumptions!$F$15) | F36: =$C36*Assumptions!$C$33 | G36: =$C36+$D36+$E36 | H36: =MAX(0,$G36-$G35)+$G35*Assumptions!$F$22
B38: CHECK: residential subs never exceed homes passed | F38: =IF(SUMPRODUCT(--($C6:$C36>Homes_Passed!$B6:$B36))=0,"PASS","FAIL")

Sheet Revenue
A1: REVENUE — ARPU x Customers
A2: DRAFT FOR DISCUSSION – SUBJECT TO LEGAL, GRANT AND FINANCIAL REVIEW
A3: Monthly ARPU x 12. Revenue beyond the selected IRU term is zero (term gate).
A5: Year | B5: Residential | C5: Business | D5: Enterprise | E5: Voice | F5: Wholesale | G5: Installation | H5: Recurring Subtotal | I5: TOTAL GROSS REVENUE
A6: 0 | B6: 0 | C6: 0 | D6: 0 | E6: 0 | F6: 0 | G6: 0 | H6: 0 | I6: 0
A7: 1 | B7: =Take_Rate_Customers!$C$7*Assumptions!$F$16*(1+Assumptions!$C$35)^($A7-1)*12*IF($A7>Assumptions!$C$8,0,1) | C7: =Take_Rate_Customers!$D$7*Assumptions!$F$17*(1+Assumptions!$C$35)^($A7-1)*12*IF($A7>Assumptions!$C$8,0,1) | D7: =Take_Rate_Customers!$E$7*Assumptions!$F$18*(1+Assumptions!$C$35)^($A7-1)*12*IF($A7>Assumptions!$C$8,0,1) | E7: =Take_Rate_Customers!$F$7*Assumptions!$F$19*(1+Assumptions!$C$35)^($A7-1)*12*IF($A7>Assumptions!$C$8,0,1) | F7: =Assumptions!$F$21*MIN(1,$A7/Assumptions!$C$31)*IF($A7>Assumptions!$C$8,0,1) | G7: =Take_Rate_Customers!$H$7*Assumptions!$C$34*IF($A7>Assumptions!$C$8,0,1) | H7: =SUM($B7:$F7) | I7: =$H7+$G7
A8: 2 | B8: =Take_Rate_Customers!$C$8*Assumptions!$F$16*(1+Assumptions!$C$35)^($A8-1)*12*IF($A8>Assumptions!$C$8,0,1) | C8: =Take_Rate_Customers!$D$8*Assumptions!$F$17*(1+Assumptions!$C$35)^($A8-1)*12*IF($A8>Assumptions!$C$8,0,1) | D8: =Take_Rate_Customers!$E$8*Assumptions!$F$18*(1+Assumptions!$C$35)^($A8-1)*12*IF($A8>Assumptions!$C$8,0,1) | E8: =Take_Rate_Customers!$F$8*Assumptions!$F$19*(1+Assumptions!$C$35)^($A8-1)*12*IF($A8>Assumptions!$C$8,0,1) | F8: =Assumptions!$F$21*MIN(1,$A8/Assumptions!$C$31)*IF($A8>Assumptions!$C$8,0,1) | G8: =Take_Rate_Customers!$H$8*Assumptions!$C$34*IF($A8>Assumptions!$C$8,0,1) | H8: =SUM($B8:$F8) | I8: =$H8+$G8
A9: 3 | B9: =Take_Rate_Customers!$C$9*Assumptions!$F$16*(1+Assumptions!$C$35)^($A9-1)*12*IF($A9>Assumptions!$C$8,0,1) | C9: =Take_Rate_Customers!$D$9*Assumptions!$F$17*(1+Assumptions!$C$35)^($A9-1)*12*IF($A9>Assumptions!$C$8,0,1) | D9: =Take_Rate_Customers!$E$9*Assumptions!$F$18*(1+Assumptions!$C$35)^($A9-1)*12*IF($A9>Assumptions!$C$8,0,1) | E9: =Take_Rate_Customers!$F$9*Assumptions!$F$19*(1+Assumptions!$C$35)^($A9-1)*12*IF($A9>Assumptions!$C$8,0,1) | F9: =Assumptions!$F$21*MIN(1,$A9/Assumptions!$C$31)*IF($A9>Assumptions!$C$8,0,1) | G9: =Take_Rate_Customers!$H$9*Assumptions!$C$34*IF($A9>Assumptions!$C$8,0,1) | H9: =SUM($B9:$F9) | I9: =$H9+$G9
A10: 4 | B10: =Take_Rate_Customers!$C$10*Assumptions!$F$16*(1+Assumptions!$C$35)^($A10-1)*12*IF($A10>Assumptions!$C$8,0,1) | C10: =Take_Rate_Customers!$D$10*Assumptions!$F$17*(1+Assumptions!$C$35)^($A10-1)*12*IF($A10>Assumptions!$C$8,0,1) | D10: =Take_Rate_Customers!$E$10*Assumptions!$F$18*(1+Assumptions!$C$35)^($A10-1)*12*IF($A10>Assumptions!$C$8,0,1) | E10: =Take_Rate_Customers!$F$10*Assumptions!$F$19*(1+Assumptions!$C$35)^($A10-1)*12*IF($A10>Assumptions!$C$8,0,1) | F10: =Assumptions!$F$21*MIN(1,$A10/Assumptions!$C$31)*IF($A10>Assumptions!$C$8,0,1) | G10: =Take_Rate_Customers!$H$10*Assumptions!$C$34*IF($A10>Assumptions!$C$8,0,1) | H10: =SUM($B10:$F10) | I10: =$H10+$G10
A11: 5 | B11: =Take_Rate_Customers!$C$11*Assumptions!$F$16*(1+Assumptions!$C$35)^($A11-1)*12*IF($A11>Assumptions!$C$8,0,1) | C11: =Take_Rate_Customers!$D$11*Assumptions!$F$17*(1+Assumptions!$C$35)^($A11-1)*12*IF($A11>Assumptions!$C$8,0,1) | D11: =Take_Rate_Customers!$E$11*Assumptions!$F$18*(1+Assumptions!$C$35)^($A11-1)*12*IF($A11>Assumptions!$C$8,0,1) | E11: =Take_Rate_Customers!$F$11*Assumptions!$F$19*(1+Assumptions!$C$35)^($A11-1)*12*IF($A11>Assumptions!$C$8,0,1) | F11: =Assumptions!$F$21*MIN(1,$A11/Assumptions!$C$31)*IF($A11>Assumptions!$C$8,0,1) | G11: =Take_Rate_Customers!$H$11*Assumptions!$C$34*IF($A11>Assumptions!$C$8,0,1) | H11: =SUM($B11:$F11) | I11: =$H11+$G11
A12: 6 | B12: =Take_Rate_Customers!$C$12*Assumptions!$F$16*(1+Assumptions!$C$35)^($A12-1)*12*IF($A12>Assumptions!$C$8,0,1) | C12: =Take_Rate_Customers!$D$12*Assumptions!$F$17*(1+Assumptions!$C$35)^($A12-1)*12*IF($A12>Assumptions!$C$8,0,1) | D12: =Take_Rate_Customers!$E$12*Assumptions!$F$18*(1+Assumptions!$C$35)^($A12-1)*12*IF($A12>Assumptions!$C$8,0,1) | E12: =Take_Rate_Customers!$F$12*Assumptions!$F$19*(1+Assumptions!$C$35)^($A12-1)*12*IF($A12>Assumptions!$C$8,0,1) | F12: =Assumptions!$F$21*MIN(1,$A12/Assumptions!$C$31)*IF($A12>Assumptions!$C$8,0,1) | G12: =Take_Rate_Customers!$H$12*Assumptions!$C$34*IF($A12>Assumptions!$C$8,0,1) | H12: =SUM($B12:$F12) | I12: =$H12+$G12
A13: 7 | B13: =Take_Rate_Customers!$C$13*Assumptions!$F$16*(1+Assumptions!$C$35)^($A13-1)*12*IF($A13>Assumptions!$C$8,0,1) | C13: =Take_Rate_Customers!$D$13*Assumptions!$F$17*(1+Assumptions!$C$35)^($A13-1)*12*IF($A13>Assumptions!$C$8,0,1) | D13: =Take_Rate_Customers!$E$13*Assumptions!$F$18*(1+Assumptions!$C$35)^($A13-1)*12*IF($A13>Assumptions!$C$8,0,1) | E13: =Take_Rate_Customers!$F$13*Assumptions!$F$19*(1+Assumptions!$C$35)^($A13-1)*12*IF($A13>Assumptions!$C$8,0,1) | F13: =Assumptions!$F$21*MIN(1,$A13/Assumptions!$C$31)*IF($A13>Assumptions!$C$8,0,1) | G13: =Take_Rate_Customers!$H$13*Assumptions!$C$34*IF($A13>Assumptions!$C$8,0,1) | H13: =SUM($B13:$F13) | I13: =$H13+$G13
A14: 8 | B14: =Take_Rate_Customers!$C$14*Assumptions!$F$16*(1+Assumptions!$C$35)^($A14-1)*12*IF($A14>Assumptions!$C$8,0,1) | C14: =Take_Rate_Customers!$D$14*Assumptions!$F$17*(1+Assumptions!$C$35)^($A14-1)*12*IF($A14>Assumptions!$C$8,0,1) | D14: =Take_Rate_Customers!$E$14*Assumptions!$F$18*(1+Assumptions!$C$35)^($A14-1)*12*IF($A14>Assumptions!$C$8,0,1) | E14: =Take_Rate_Customers!$F$14*Assumptions!$F$19*(1+Assumptions!$C$35)^($A14-1)*12*IF($A14>Assumptions!$C$8,0,1) | F14: =Assumptions!$F$21*MIN(1,$A14/Assumptions!$C$31)*IF($A14>Assumptions!$C$8,0,1) | G14: =Take_Rate_Customers!$H$14*Assumptions!$C$34*IF($A14>Assumptions!$C$8,0,1) | H14: =SUM($B14:$F14) | I14: =$H14+$G14
A15: 9 | B15: =Take_Rate_Customers!$C$15*Assumptions!$F$16*(1+Assumptions!$C$35)^($A15-1)*12*IF($A15>Assumptions!$C$8,0,1) | C15: =Take_Rate_Customers!$D$15*Assumptions!$F$17*(1+Assumptions!$C$35)^($A15-1)*12*IF($A15>Assumptions!$C$8,0,1) | D15: =Take_Rate_Customers!$E$15*Assumptions!$F$18*(1+Assumptions!$C$35)^($A15-1)*12*IF($A15>Assumptions!$C$8,0,1) | E15: =Take_Rate_Customers!$F$15*Assumptions!$F$19*(1+Assumptions!$C$35)^($A15-1)*12*IF($A15>Assumptions!$C$8,0,1) | F15: =Assumptions!$F$21*MIN(1,$A15/Assumptions!$C$31)*IF($A15>Assumptions!$C$8,0,1) | G15: =Take_Rate_Customers!$H$15*Assumptions!$C$34*IF($A15>Assumptions!$C$8,0,1) | H15: =SUM($B15:$F15) | I15: =$H15+$G15
A16: 10 | B16: =Take_Rate_Customers!$C$16*Assumptions!$F$16*(1+Assumptions!$C$35)^($A16-1)*12*IF($A16>Assumptions!$C$8,0,1) | C16: =Take_Rate_Customers!$D$16*Assumptions!$F$17*(1+Assumptions!$C$35)^($A16-1)*12*IF($A16>Assumptions!$C$8,0,1) | D16: =Take_Rate_Customers!$E$16*Assumptions!$F$18*(1+Assumptions!$C$35)^($A16-1)*12*IF($A16>Assumptions!$C$8,0,1) | E16: =Take_Rate_Customers!$F$16*Assumptions!$F$19*(1+Assumptions!$C$35)^($A16-1)*12*IF($A16>Assumptions!$C$8,0,1) | F16: =Assumptions!$F$21*MIN(1,$A16/Assumptions!$C$31)*IF($A16>Assumptions!$C$8,0,1) | G16: =Take_Rate_Customers!$H$16*Assumptions!$C$34*IF($A16>Assumptions!$C$8,0,1) | H16: =SUM($B16:$F16) | I16: =$H16+$G16
A17: 11 | B17: =Take_Rate_Customers!$C$17*Assumptions!$F$16*(1+Assumptions!$C$35)^($A17-1)*12*IF($A17>Assumptions!$C$8,0,1) | C17: =Take_Rate_Customers!$D$17*Assumptions!$F$17*(1+Assumptions!$C$35)^($A17-1)*12*IF($A17>Assumptions!$C$8,0,1) | D17: =Take_Rate_Customers!$E$17*Assumptions!$F$18*(1+Assumptions!$C$35)^($A17-1)*12*IF($A17>Assumptions!$C$8,0,1) | E17: =Take_Rate_Customers!$F$17*Assumptions!$F$19*(1+Assumptions!$C$35)^($A17-1)*12*IF($A17>Assumptions!$C$8,0,1) | F17: =Assumptions!$F$21*MIN(1,$A17/Assumptions!$C$31)*IF($A17>Assumptions!$C$8,0,1) | G17: =Take_Rate_Customers!$H$17*Assumptions!$C$34*IF($A17>Assumptions!$C$8,0,1) | H17: =SUM($B17:$F17) | I17: =$H17+$G17
A18: 12 | B18: =Take_Rate_Customers!$C$18*Assumptions!$F$16*(1+Assumptions!$C$35)^($A18-1)*12*IF($A18>Assumptions!$C$8,0,1) | C18: =Take_Rate_Customers!$D$18*Assumptions!$F$17*(1+Assumptions!$C$35)^($A18-1)*12*IF($A18>Assumptions!$C$8,0,1) | D18: =Take_Rate_Customers!$E$18*Assumptions!$F$18*(1+Assumptions!$C$35)^($A18-1)*12*IF($A18>Assumptions!$C$8,0,1) | E18: =Take_Rate_Customers!$F$18*Assumptions!$F$19*(1+Assumptions!$C$35)^($A18-1)*12*IF($A18>Assumptions!$C$8,0,1) | F18: =Assumptions!$F$21*MIN(1,$A18/Assumptions!$C$31)*IF($A18>Assumptions!$C$8,0,1) | G18: =Take_Rate_Customers!$H$18*Assumptions!$C$34*IF($A18>Assumptions!$C$8,0,1) | H18: =SUM($B18:$F18) | I18: =$H18+$G18
A19: 13 | B19: =Take_Rate_Customers!$C$19*Assumptions!$F$16*(1+Assumptions!$C$35)^($A19-1)*12*IF($A19>Assumptions!$C$8,0,1) | C19: =Take_Rate_Customers!$D$19*Assumptions!$F$17*(1+Assumptions!$C$35)^($A19-1)*12*IF($A19>Assumptions!$C$8,0,1) | D19: =Take_Rate_Customers!$E$19*Assumptions!$F$18*(1+Assumptions!$C$35)^($A19-1)*12*IF($A19>Assumptions!$C$8,0,1) | E19: =Take_Rate_Customers!$F$19*Assumptions!$F$19*(1+Assumptions!$C$35)^($A19-1)*12*IF($A19>Assumptions!$C$8,0,1) | F19: =Assumptions!$F$21*MIN(1,$A19/Assumptions!$C$31)*IF($A19>Assumptions!$C$8,0,1) | G19: =Take_Rate_Customers!$H$19*Assumptions!$C$34*IF($A19>Assumptions!$C$8,0,1) | H19: =SUM($B19:$F19) | I19: =$H19+$G19
A20: 14 | B20: =Take_Rate_Customers!$C$20*Assumptions!$F$16*(1+Assumptions!$C$35)^($A20-1)*12*IF($A20>Assumptions!$C$8,0,1) | C20: =Take_Rate_Customers!$D$20*Assumptions!$F$17*(1+Assumptions!$C$35)^($A20-1)*12*IF($A20>Assumptions!$C$8,0,1) | D20: =Take_Rate_Customers!$E$20*Assumptions!$F$18*(1+Assumptions!$C$35)^($A20-1)*12*IF($A20>Assumptions!$C$8,0,1) | E20: =Take_Rate_Customers!$F$20*Assumptions!$F$19*(1+Assumptions!$C$35)^($A20-1)*12*IF($A20>Assumptions!$C$8,0,1) | F20: =Assumptions!$F$21*MIN(1,$A20/Assumptions!$C$31)*IF($A20>Assumptions!$C$8,0,1) | G20: =Take_Rate_Customers!$H$20*Assumptions!$C$34*IF($A20>Assumptions!$C$8,0,1) | H20: =SUM($B20:$F20) | I20: =$H20+$G20
A21: 15 | B21: =Take_Rate_Customers!$C$21*Assumptions!$F$16*(1+Assumptions!$C$35)^($A21-1)*12*IF($A21>Assumptions!$C$8,0,1) | C21: =Take_Rate_Customers!$D$21*Assumptions!$F$17*(1+Assumptions!$C$35)^($A21-1)*12*IF($A21>Assumptions!$C$8,0,1) | D21: =Take_Rate_Customers!$E$21*Assumptions!$F$18*(1+Assumptions!$C$35)^($A21-1)*12*IF($A21>Assumptions!$C$8,0,1) | E21: =Take_Rate_Customers!$F$21*Assumptions!$F$19*(1+Assumptions!$C$35)^($A21-1)*12*IF($A21>Assumptions!$C$8,0,1) | F21: =Assumptions!$F$21*MIN(1,$A21/Assumptions!$C$31)*IF($A21>Assumptions!$C$8,0,1) | G21: =Take_Rate_Customers!$H$21*Assumptions!$C$34*IF($A21>Assumptions!$C$8,0,1) | H21: =SUM($B21:$F21) | I21: =$H21+$G21
A22: 16 | B22: =Take_Rate_Customers!$C$22*Assumptions!$F$16*(1+Assumptions!$C$35)^($A22-1)*12*IF($A22>Assumptions!$C$8,0,1) | C22: =Take_Rate_Customers!$D$22*Assumptions!$F$17*(1+Assumptions!$C$35)^($A22-1)*12*IF($A22>Assumptions!$C$8,0,1) | D22: =Take_Rate_Customers!$E$22*Assumptions!$F$18*(1+Assumptions!$C$35)^($A22-1)*12*IF($A22>Assumptions!$C$8,0,1) | E22: =Take_Rate_Customers!$F$22*Assumptions!$F$19*(1+Assumptions!$C$35)^($A22-1)*12*IF($A22>Assumptions!$C$8,0,1) | F22: =Assumptions!$F$21*MIN(1,$A22/Assumptions!$C$31)*IF($A22>Assumptions!$C$8,0,1) | G22: =Take_Rate_Customers!$H$22*Assumptions!$C$34*IF($A22>Assumptions!$C$8,0,1) | H22: =SUM($B22:$F22) | I22: =$H22+$G22
A23: 17 | B23: =Take_Rate_Customers!$C$23*Assumptions!$F$16*(1+Assumptions!$C$35)^($A23-1)*12*IF($A23>Assumptions!$C$8,0,1) | C23: =Take_Rate_Customers!$D$23*Assumptions!$F$17*(1+Assumptions!$C$35)^($A23-1)*12*IF($A23>Assumptions!$C$8,0,1) | D23: =Take_Rate_Customers!$E$23*Assumptions!$F$18*(1+Assumptions!$C$35)^($A23-1)*12*IF($A23>Assumptions!$C$8,0,1) | E23: =Take_Rate_Customers!$F$23*Assumptions!$F$19*(1+Assumptions!$C$35)^($A23-1)*12*IF($A23>Assumptions!$C$8,0,1) | F23: =Assumptions!$F$21*MIN(1,$A23/Assumptions!$C$31)*IF($A23>Assumptions!$C$8,0,1) | G23: =Take_Rate_Customers!$H$23*Assumptions!$C$34*IF($A23>Assumptions!$C$8,0,1) | H23: =SUM($B23:$F23) | I23: =$H23+$G23
A24: 18 | B24: =Take_Rate_Customers!$C$24*Assumptions!$F$16*(1+Assumptions!$C$35)^($A24-1)*12*IF($A24>Assumptions!$C$8,0,1) | C24: =Take_Rate_Customers!$D$24*Assumptions!$F$17*(1+Assumptions!$C$35)^($A24-1)*12*IF($A24>Assumptions!$C$8,0,1) | D24: =Take_Rate_Customers!$E$24*Assumptions!$F$18*(1+Assumptions!$C$35)^($A24-1)*12*IF($A24>Assumptions!$C$8,0,1) | E24: =Take_Rate_Customers!$F$24*Assumptions!$F$19*(1+Assumptions!$C$35)^($A24-1)*12*IF($A24>Assumptions!$C$8,0,1) | F24: =Assumptions!$F$21*MIN(1,$A24/Assumptions!$C$31)*IF($A24>Assumptions!$C$8,0,1) | G24: =Take_Rate_Customers!$H$24*Assumptions!$C$34*IF($A24>Assumptions!$C$8,0,1) | H24: =SUM($B24:$F24) | I24: =$H24+$G24
A25: 19 | B25: =Take_Rate_Customers!$C$25*Assumptions!$F$16*(1+Assumptions!$C$35)^($A25-1)*12*IF($A25>Assumptions!$C$8,0,1) | C25: =Take_Rate_Customers!$D$25*Assumptions!$F$17*(1+Assumptions!$C$35)^($A25-1)*12*IF($A25>Assumptions!$C$8,0,1) | D25: =Take_Rate_Customers!$E$25*Assumptions!$F$18*(1+Assumptions!$C$35)^($A25-1)*12*IF($A25>Assumptions!$C$8,0,1) | E25: =Take_Rate_Customers!$F$25*Assumptions!$F$19*(1+Assumptions!$C$35)^($A25-1)*12*IF($A25>Assumptions!$C$8,0,1) | F25: =Assumptions!$F$21*MIN(1,$A25/Assumptions!$C$31)*IF($A25>Assumptions!$C$8,0,1) | G25: =Take_Rate_Customers!$H$25*Assumptions!$C$34*IF($A25>Assumptions!$C$8,0,1) | H25: =SUM($B25:$F25) | I25: =$H25+$G25
A26: 20 | B26: =Take_Rate_Customers!$C$26*Assumptions!$F$16*(1+Assumptions!$C$35)^($A26-1)*12*IF($A26>Assumptions!$C$8,0,1) | C26: =Take_Rate_Customers!$D$26*Assumptions!$F$17*(1+Assumptions!$C$35)^($A26-1)*12*IF($A26>Assumptions!$C$8,0,1) | D26: =Take_Rate_Customers!$E$26*Assumptions!$F$18*(1+Assumptions!$C$35)^($A26-1)*12*IF($A26>Assumptions!$C$8,0,1) | E26: =Take_Rate_Customers!$F$26*Assumptions!$F$19*(1+Assumptions!$C$35)^($A26-1)*12*IF($A26>Assumptions!$C$8,0,1) | F26: =Assumptions!$F$21*MIN(1,$A26/Assumptions!$C$31)*IF($A26>Assumptions!$C$8,0,1) | G26: =Take_Rate_Customers!$H$26*Assumptions!$C$34*IF($A26>Assumptions!$C$8,0,1) | H26: =SUM($B26:$F26) | I26: =$H26+$G26
A27: 21 | B27: =Take_Rate_Customers!$C$27*Assumptions!$F$16*(1+Assumptions!$C$35)^($A27-1)*12*IF($A27>Assumptions!$C$8,0,1) | C27: =Take_Rate_Customers!$D$27*Assumptions!$F$17*(1+Assumptions!$C$35)^($A27-1)*12*IF($A27>Assumptions!$C$8,0,1) | D27: =Take_Rate_Customers!$E$27*Assumptions!$F$18*(1+Assumptions!$C$35)^($A27-1)*12*IF($A27>Assumptions!$C$8,0,1) | E27: =Take_Rate_Customers!$F$27*Assumptions!$F$19*(1+Assumptions!$C$35)^($A27-1)*12*IF($A27>Assumptions!$C$8,0,1) | F27: =Assumptions!$F$21*MIN(1,$A27/Assumptions!$C$31)*IF($A27>Assumptions!$C$8,0,1) | G27: =Take_Rate_Customers!$H$27*Assumptions!$C$34*IF($A27>Assumptions!$C$8,0,1) | H27: =SUM($B27:$F27) | I27: =$H27+$G27
A28: 22 | B28: =Take_Rate_Customers!$C$28*Assumptions!$F$16*(1+Assumptions!$C$35)^($A28-1)*12*IF($A28>Assumptions!$C$8,0,1) | C28: =Take_Rate_Customers!$D$28*Assumptions!$F$17*(1+Assumptions!$C$35)^($A28-1)*12*IF($A28>Assumptions!$C$8,0,1) | D28: =Take_Rate_Customers!$E$28*Assumptions!$F$18*(1+Assumptions!$C$35)^($A28-1)*12*IF($A28>Assumptions!$C$8,0,1) | E28: =Take_Rate_Customers!$F$28*Assumptions!$F$19*(1+Assumptions!$C$35)^($A28-1)*12*IF($A28>Assumptions!$C$8,0,1) | F28: =Assumptions!$F$21*MIN(1,$A28/Assumptions!$C$31)*IF($A28>Assumptions!$C$8,0,1) | G28: =Take_Rate_Customers!$H$28*Assumptions!$C$34*IF($A28>Assumptions!$C$8,0,1) | H28: =SUM($B28:$F28) | I28: =$H28+$G28
A29: 23 | B29: =Take_Rate_Customers!$C$29*Assumptions!$F$16*(1+Assumptions!$C$35)^($A29-1)*12*IF($A29>Assumptions!$C$8,0,1) | C29: =Take_Rate_Customers!$D$29*Assumptions!$F$17*(1+Assumptions!$C$35)^($A29-1)*12*IF($A29>Assumptions!$C$8,0,1) | D29: =Take_Rate_Customers!$E$29*Assumptions!$F$18*(1+Assumptions!$C$35)^($A29-1)*12*IF($A29>Assumptions!$C$8,0,1) | E29: =Take_Rate_Customers!$F$29*Assumptions!$F$19*(1+Assumptions!$C$35)^($A29-1)*12*IF($A29>Assumptions!$C$8,0,1) | F29: =Assumptions!$F$21*MIN(1,$A29/Assumptions!$C$31)*IF($A29>Assumptions!$C$8,0,1) | G29: =Take_Rate_Customers!$H$29*Assumptions!$C$34*IF($A29>Assumptions!$C$8,0,1) | H29: =SUM($B29:$F29) | I29: =$H29+$G29
A30: 24 | B30: =Take_Rate_Customers!$C$30*Assumptions!$F$16*(1+Assumptions!$C$35)^($A30-1)*12*IF($A30>Assumptions!$C$8,0,1) | C30: =Take_Rate_Customers!$D$30*Assumptions!$F$17*(1+Assumptions!$C$35)^($A30-1)*12*IF($A30>Assumptions!$C$8,0,1) | D30: =Take_Rate_Customers!$E$30*Assumptions!$F$18*(1+Assumptions!$C$35)^($A30-1)*12*IF($A30>Assumptions!$C$8,0,1) | E30: =Take_Rate_Customers!$F$30*Assumptions!$F$19*(1+Assumptions!$C$35)^($A30-1)*12*IF($A30>Assumptions!$C$8,0,1) | F30: =Assumptions!$F$21*MIN(1,$A30/Assumptions!$C$31)*IF($A30>Assumptions!$C$8,0,1) | G30: =Take_Rate_Customers!$H$30*Assumptions!$C$34*IF($A30>Assumptions!$C$8,0,1) | H30: =SUM($B30:$F30) | I30: =$H30+$G30
A31: 25 | B31: =Take_Rate_Customers!$C$31*Assumptions!$F$16*(1+Assumptions!$C$35)^($A31-1)*12*IF($A31>Assumptions!$C$8,0,1) | C31: =Take_Rate_Customers!$D$31*Assumptions!$F$17*(1+Assumptions!$C$35)^($A31-1)*12*IF($A31>Assumptions!$C$8,0,1) | D31: =Take_Rate_Customers!$E$31*Assumptions!$F$18*(1+Assumptions!$C$35)^($A31-1)*12*IF($A31>Assumptions!$C$8,0,1) | E31: =Take_Rate_Customers!$F$31*Assumptions!$F$19*(1+Assumptions!$C$35)^($A31-1)*12*IF($A31>Assumptions!$C$8,0,1) | F31: =Assumptions!$F$21*MIN(1,$A31/Assumptions!$C$31)*IF($A31>Assumptions!$C$8,0,1) | G31: =Take_Rate_Customers!$H$31*Assumptions!$C$34*IF($A31>Assumptions!$C$8,0,1) | H31: =SUM($B31:$F31) | I31: =$H31+$G31
A32: 26 | B32: =Take_Rate_Customers!$C$32*Assumptions!$F$16*(1+Assumptions!$C$35)^($A32-1)*12*IF($A32>Assumptions!$C$8,0,1) | C32: =Take_Rate_Customers!$D$32*Assumptions!$F$17*(1+Assumptions!$C$35)^($A32-1)*12*IF($A32>Assumptions!$C$8,0,1) | D32: =Take_Rate_Customers!$E$32*Assumptions!$F$18*(1+Assumptions!$C$35)^($A32-1)*12*IF($A32>Assumptions!$C$8,0,1) | E32: =Take_Rate_Customers!$F$32*Assumptions!$F$19*(1+Assumptions!$C$35)^($A32-1)*12*IF($A32>Assumptions!$C$8,0,1) | F32: =Assumptions!$F$21*MIN(1,$A32/Assumptions!$C$31)*IF($A32>Assumptions!$C$8,0,1) | G32: =Take_Rate_Customers!$H$32*Assumptions!$C$34*IF($A32>Assumptions!$C$8,0,1) | H32: =SUM($B32:$F32) | I32: =$H32+$G32
A33: 27 | B33: =Take_Rate_Customers!$C$33*Assumptions!$F$16*(1+Assumptions!$C$35)^($A33-1)*12*IF($A33>Assumptions!$C$8,0,1) | C33: =Take_Rate_Customers!$D$33*Assumptions!$F$17*(1+Assumptions!$C$35)^($A33-1)*12*IF($A33>Assumptions!$C$8,0,1) | D33: =Take_Rate_Customers!$E$33*Assumptions!$F$18*(1+Assumptions!$C$35)^($A33-1)*12*IF($A33>Assumptions!$C$8,0,1) | E33: =Take_Rate_Customers!$F$33*Assumptions!$F$19*(1+Assumptions!$C$35)^($A33-1)*12*IF($A33>Assumptions!$C$8,0,1) | F33: =Assumptions!$F$21*MIN(1,$A33/Assumptions!$C$31)*IF($A33>Assumptions!$C$8,0,1) | G33: =Take_Rate_Customers!$H$33*Assumptions!$C$34*IF($A33>Assumptions!$C$8,0,1) | H33: =SUM($B33:$F33) | I33: =$H33+$G33
A34: 28 | B34: =Take_Rate_Customers!$C$34*Assumptions!$F$16*(1+Assumptions!$C$35)^($A34-1)*12*IF($A34>Assumptions!$C$8,0,1) | C34: =Take_Rate_Customers!$D$34*Assumptions!$F$17*(1+Assumptions!$C$35)^($A34-1)*12*IF($A34>Assumptions!$C$8,0,1) | D34: =Take_Rate_Customers!$E$34*Assumptions!$F$18*(1+Assumptions!$C$35)^($A34-1)*12*IF($A34>Assumptions!$C$8,0,1) | E34: =Take_Rate_Customers!$F$34*Assumptions!$F$19*(1+Assumptions!$C$35)^($A34-1)*12*IF($A34>Assumptions!$C$8,0,1) | F34: =Assumptions!$F$21*MIN(1,$A34/Assumptions!$C$31)*IF($A34>Assumptions!$C$8,0,1) | G34: =Take_Rate_Customers!$H$34*Assumptions!$C$34*IF($A34>Assumptions!$C$8,0,1) | H34: =SUM($B34:$F34) | I34: =$H34+$G34
A35: 29 | B35: =Take_Rate_Customers!$C$35*Assumptions!$F$16*(1+Assumptions!$C$35)^($A35-1)*12*IF($A35>Assumptions!$C$8,0,1) | C35: =Take_Rate_Customers!$D$35*Assumptions!$F$17*(1+Assumptions!$C$35)^($A35-1)*12*IF($A35>Assumptions!$C$8,0,1) | D35: =Take_Rate_Customers!$E$35*Assumptions!$F$18*(1+Assumptions!$C$35)^($A35-1)*12*IF($A35>Assumptions!$C$8,0,1) | E35: =Take_Rate_Customers!$F$35*Assumptions!$F$19*(1+Assumptions!$C$35)^($A35-1)*12*IF($A35>Assumptions!$C$8,0,1) | F35: =Assumptions!$F$21*MIN(1,$A35/Assumptions!$C$31)*IF($A35>Assumptions!$C$8,0,1) | G35: =Take_Rate_Customers!$H$35*Assumptions!$C$34*IF($A35>Assumptions!$C$8,0,1) | H35: =SUM($B35:$F35) | I35: =$H35+$G35
A36: 30 | B36: =Take_Rate_Customers!$C$36*Assumptions!$F$16*(1+Assumptions!$C$35)^($A36-1)*12*IF($A36>Assumptions!$C$8,0,1) | C36: =Take_Rate_Customers!$D$36*Assumptions!$F$17*(1+Assumptions!$C$35)^($A36-1)*12*IF($A36>Assumptions!$C$8,0,1) | D36: =Take_Rate_Customers!$E$36*Assumptions!$F$18*(1+Assumptions!$C$35)^($A36-1)*12*IF($A36>Assumptions!$C$8,0,1) | E36: =Take_Rate_Customers!$F$36*Assumptions!$F$19*(1+Assumptions!$C$35)^($A36-1)*12*IF($A36>Assumptions!$C$8,0,1) | F36: =Assumptions!$F$21*MIN(1,$A36/Assumptions!$C$31)*IF($A36>Assumptions!$C$8,0,1) | G36: =Take_Rate_Customers!$H$36*Assumptions!$C$34*IF($A36>Assumptions!$C$8,0,1) | H36: =SUM($B36:$F36) | I36: =$H36+$G36
B38: CHECK: no #REF errors in total gross revenue column | F38: =IF(SUMPRODUCT(--ISERROR($I6:$I36))=0,"PASS","FAIL")

Sheet Operating_Expenses
A1: OPERATING EXPENSES
A2: DRAFT FOR DISCUSSION – SUBJECT TO LEGAL, GRANT AND FINANCIAL REVIEW
A3: Fixed components inflate; %-of-revenue components scale with revenue. Electronics replacement is a MEMO here — the capital charge lives in Capital_Replacement to avoid double counting.
A5: Year | B5: Infl. Factor | C5: Network Ops | D5: Maintenance | E5: Staffing | F5: Marketing | G5: G&A | H5: Bad Debt | I5: TOTAL OPEX | J5: Electronics (memo)
A6: 0 | B6: 1 | C6: 0 | D6: 0 | E6: 0 | F6: 0 | G6: 0 | H6: 0 | I6: 0 | J6: 0
A7: 1 | B7: =(1+Assumptions!$F$24)^($A7-1) | C7: =Take_Rate_Customers!$G$7*Assumptions!$C$36*$B7 | D7: =Assumptions!$C$37*Construction_Budget!$E$17*$B7 | E7: =Assumptions!$C$38*Assumptions!$C$39*$B7 | F7: =Assumptions!$C$40*Revenue!$I$7 | G7: =Assumptions!$C$41*Revenue!$I$7 | H7: =Assumptions!$F$23*Revenue!$H$7 | I7: =SUM($C7:$H7) | J7: =Construction_Budget!$E$19/Assumptions!$C$42*$B7
A8: 2 | B8: =(1+Assumptions!$F$24)^($A8-1) | C8: =Take_Rate_Customers!$G$8*Assumptions!$C$36*$B8 | D8: =Assumptions!$C$37*Construction_Budget!$E$17*$B8 | E8: =Assumptions!$C$38*Assumptions!$C$39*$B8 | F8: =Assumptions!$C$40*Revenue!$I$8 | G8: =Assumptions!$C$41*Revenue!$I$8 | H8: =Assumptions!$F$23*Revenue!$H$8 | I8: =SUM($C8:$H8) | J8: =Construction_Budget!$E$19/Assumptions!$C$42*$B8
A9: 3 | B9: =(1+Assumptions!$F$24)^($A9-1) | C9: =Take_Rate_Customers!$G$9*Assumptions!$C$36*$B9 | D9: =Assumptions!$C$37*Construction_Budget!$E$17*$B9 | E9: =Assumptions!$C$38*Assumptions!$C$39*$B9 | F9: =Assumptions!$C$40*Revenue!$I$9 | G9: =Assumptions!$C$41*Revenue!$I$9 | H9: =Assumptions!$F$23*Revenue!$H$9 | I9: =SUM($C9:$H9) | J9: =Construction_Budget!$E$19/Assumptions!$C$42*$B9
A10: 4 | B10: =(1+Assumptions!$F$24)^($A10-1) | C10: =Take_Rate_Customers!$G$10*Assumptions!$C$36*$B10 | D10: =Assumptions!$C$37*Construction_Budget!$E$17*$B10 | E10: =Assumptions!$C$38*Assumptions!$C$39*$B10 | F10: =Assumptions!$C$40*Revenue!$I$10 | G10: =Assumptions!$C$41*Revenue!$I$10 | H10: =Assumptions!$F$23*Revenue!$H$10 | I10: =SUM($C10:$H10) | J10: =Construction_Budget!$E$19/Assumptions!$C$42*$B10
A11: 5 | B11: =(1+Assumptions!$F$24)^($A11-1) | C11: =Take_Rate_Customers!$G$11*Assumptions!$C$36*$B11 | D11: =Assumptions!$C$37*Construction_Budget!$E$17*$B11 | E11: =Assumptions!$C$38*Assumptions!$C$39*$B11 | F11: =Assumptions!$C$40*Revenue!$I$11 | G11: =Assumptions!$C$41*Revenue!$I$11 | H11: =Assumptions!$F$23*Revenue!$H$11 | I11: =SUM($C11:$H11) | J11: =Construction_Budget!$E$19/Assumptions!$C$42*$B11
A12: 6 | B12: =(1+Assumptions!$F$24)^($A12-1) | C12: =Take_Rate_Customers!$G$12*Assumptions!$C$36*$B12 | D12: =Assumptions!$C$37*Construction_Budget!$E$17*$B12 | E12: =Assumptions!$C$38*Assumptions!$C$39*$B12 | F12: =Assumptions!$C$40*Revenue!$I$12 | G12: =Assumptions!$C$41*Revenue!$I$12 | H12: =Assumptions!$F$23*Revenue!$H$12 | I12: =SUM($C12:$H12) | J12: =Construction_Budget!$E$19/Assumptions!$C$42*$B12
A13: 7 | B13: =(1+Assumptions!$F$24)^($A13-1) | C13: =Take_Rate_Customers!$G$13*Assumptions!$C$36*$B13 | D13: =Assumptions!$C$37*Construction_Budget!$E$17*$B13 | E13: =Assumptions!$C$38*Assumptions!$C$39*$B13 | F13: =Assumptions!$C$40*Revenue!$I$13 | G13: =Assumptions!$C$41*Revenue!$I$13 | H13: =Assumptions!$F$23*Revenue!$H$13 | I13: =SUM($C13:$H13) | J13: =Construction_Budget!$E$19/Assumptions!$C$42*$B13
A14: 8 | B14: =(1+Assumptions!$F$24)^($A14-1) | C14: =Take_Rate_Customers!$G$14*Assumptions!$C$36*$B14 | D14: =Assumptions!$C$37*Construction_Budget!$E$17*$B14 | E14: =Assumptions!$C$38*Assumptions!$C$39*$B14 | F14: =Assumptions!$C$40*Revenue!$I$14 | G14: =Assumptions!$C$41*Revenue!$I$14 | H14: =Assumptions!$F$23*Revenue!$H$14 | I14: =SUM($C14:$H14) | J14: =Construction_Budget!$E$19/Assumptions!$C$42*$B14
A15: 9 | B15: =(1+Assumptions!$F$24)^($A15-1) | C15: =Take_Rate_Customers!$G$15*Assumptions!$C$36*$B15 | D15: =Assumptions!$C$37*Construction_Budget!$E$17*$B15 | E15: =Assumptions!$C$38*Assumptions!$C$39*$B15 | F15: =Assumptions!$C$40*Revenue!$I$15 | G15: =Assumptions!$C$41*Revenue!$I$15 | H15: =Assumptions!$F$23*Revenue!$H$15 | I15: =SUM($C15:$H15) | J15: =Construction_Budget!$E$19/Assumptions!$C$42*$B15
A16: 10 | B16: =(1+Assumptions!$F$24)^($A16-1) | C16: =Take_Rate_Customers!$G$16*Assumptions!$C$36*$B16 | D16: =Assumptions!$C$37*Construction_Budget!$E$17*$B16 | E16: =Assumptions!$C$38*Assumptions!$C$39*$B16 | F16: =Assumptions!$C$40*Revenue!$I$16 | G16: =Assumptions!$C$41*Revenue!$I$16 | H16: =Assumptions!$F$23*Revenue!$H$16 | I16: =SUM($C16:$H16) | J16: =Construction_Budget!$E$19/Assumptions!$C$42*$B16
A17: 11 | B17: =(1+Assumptions!$F$24)^($A17-1) | C17: =Take_Rate_Customers!$G$17*Assumptions!$C$36*$B17 | D17: =Assumptions!$C$37*Construction_Budget!$E$17*$B17 | E17: =Assumptions!$C$38*Assumptions!$C$39*$B17 | F17: =Assumptions!$C$40*Revenue!$I$17 | G17: =Assumptions!$C$41*Revenue!$I$17 | H17: =Assumptions!$F$23*Revenue!$H$17 | I17: =SUM($C17:$H17) | J17: =Construction_Budget!$E$19/Assumptions!$C$42*$B17
A18: 12 | B18: =(1+Assumptions!$F$24)^($A18-1) | C18: =Take_Rate_Customers!$G$18*Assumptions!$C$36*$B18 | D18: =Assumptions!$C$37*Construction_Budget!$E$17*$B18 | E18: =Assumptions!$C$38*Assumptions!$C$39*$B18 | F18: =Assumptions!$C$40*Revenue!$I$18 | G18: =Assumptions!$C$41*Revenue!$I$18 | H18: =Assumptions!$F$23*Revenue!$H$18 | I18: =SUM($C18:$H18) | J18: =Construction_Budget!$E$19/Assumptions!$C$42*$B18
A19: 13 | B19: =(1+Assumptions!$F$24)^($A19-1) | C19: =Take_Rate_Customers!$G$19*Assumptions!$C$36*$B19 | D19: =Assumptions!$C$37*Construction_Budget!$E$17*$B19 | E19: =Assumptions!$C$38*Assumptions!$C$39*$B19 | F19: =Assumptions!$C$40*Revenue!$I$19 | G19: =Assumptions!$C$41*Revenue!$I$19 | H19: =Assumptions!$F$23*Revenue!$H$19 | I19: =SUM($C19:$H19) | J19: =Construction_Budget!$E$19/Assumptions!$C$42*$B19
A20: 14 | B20: =(1+Assumptions!$F$24)^($A20-1) | C20: =Take_Rate_Customers!$G$20*Assumptions!$C$36*$B20 | D20: =Assumptions!$C$37*Construction_Budget!$E$17*$B20 | E20: =Assumptions!$C$38*Assumptions!$C$39*$B20 | F20: =Assumptions!$C$40*Revenue!$I$20 | G20: =Assumptions!$C$41*Revenue!$I$20 | H20: =Assumptions!$F$23*Revenue!$H$20 | I20: =SUM($C20:$H20) | J20: =Construction_Budget!$E$19/Assumptions!$C$42*$B20
A21: 15 | B21: =(1+Assumptions!$F$24)^($A21-1) | C21: =Take_Rate_Customers!$G$21*Assumptions!$C$36*$B21 | D21: =Assumptions!$C$37*Construction_Budget!$E$17*$B21 | E21: =Assumptions!$C$38*Assumptions!$C$39*$B21 | F21: =Assumptions!$C$40*Revenue!$I$21 | G21: =Assumptions!$C$41*Revenue!$I$21 | H21: =Assumptions!$F$23*Revenue!$H$21 | I21: =SUM($C21:$H21) | J21: =Construction_Budget!$E$19/Assumptions!$C$42*$B21
A22: 16 | B22: =(1+Assumptions!$F$24)^($A22-1) | C22: =Take_Rate_Customers!$G$22*Assumptions!$C$36*$B22 | D22: =Assumptions!$C$37*Construction_Budget!$E$17*$B22 | E22: =Assumptions!$C$38*Assumptions!$C$39*$B22 | F22: =Assumptions!$C$40*Revenue!$I$22 | G22: =Assumptions!$C$41*Revenue!$I$22 | H22: =Assumptions!$F$23*Revenue!$H$22 | I22: =SUM($C22:$H22) | J22: =Construction_Budget!$E$19/Assumptions!$C$42*$B22
A23: 17 | B23: =(1+Assumptions!$F$24)^($A23-1) | C23: =Take_Rate_Customers!$G$23*Assumptions!$C$36*$B23 | D23: =Assumptions!$C$37*Construction_Budget!$E$17*$B23 | E23: =Assumptions!$C$38*Assumptions!$C$39*$B23 | F23: =Assumptions!$C$40*Revenue!$I$23 | G23: =Assumptions!$C$41*Revenue!$I$23 | H23: =Assumptions!$F$23*Revenue!$H$23 | I23: =SUM($C23:$H23) | J23: =Construction_Budget!$E$19/Assumptions!$C$42*$B23
A24: 18 | B24: =(1+Assumptions!$F$24)^($A24-1) | C24: =Take_Rate_Customers!$G$24*Assumptions!$C$36*$B24 | D24: =Assumptions!$C$37*Construction_Budget!$E$17*$B24 | E24: =Assumptions!$C$38*Assumptions!$C$39*$B24 | F24: =Assumptions!$C$40*Revenue!$I$24 | G24: =Assumptions!$C$41*Revenue!$I$24 | H24: =Assumptions!$F$23*Revenue!$H$24 | I24: =SUM($C24:$H24) | J24: =Construction_Budget!$E$19/Assumptions!$C$42*$B24
A25: 19 | B25: =(1+Assumptions!$F$24)^($A25-1) | C25: =Take_Rate_Customers!$G$25*Assumptions!$C$36*$B25 | D25: =Assumptions!$C$37*Construction_Budget!$E$17*$B25 | E25: =Assumptions!$C$38*Assumptions!$C$39*$B25 | F25: =Assumptions!$C$40*Revenue!$I$25 | G25: =Assumptions!$C$41*Revenue!$I$25 | H25: =Assumptions!$F$23*Revenue!$H$25 | I25: =SUM($C25:$H25) | J25: =Construction_Budget!$E$19/Assumptions!$C$42*$B25
A26: 20 | B26: =(1+Assumptions!$F$24)^($A26-1) | C26: =Take_Rate_Customers!$G$26*Assumptions!$C$36*$B26 | D26: =Assumptions!$C$37*Construction_Budget!$E$17*$B26 | E26: =Assumptions!$C$38*Assumptions!$C$39*$B26 | F26: =Assumptions!$C$40*Revenue!$I$26 | G26: =Assumptions!$C$41*Revenue!$I$26 | H26: =Assumptions!$F$23*Revenue!$H$26 | I26: =SUM($C26:$H26) | J26: =Construction_Budget!$E$19/Assumptions!$C$42*$B26
A27: 21 | B27: =(1+Assumptions!$F$24)^($A27-1) | C27: =Take_Rate_Customers!$G$27*Assumptions!$C$36*$B27 | D27: =Assumptions!$C$37*Construction_Budget!$E$17*$B27 | E27: =Assumptions!$C$38*Assumptions!$C$39*$B27 | F27: =Assumptions!$C$40*Revenue!$I$27 | G27: =Assumptions!$C$41*Revenue!$I$27 | H27: =Assumptions!$F$23*Revenue!$H$27 | I27: =SUM($C27:$H27) | J27: =Construction_Budget!$E$19/Assumptions!$C$42*$B27
A28: 22 | B28: =(1+Assumptions!$F$24)^($A28-1) | C28: =Take_Rate_Customers!$G$28*Assumptions!$C$36*$B28 | D28: =Assumptions!$C$37*Construction_Budget!$E$17*$B28 | E28: =Assumptions!$C$38*Assumptions!$C$39*$B28 | F28: =Assumptions!$C$40*Revenue!$I$28 | G28: =Assumptions!$C$41*Revenue!$I$28 | H28: =Assumptions!$F$23*Revenue!$H$28 | I28: =SUM($C28:$H28) | J28: =Construction_Budget!$E$19/Assumptions!$C$42*$B28
A29: 23 | B29: =(1+Assumptions!$F$24)^($A29-1) | C29: =Take_Rate_Customers!$G$29*Assumptions!$C$36*$B29 | D29: =Assumptions!$C$37*Construction_Budget!$E$17*$B29 | E29: =Assumptions!$C$38*Assumptions!$C$39*$B29 | F29: =Assumptions!$C$40*Revenue!$I$29 | G29: =Assumptions!$C$41*Revenue!$I$29 | H29: =Assumptions!$F$23*Revenue!$H$29 | I29: =SUM($C29:$H29) | J29: =Construction_Budget!$E$19/Assumptions!$C$42*$B29
A30: 24 | B30: =(1+Assumptions!$F$24)^($A30-1) | C30: =Take_Rate_Customers!$G$30*Assumptions!$C$36*$B30 | D30: =Assumptions!$C$37*Construction_Budget!$E$17*$B30 | E30: =Assumptions!$C$38*Assumptions!$C$39*$B30 | F30: =Assumptions!$C$40*Revenue!$I$30 | G30: =Assumptions!$C$41*Revenue!$I$30 | H30: =Assumptions!$F$23*Revenue!$H$30 | I30: =SUM($C30:$H30) | J30: =Construction_Budget!$E$19/Assumptions!$C$42*$B30
A31: 25 | B31: =(1+Assumptions!$F$24)^($A31-1) | C31: =Take_Rate_Customers!$G$31*Assumptions!$C$36*$B31 | D31: =Assumptions!$C$37*Construction_Budget!$E$17*$B31 | E31: =Assumptions!$C$38*Assumptions!$C$39*$B31 | F31: =Assumptions!$C$40*Revenue!$I$31 | G31: =Assumptions!$C$41*Revenue!$I$31 | H31: =Assumptions!$F$23*Revenue!$H$31 | I31: =SUM($C31:$H31) | J31: =Construction_Budget!$E$19/Assumptions!$C$42*$B31
A32: 26 | B32: =(1+Assumptions!$F$24)^($A32-1) | C32: =Take_Rate_Customers!$G$32*Assumptions!$C$36*$B32 | D32: =Assumptions!$C$37*Construction_Budget!$E$17*$B32 | E32: =Assumptions!$C$38*Assumptions!$C$39*$B32 | F32: =Assumptions!$C$40*Revenue!$I$32 | G32: =Assumptions!$C$41*Revenue!$I$32 | H32: =Assumptions!$F$23*Revenue!$H$32 | I32: =SUM($C32:$H32) | J32: =Construction_Budget!$E$19/Assumptions!$C$42*$B32
A33: 27 | B33: =(1+Assumptions!$F$24)^($A33-1) | C33: =Take_Rate_Customers!$G$33*Assumptions!$C$36*$B33 | D33: =Assumptions!$C$37*Construction_Budget!$E$17*$B33 | E33: =Assumptions!$C$38*Assumptions!$C$39*$B33 | F33: =Assumptions!$C$40*Revenue!$I$33 | G33: =Assumptions!$C$41*Revenue!$I$33 | H33: =Assumptions!$F$23*Revenue!$H$33 | I33: =SUM($C33:$H33) | J33: =Construction_Budget!$E$19/Assumptions!$C$42*$B33
A34: 28 | B34: =(1+Assumptions!$F$24)^($A34-1) | C34: =Take_Rate_Customers!$G$34*Assumptions!$C$36*$B34 | D34: =Assumptions!$C$37*Construction_Budget!$E$17*$B34 | E34: =Assumptions!$C$38*Assumptions!$C$39*$B34 | F34: =Assumptions!$C$40*Revenue!$I$34 | G34: =Assumptions!$C$41*Revenue!$I$34 | H34: =Assumptions!$F$23*Revenue!$H$34 | I34: =SUM($C34:$H34) | J34: =Construction_Budget!$E$19/Assumptions!$C$42*$B34
A35: 29 | B35: =(1+Assumptions!$F$24)^($A35-1) | C35: =Take_Rate_Customers!$G$35*Assumptions!$C$36*$B35 | D35: =Assumptions!$C$37*Construction_Budget!$E$17*$B35 | E35: =Assumptions!$C$38*Assumptions!$C$39*$B35 | F35: =Assumptions!$C$40*Revenue!$I$35 | G35: =Assumptions!$C$41*Revenue!$I$35 | H35: =Assumptions!$F$23*Revenue!$H$35 | I35: =SUM($C35:$H35) | J35: =Construction_Budget!$E$19/Assumptions!$C$42*$B35
A36: 30 | B36: =(1+Assumptions!$F$24)^($A36-1) | C36: =Take_Rate_Customers!$G$36*Assumptions!$C$36*$B36 | D36: =Assumptions!$C$37*Construction_Budget!$E$17*$B36 | E36: =Assumptions!$C$38*Assumptions!$C$39*$B36 | F36: =Assumptions!$C$40*Revenue!$I$36 | G36: =Assumptions!$C$41*Revenue!$I$36 | H36: =Assumptions!$F$23*Revenue!$H$36 | I36: =SUM($C36:$H36) | J36: =Construction_Budget!$E$19/Assumptions!$C$42*$B36
B38: CHECK: total opex is non-negative and error-free | F38: =IF(AND(MIN($I6:$I36)>=0,SUMPRODUCT(--ISERROR($I6:$I36))=0),"PASS","FAIL")

Sheet Capital_Replacement
A1: CAPITAL REPLACEMENT — Electronics Refresh & Reserve
A2: DRAFT FOR DISCUSSION – SUBJECT TO LEGAL, GRANT AND FINANCIAL REVIEW
A3: Annualized charge flows to cash flow. Lumpy refresh + reserve funding test reserve adequacy.
A5: Year | B5: Annualized Elec. Charge | C5: Lumpy Refresh (memo) | D5: Reserve Funding | E5: Cum. Reserve | F5: Cum. Refresh Spend
A6: 0 | B6: 0 | C6: 0 | D6: 0 | E6: 0 | F6: 0
A7: 1 | B7: =Construction_Budget!$E$19/Assumptions!$C$42*(1+Assumptions!$F$24)^($A7-1) | C7: =IF(AND($A7>0,MOD($A7,Assumptions!$C$42)=0),Construction_Budget!$E$19*(1+Assumptions!$F$24)^$A7,0) | D7: =Assumptions!$C$43*Revenue!$I$7 | E7: =0+$D7 | F7: =0+$C7
A8: 2 | B8: =Construction_Budget!$E$19/Assumptions!$C$42*(1+Assumptions!$F$24)^($A8-1) | C8: =IF(AND($A8>0,MOD($A8,Assumptions!$C$42)=0),Construction_Budget!$E$19*(1+Assumptions!$F$24)^$A8,0) | D8: =Assumptions!$C$43*Revenue!$I$8 | E8: =$E7+$D8 | F8: =$F7+$C8
A9: 3 | B9: =Construction_Budget!$E$19/Assumptions!$C$42*(1+Assumptions!$F$24)^($A9-1) | C9: =IF(AND($A9>0,MOD($A9,Assumptions!$C$42)=0),Construction_Budget!$E$19*(1+Assumptions!$F$24)^$A9,0) | D9: =Assumptions!$C$43*Revenue!$I$9 | E9: =$E8+$D9 | F9: =$F8+$C9
A10: 4 | B10: =Construction_Budget!$E$19/Assumptions!$C$42*(1+Assumptions!$F$24)^($A10-1) | C10: =IF(AND($A10>0,MOD($A10,Assumptions!$C$42)=0),Construction_Budget!$E$19*(1+Assumptions!$F$24)^$A10,0) | D10: =Assumptions!$C$43*Revenue!$I$10 | E10: =$E9+$D10 | F10: =$F9+$C10
A11: 5 | B11: =Construction_Budget!$E$19/Assumptions!$C$42*(1+Assumptions!$F$24)^($A11-1) | C11: =IF(AND($A11>0,MOD($A11,Assumptions!$C$42)=0),Construction_Budget!$E$19*(1+Assumptions!$F$24)^$A11,0) | D11: =Assumptions!$C$43*Revenue!$I$11 | E11: =$E10+$D11 | F11: =$F10+$C11
A12: 6 | B12: =Construction_Budget!$E$19/Assumptions!$C$42*(1+Assumptions!$F$24)^($A12-1) | C12: =IF(AND($A12>0,MOD($A12,Assumptions!$C$42)=0),Construction_Budget!$E$19*(1+Assumptions!$F$24)^$A12,0) | D12: =Assumptions!$C$43*Revenue!$I$12 | E12: =$E11+$D12 | F12: =$F11+$C12
A13: 7 | B13: =Construction_Budget!$E$19/Assumptions!$C$42*(1+Assumptions!$F$24)^($A13-1) | C13: =IF(AND($A13>0,MOD($A13,Assumptions!$C$42)=0),Construction_Budget!$E$19*(1+Assumptions!$F$24)^$A13,0) | D13: =Assumptions!$C$43*Revenue!$I$13 | E13: =$E12+$D13 | F13: =$F12+$C13
A14: 8 | B14: =Construction_Budget!$E$19/Assumptions!$C$42*(1+Assumptions!$F$24)^($A14-1) | C14: =IF(AND($A14>0,MOD($A14,Assumptions!$C$42)=0),Construction_Budget!$E$19*(1+Assumptions!$F$24)^$A14,0) | D14: =Assumptions!$C$43*Revenue!$I$14 | E14: =$E13+$D14 | F14: =$F13+$C14
A15: 9 | B15: =Construction_Budget!$E$19/Assumptions!$C$42*(1+Assumptions!$F$24)^($A15-1) | C15: =IF(AND($A15>0,MOD($A15,Assumptions!$C$42)=0),Construction_Budget!$E$19*(1+Assumptions!$F$24)^$A15,0) | D15: =Assumptions!$C$43*Revenue!$I$15 | E15: =$E14+$D15 | F15: =$F14+$C15
A16: 10 | B16: =Construction_Budget!$E$19/Assumptions!$C$42*(1+Assumptions!$F$24)^($A16-1) | C16: =IF(AND($A16>0,MOD($A16,Assumptions!$C$42)=0),Construction_Budget!$E$19*(1+Assumptions!$F$24)^$A16,0) | D16: =Assumptions!$C$43*Revenue!$I$16 | E16: =$E15+$D16 | F16: =$F15+$C16
A17: 11 | B17: =Construction_Budget!$E$19/Assumptions!$C$42*(1+Assumptions!$F$24)^($A17-1) | C17: =IF(AND($A17>0,MOD($A17,Assumptions!$C$42)=0),Construction_Budget!$E$19*(1+Assumptions!$F$24)^$A17,0) | D17: =Assumptions!$C$43*Revenue!$I$17 | E17: =$E16+$D17 | F17: =$F16+$C17
A18: 12 | B18: =Construction_Budget!$E$19/Assumptions!$C$42*(1+Assumptions!$F$24)^($A18-1) | C18: =IF(AND($A18>0,MOD($A18,Assumptions!$C$42)=0),Construction_Budget!$E$19*(1+Assumptions!$F$24)^$A18,0) | D18: =Assumptions!$C$43*Revenue!$I$18 | E18: =$E17+$D18 | F18: =$F17+$C18
A19: 13 | B19: =Construction_Budget!$E$19/Assumptions!$C$42*(1+Assumptions!$F$24)^($A19-1) | C19: =IF(AND($A19>0,MOD($A19,Assumptions!$C$42)=0),Construction_Budget!$E$19*(1+Assumptions!$F$24)^$A19,0) | D19: =Assumptions!$C$43*Revenue!$I$19 | E19: =$E18+$D19 | F19: =$F18+$C19
A20: 14 | B20: =Construction_Budget!$E$19/Assumptions!$C$42*(1+Assumptions!$F$24)^($A20-1) | C20: =IF(AND($A20>0,MOD($A20,Assumptions!$C$42)=0),Construction_Budget!$E$19*(1+Assumptions!$F$24)^$A20,0) | D20: =Assumptions!$C$43*Revenue!$I$20 | E20: =$E19+$D20 | F20: =$F19+$C20
A21: 15 | B21: =Construction_Budget!$E$19/Assumptions!$C$42*(1+Assumptions!$F$24)^($A21-1) | C21: =IF(AND($A21>0,MOD($A21,Assumptions!$C$42)=0),Construction_Budget!$E$19*(1+Assumptions!$F$24)^$A21,0) | D21: =Assumptions!$C$43*Revenue!$I$21 | E21: =$E20+$D21 | F21: =$F20+$C21
